Workbook
Name ACTIONSHOT: Roster!$S$3:$S$102
Name AGE: Roster!$O$3:$O$102
Name BIO_HEADER: Roster!$N$3:$N$4
Name CAT_1: 'Season Stats'!$D$1:$D$100
Name CAT_1_HILITE: 'Season Stats'!$E$1:$E$100
Name CAT_2: 'Season Stats'!$F$1:$F$100
Name CAT_2_HILITE: 'Season Stats'!$G$1:$G$100
Name CAT_3: 'Season Stats'!$H$1:$H$100
Name CAT_3_HILITE: 'Season Stats'!$I$1:$I$100
Name CBB_3PT: 'Player Stats'!$F$2:$F$101
Name CBB_ASSISTS: 'Player Stats'!$I$2:$I$101
Name CBB_BLOCKS: 'Player Stats'!$J$2:$J$101
Name CBB_FIELD_GOALS: 'Player Stats'!$E$2:$E$101
Name CBB_FT: 'Player Stats'!$G$2:$G$101
Name CBB_MINUTES: 'Player Stats'!$L$2:$L$101
Name CBB_POINTS: 'Player Stats'!$D$2:$D$101
Name CBB_REBOUNDS: 'Player Stats'!$H$2:$H$101
Name CBB_SEASON_3PT_FG_STAT: 'Season Stats'!$Z$1:$Z$100
Name CBB_SEASON_FT_STAT: 'Season Stats'!$Y$1:$Y$100
Name CBB_STEALS: 'Player Stats'!$K$2:$K$101
Name COACH_DEF_FIRST: 'Team Personnel'!$B$24:$B$34
Name COACH_DEF_LAST: 'Team Personnel'!$C$24:$C$34
Name COACH_DEF_TEXT: 'Team Personnel'!$E$24:$E$34
Name COACH_HEAD_DROP: 'Team Personnel'!$F$2:$F$12
Name COACH_HEAD_FIRST: 'Team Personnel'!$B$2:$B$12
Name COACH_HEAD_FULL: 'Team Personnel'!$I$2:$I$12
Name COACH_HEAD_HEADER: 'Team Personnel'!$D$2:$D$12
Name COACH_HEAD_LAST: 'Team Personnel'!$C$2:$C$12
Name COACH_HEAD_TEXT: 'Team Personnel'!$E$2:$E$12
Name COACH_OFF_DROP: 'Team Personnel'!$F$13:$F$23
Name COACH_OFF_FIRST: 'Team Personnel'!$B$13:$B$23
Name COACH_OFF_FULL: 'Team Personnel'!$I$13:$I$23
Name COACH_OFF_HEADER: 'Team Personnel'!$D$13:$D$23
Name COACH_OFF_LAST: 'Team Personnel'!$C$13:$C$23
Name COACH_OFF_TEXT: 'Team Personnel'!$E$13:$E$23
Name COACH_RESUME_DROP: 'Team Personnel'!$K$17:$K$18
Name COACH_RESUME_LINE1: 'Team Personnel'!$K$8:$K$9
Name COACH_RESUME_LINE2: 'Team Personnel'!$K$11:$K$12
Name COACH_RESUME_LINE3: 'Team Personnel'!$K$14:$K$15
Name COACH_RESUME_LINE4: 'Team Personnel'!$K$20:$K$21
Name COACH_RESUME_ROWS: 'Team Personnel'!$K$23:$K$35
Name COACH_RESUME_SUBTITLE: 'Team Personnel'!$K$5:$K$6
Name COACH_RESUME_TITLE: 'Team Personnel'!$K$2:$K$3
Name CONFERENCE_LOGOS: LOGOS!$C$1:$C$50
Name DASH_SWATCH: 'Team Info'!$H$36:$H$37
Name ESPN100: Roster!$M$3:$M$102
Name GENERIC_SWATCHES: LOGOS!$G$1:$G$50
Name HEADER: Roster!$L$3:$L$102
Name HEADSHOT: Roster!$R$3:$R$102
Name HEIGHT: Roster!$F$3:$F$102
Name HERO_1_DROP: 'Player Heroes'!$J$2:$J$101
Name HERO_1_HEADER: 'Player Heroes'!$G$2:$G$101
Name HERO_1_INFO: 'Player Heroes'!$I$2:$I$101
Name HERO_USER: 'Player Users'!$G$2:$G$101
Name HERO_USER2: 'Player Users'!$I$2:$I$101
Name HERO_USER3: 'Player Users'!$K$2:$K$101
Name HERO_USER4: 'Player Users'!$M$2:$M$101
Name HOMETOWN: Roster!$I$3:$I$102
Name JERSEY: Roster!$B$3:$B$102
Name LU_Firstname: Lineup!$C$1:$C$6

Sheet Team Info
A1: ESPN Team Sheet - v2024.1.4 | B1: Updated 10/29/25 | D1: TEAM INFO | F1: TODAY_TONIGHT_SEL | H1: SWATCH SEL
A2: TEAM INFO | B2: Home | D2: TEAM_RANK | F2: =$B$19 -> Tonight | H2: 0 | I2: LOGO
A3: Team Rank | B3: 7 | D3: =$B$3 -> 7 | F3: =UPPER(F2) -> TONIGHT | H3: 1 | I3: PRIMARY
A4: Team College | B4: LSU | H4: 2 | I4: SECONDARY
A5: Team Nickname | B5: Tigers | D5: TEAM_CITY_COLLEGE | F5: SEASON_SEL | H5: 3 | I5: BOTTOMLINE
A6: Team Tricode | B6: LSU | D6: =$B$4 -> LSU | F6: =$B$20 -> Last Season | H6: 4 | I6: BLACK
A7: Team Dashboard Name (CAPS) | B7: LSU | D7: =UPPER(D6) -> LSU | F7: =UPPER(F6) -> LAST SEASON | H7: 5 | I7: GRAY
A8: Split Locator Name CAPS (LINE1|LINE2) | B8: LSU | H8: 6 | I8: GOLD
A9: Team Record (CAPS) | B9: X-X | D9: TEAM_NICKNAME | F9: TODAY_TONIGHT_SEL_COLON | H9: 7 | I9: PINK
D10: =$B$5 -> Tigers | F10: =$F$2&":" -> Tonight: | H10: 8 | I10: YELLOW
A11: TEAM LOGOS / SWATCH / HEADSHOTS | D11: =UPPER(D10) -> TIGERS | H11: 9 | I11: CUSTOM
A12: LOGO / SWATCH / HEADSHOT / ACTION | B12: LSU | F12: SEASON_SEL_COLON
A13: Swatch Selector | B13: 0 | C13: =H25 -> LOGO | D13: TEAM_TRICODE | F13: =$F$6&":" -> Last Season: | H13: TODAY/SEASON SEL
A14: Dashboard Swatch Selector | B14: 0 | C14: =H30 -> LOGO | D14: =$B$6 -> LSU | H14: Season
A15: BG Color (0=Color, 1=White) 0=Default | B15: 0 | C15: =H34 -> COLOR | H15: Last Season
A16: Headshots On/Off (0=Off, 1=On) | B16: 0 | C16: =F25 -> Off
A17: Custom Dash/Slider Swatch Color | B17: AQUA_BLUE_GENERIC | D17: TEAM_FULL_NAME | F17: AWAY/HOME SEL
A18: TODAY / SEASON SELECTION | D18: =B4&" "&B5 -> LSU Tigers | F18: Away | H18: Today
A19: Today / Tonight Selection | B19: Tonight | D19: =UPPER(D18) -> LSU TIGERS | F19: Home | H19: Tonight
A20: Season / Last Season | B20: Last Season
D21: TEAM_DASH_NAME | F21: HEADSHOT_ONOFF | H21: SWATCH_SELECT
A22: TEXT COLOR | D22: =$B$7 -> LSU
A23: Text Color (Default = 0, Black = 1) | B23: 0 | C23: =F33 -> Default
A24: Note: Fill out information in BLUE cells only and select Away/Home in cell B2 | F24: =$B$16 -> 0 | H24: =B$13 -> 0
F25: =IF(F24=1,"On","Off") -> Off | H25: =IF(H24=1,"PRIMARY",IF(H24=2,"SECONDARY",IF(H24=3,"BOTTOMLINE",IF(H24=0,"LOGO")))) -> LOGO
A26: For Dashboard Jersey colors that are different than typical team colors, | D26: TEAM_RANK_NAME
A27: and are not using the predefined colors (options 4-8), users should select 9 (CUSTOM) | D27: =D3&" "&D6 -> 7 LSU | F27: On/Off
A28: and then select a color option in cell B17. | D28: =UPPER(D27) -> 7 LSU | F28: 0 | H28: DASH_SWATCH_SELECT
F29: 1 | H29: =$B$14 -> 0
D30: TEAM_RANK_NAME_NICKNAME | H30: =IF(H29=1,"PRIMARY",IF(H29=2,"SECONDARY",IF(H29=3,"BOTTOMLINE",IF(H29=4,"BLACK",IF(H29=5,"GRAY",IF(H29=6,"GOLD",IF(H29=7,"PINK",IF(H29=8,"YELLOW",IF(H29=9,"CUSTOM",IF(H29=0,"LOGO")))))))))) -> LOGO
D31: =D3&" "&D6&" "&D10 -> 7 LSU Tigers | F31: TEXT COLOR
D32: =UPPER(D31) -> 7 LSU TIGERS | F32: =$B$23 -> 0 | H32: BG_COLOR_SELECT
F33: =IF(F32=1,"Black","Default") -> Default | H33: =$B$15 -> 0
D34: TEAM_RANK_NAME_RECORD | H34: =IF(B15=0,"COLOR","WHITE") -> COLOR
D35: =D3&" "&D6&" "& "(" & D42 &")" -> 7 LSU (X-X)
D36: =UPPER(D35) -> 7 LSU (X-X) | H36: DASH_SWATCH
H37: =B17 -> AQUA_BLUE_GENERIC
D38: TEAM_LOGOTEXT
D39: =$B$12 -> LSU
D41: TEAM_RECORD_OVERALL
...

Sheet Team Personnel
A1: Away: 179-199; Home 279-299 | B1: CAPS | C1: CAPS | D1: CAPS | E1: Upper / Lower | F1: Upper/Lower (if needed)
A2: Save # | B2: First Name CAPS | C2: Last Name CAPS | D2: Header | E2: Line 1 Text | F2: Dropline Text | I2: COACH_HEAD_FULL | K2: COACH_RESUME_TITLE
A3: =IF('Team Info'!$B$2 = "Away",180,280) -> 280 | B3: FIRST | C3: LAST | E3: Coach Info Here | F3: Sticker only - no dropline | I3: =B3 &" " & C3 -> FIRST LAST | K3: =B37 -> COACHING RÉSUMÉ
A4: =A3+1 -> 281 | B4: =$B$3 -> FIRST | C4: =$C$3 -> LAST | I4: =B4 &" " & C4 -> FIRST LAST
A5: =A3+2 -> 282 | B5: =$B$3 -> FIRST | C5: =$C$3 -> LAST | I5: =B5 &" " & C5 -> FIRST LAST | K5: COACH_RESUME_SUBTITLE
A6: =A3+3 -> 283 | B6: =$B$3 -> FIRST | C6: =$C$3 -> LAST | I6: =B6 &" " & C6 -> FIRST LAST
A7: =A3+4 -> 284 | B7: =$B$3 -> FIRST | C7: =$C$3 -> LAST | I7: =B7 &" " & C7 -> FIRST LAST
A8: =A3+5 -> 285 | B8: =$B$3 -> FIRST | C8: =$C$3 -> LAST | I8: =B8 &" " & C8 -> FIRST LAST | K8: COACH_RESUME_LINE1
A9: =A3+6 -> 286 | B9: =$B$3 -> FIRST | C9: =$C$3 -> LAST | I9: =B9 &" " & C9 -> FIRST LAST | K9: =B41 -> Line1 Test Line 1a
A10: =A3+7 -> 287 | B10: =$B$3 -> FIRST | C10: =$C$3 -> LAST | I10: =B10 &" " & C10 -> FIRST LAST
A11: =A3+8 -> 288 | B11: =$B$3 -> FIRST | C11: =$C$3 -> LAST | I11: =B11 &" " & C11 -> FIRST LAST | K11: COACH_RESUME_LINE2
A12: =A3+9 -> 289 | B12: =$B$3 -> FIRST | C12: =$C$3 -> LAST | I12: =B12 &" " & C12 -> FIRST LAST | K12: =B43 -> Line2 Text Line 2a
A13: Save # | B13: First Name CAPS | C13: Last Name CAPS | D13: Header | E13: Line 1 Text | F13: Dropline Text | G13: Do not delete COLUMNS. Do not Delete rows above here. | I13: COACH_OFF_FULL
A14: =IF('Team Info'!$B$2 = "Away",190,290) -> 290 | B14: FIRST | C14: LAST | I14: =B14 &" " & C14 -> FIRST LAST | K14: COACH_RESUME_LINE3
A15: =A14+1 -> 291 | B15: FIRST | C15: LAST | I15: =B15 &" " & C15 -> FIRST LAST | K15: =B45 -> Line3 Test Line3a
A16: =A14+2 -> 292 | B16: FIRST | C16: LAST | I16: =B16 &" " & C16 -> FIRST LAST
A17: =A14+3 -> 293 | B17: FIRST | C17: LAST | I17: =B17 &" " & C17 -> FIRST LAST | K17: COACH_RESUME_DROP
A18: =A14+4 -> 294 | B18: FIRST | C18: LAST | I18: =B18 &" " & C18 -> FIRST LAST | K18: =B49
A19: =A14+5 -> 295 | B19: FIRST | C19: LAST | I19: =B19 &" " & C19 -> FIRST LAST
A20: =A14+6 -> 296 | B20: FIRST | C20: LAST | I20: =B20 &" " & C20 -> FIRST LAST | K20: COACH_RESUME_LINE4
A21: =A14+7 -> 297 | B21: FIRST | C21: LAST | I21: =B21 &" " & C21 -> FIRST LAST | K21: =B47 -> Line4 Text Line4a
A22: =A14+8 -> 298 | B22: FIRST | C22: LAST | I22: =B22 &" " & C22 -> FIRST LAST
A23: =A14+9 -> 299 | B23: FIRST | C23: LAST | I23: =B23 &" " & C23 -> FIRST LAST | K23: COACH_RESUME_ROWS
A24: Save # | B24: First Name CAPS | C24: Last Name CAPS | E24: Line 1 Text (Upper/Lower) | F24: Stickers only | K24: =B56 -> 0
A25: =IF('Team Info'!$B$2 = "Away",190,290) -> 290 | B25: MIKE | C25: STOOPS | E25: Defensive Coordinator
A26: =A25+1 -> 291 | B26: RUFFIN | C26: McNEIL | E26: Assistant Head Coach/Defensive Tackles Coach
A27: =A25+2 -> 292 | B27: DEF. COACH | C27: DEF. COACH
A28: =A25+3 -> 293 | B28: DEF. COACH | C28: DEF. COACH
A29: =A25+4 -> 294 | B29: DEF. COACH | C29: DEF. COACH
A30: =A25+5 -> 295 | B30: DEF. COACH | C30: DEF. COACH
A31: =A25+6 -> 296 | B31: DEF. COACH | C31: DEF. COACH
A32: =A25+7 -> 297 | B32: DEF. COACH | C32: DEF. COACH
A33: =A25+8 -> 298 | B33: DEF. COACH | C33: DEF. COACH
A34: =A25+9 -> 299 | B34: DEF. COACH | C34: DEF. COACH
A35: ** MAKE SURE YOU SELECT AWAY OR HOME ON THE TEAM INFO TAB (CELL B2) ** | K35: =B38 -> 3
A36: Coach Resume: | B36: =IF('Team Info'!$B$2 = "Away",179,279) -> 279
A37: Title | B37: COACHING RÉSUMÉ | D37: Head Coach: Fill in first/last name in cells B3/C3. This will copy to the remaining head coach shells.
A38: Num Rows (1-4) | B38: 3
A39: First Name (CAPS) | B39: =B3 -> FIRST
A40: Last Name (CAPS) | B40: =C3 -> LAST
...

Sheet Roster
A1: Roster | B1: BIOS: 11xx Away, 21xx Home | I1: Choose Header or Major in Cell K3 | K1: ACCN & SECN Teams = Major
E2: G / F / C | H2: Date calc - enter as xx/xx/xx | J2: Enter FR, SO, JR, or SR | K2: ALL CAPS | M2: Optional
A3: Jersey | B3: Display | C3: First Name | D3: Last Name | E3: POS | F3: Height | G3: Weight | H3: Birthday | I3: Hometown | J3: Year | K3: Major | L3: Bio Dropline | M3: ESPN 100 Rank | N3: HEADER | O3: Age | P3: Position | Q3: Year | R3: Headshot | S3: Actionshot | T3: Full Name | U3: Initial Name | V3: Year | W3: Full Name CAPS | X3: First Name CAPS | Y3: Last Name CAPS | Z3: Year CAPS
A4: 1 | B4: 1 | C4: First | D4: Last | E4: G | F4: 5'10" | G4: 195 | I4: Charlotte, NC | J4: FR | N4: =IF(K3="Header", 0, 1) -> 1 | O4: =INT(YEARFRAC($H4, TODAY())) -> 125 | P4: =IF($E4="G", "Guard", IF($E4="F", "Forward", IF($E4="C", "Center", ""))) -> Guard | Q4: =IF($J4="SR", "Senior", IF($J4=4,"Senior",IF($J4="JR", "Junior", IF($J4=3,"Junior",IF($J4="SO", "Sophomore", IF($J4=2,"Sophomore",IF($J4="FR", "Freshman",IF($J4=1,"Freshman","")))))))) -> Freshman | R4: ="D:\IMS Images\Headshots\CBB\"&'Team Info'!$B$12&"\"&D4&"_"&C4&".png" -> D:\IMS Images\Headshots\CBB\LSU\Last_First.png | S4: ="D:\IMS Images\ActionShots\CBB\"&'Team Info'!$B$12&"\"&D4&"_"&C4&".png" -> D:\IMS Images\ActionShots\CBB\LSU\Last_First.png | T4: =C4&" "&D4 -> First Last | U4: =LEFT(C4,1)&". "&D4 -> F. Last | V4: =IF($J4="SR", "SR", IF($J4=4,"SR",IF($J4="JR", "JR", IF($J4=3,"JR",IF($J4="SO", "SO", IF($J4=2,"SO",IF($J4="FR", "FR",IF($J4=1,"FR","")))))))) -> FR | W4: =UPPER(T4) -> FIRST LAST | X4: =UPPER(C4) -> FIRST | Y4: =UPPER(D4) -> LAST | Z4: =UPPER(Q4) -> FRESHMAN
A5: 2 | B5: 2 | O5: =INT(YEARFRAC($H5, TODAY())) -> 125 | P5: =IF($E5="G", "Guard", IF($E5="F", "Forward", IF($E5="C", "Center", ""))) | Q5: =IF($J5="SR", "Senior", IF($J5=4,"Senior",IF($J5="JR", "Junior", IF($J5=3,"Junior",IF($J5="SO", "Sophomore", IF($J5=2,"Sophomore",IF($J5="FR", "Freshman",IF($J5=1,"Freshman","")))))))) | R5: ="D:\IMS Images\Headshots\CBB\"&'Team Info'!$B$12&"\"&D5&"_"&C5&".png" -> D:\IMS Images\Headshots\CBB\LSU\_.png | S5: ="D:\IMS Images\ActionShots\CBB\"&'Team Info'!$B$12&"\"&D5&"_"&C5&".png" -> D:\IMS Images\ActionShots\CBB\LSU\_.png | T5: =C5&" "&D5 | U5: =LEFT(C5,1)&". "&D5 -> . | V5: =IF($J5="SR", "SR", IF($J5=4,"SR",IF($J5="JR", "JR", IF($J5=3,"JR",IF($J5="SO", "SO", IF($J5=2,"SO",IF($J5="FR", "FR",IF($J5=1,"FR","")))))))) | W5: =UPPER(T5) | X5: =UPPER(C5) | Y5: =UPPER(D5) | Z5: =UPPER(Q5)
A6: 3 | B6: 3 | O6: =INT(YEARFRAC($H6, TODAY())) -> 125 | P6: =IF($E6="G", "Guard", IF($E6="F", "Forward", IF($E6="C", "Center", ""))) | Q6: =IF($J6="SR", "Senior", IF($J6=4,"Senior",IF($J6="JR", "Junior", IF($J6=3,"Junior",IF($J6="SO", "Sophomore", IF($J6=2,"Sophomore",IF($J6="FR", "Freshman",IF($J6=1,"Freshman","")))))))) | R6: ="D:\IMS Images\Headshots\CBB\"&'Team Info'!$B$12&"\"&D6&"_"&C6&".png" -> D:\IMS Images\Headshots\CBB\LSU\_.png | S6: ="D:\IMS Images\ActionShots\CBB\"&'Team Info'!$B$12&"\"&D6&"_"&C6&".png" -> D:\IMS Images\ActionShots\CBB\LSU\_.png | T6: =C6&" "&D6 | U6: =LEFT(C6,1)&". "&D6 -> . | V6: =IF($J6="SR", "SR", IF($J6=4,"SR",IF($J6="JR", "JR", IF($J6=3,"JR",IF($J6="SO", "SO", IF($J6=2,"SO",IF($J6="FR", "FR",IF($J6=1,"FR","")))))))) | W6: =UPPER(T6) | X6: =UPPER(C6) | Y6: =UPPER(D6) | Z6: =UPPER(Q6)
A7: 4 | B7: 4 | N7: HDR_SEL | O7: =INT(YEARFRAC($H7, TODAY())) -> 125 | P7: =IF($E7="G", "Guard", IF($E7="F", "Forward", IF($E7="C", "Center", ""))) | Q7: =IF($J7="SR", "Senior", IF($J7=4,"Senior",IF($J7="JR", "Junior", IF($J7=3,"Junior",IF($J7="SO", "Sophomore", IF($J7=2,"Sophomore",IF($J7="FR", "Freshman",IF($J7=1,"Freshman","")))))))) | R7: ="D:\IMS Images\Headshots\CBB\"&'Team Info'!$B$12&"\"&D7&"_"&C7&".png" -> D:\IMS Images\Headshots\CBB\LSU\_.png | S7: ="D:\IMS Images\ActionShots\CBB\"&'Team Info'!$B$12&"\"&D7&"_"&C7&".png" -> D:\IMS Images\ActionShots\CBB\LSU\_.png | T7: =C7&" "&D7 | U7: =LEFT(C7,1)&". "&D7 -> . | V7: =IF($J7="SR", "SR", IF($J7=4,"SR",IF($J7="JR", "JR", IF($J7=3,"JR",IF($J7="SO", "SO", IF($J7=2,"SO",IF($J7="FR", "FR",IF($J7=1,"FR","")))))))) | W7: =UPPER(T7) | X7: =UPPER(C7) | Y7: =UPPER(D7) | Z7: =UPPER(Q7)
A8: 5 | B8: 5 | N8: Header | O8: =INT(YEARFRAC($H8, TODAY())) -> 125 | P8: =IF($E8="G", "Guard", IF($E8="F", "Forward", IF($E8="C", "Center", ""))) | Q8: =IF($J8="SR", "Senior", IF($J8=4,"Senior",IF($J8="JR", "Junior", IF($J8=3,"Junior",IF($J8="SO", "Sophomore", IF($J8=2,"Sophomore",IF($J8="FR", "Freshman",IF($J8=1,"Freshman","")))))))) | R8: ="D:\IMS Images\Headshots\CBB\"&'Team Info'!$B$12&"\"&D8&"_"&C8&".png" -> D:\IMS Images\Headshots\CBB\LSU\_.png | S8: ="D:\IMS Images\ActionShots\CBB\"&'Team Info'!$B$12&"\"&D8&"_"&C8&".png" -> D:\IMS Images\ActionShots\CBB\LSU\_.png | T8: =C8&" "&D8 | U8: =LEFT(C8,1)&". "&D8 -> . | V8: =IF($J8="SR", "SR", IF($J8=4,"SR",IF($J8="JR", "JR", IF($J8=3,"JR",IF($J8="SO", "SO", IF($J8=2,"SO",IF($J8="FR", "FR",IF($J8=1,"FR","")))))))) | W8: =UPPER(T8) | X8: =UPPER(C8) | Y8: =UPPER(D8) | Z8: =UPPER(Q8)
A9: 6 | B9: 6 | N9: Major | O9: =INT(YEARFRAC($H9, TODAY())) -> 125 | P9: =IF($E9="G", "Guard", IF($E9="F", "Forward", IF($E9="C", "Center", ""))) | Q9: =IF($J9="SR", "Senior", IF($J9=4,"Senior",IF($J9="JR", "Junior", IF($J9=3,"Junior",IF($J9="SO", "Sophomore", IF($J9=2,"Sophomore",IF($J9="FR", "Freshman",IF($J9=1,"Freshman","")))))))) | R9: ="D:\IMS Images\Headshots\CBB\"&'Team Info'!$B$12&"\"&D9&"_"&C9&".png" -> D:\IMS Images\Headshots\CBB\LSU\_.png | S9: ="D:\IMS Images\ActionShots\CBB\"&'Team Info'!$B$12&"\"&D9&"_"&C9&".png" -> D:\IMS Images\ActionShots\CBB\LSU\_.png | T9: =C9&" "&D9 | U9: =LEFT(C9,1)&". "&D9 -> . | V9: =IF($J9="SR", "SR", IF($J9=4,"SR",IF($J9="JR", "JR", IF($J9=3,"JR",IF($J9="SO", "SO", IF($J9=2,"SO",IF($J9="FR", "FR",IF($J9=1,"FR","")))))))) | W9: =UPPER(T9) | X9: =UPPER(C9) | Y9: =UPPER(D9) | Z9: =UPPER(Q9)
A10: 7 | B10: 7 | O10: =INT(YEARFRAC($H10, TODAY())) -> 125 | P10: =IF($E10="G", "Guard", IF($E10="F", "Forward", IF($E10="C", "Center", ""))) | Q10: =IF($J10="SR", "Senior", IF($J10=4,"Senior",IF($J10="JR", "Junior", IF($J10=3,"Junior",IF($J10="SO", "Sophomore", IF($J10=2,"Sophomore",IF($J10="FR", "Freshman",IF($J10=1,"Freshman","")))))))) | R10: ="D:\IMS Images\Headshots\CBB\"&'Team Info'!$B$12&"\"&D10&"_"&C10&".png" -> D:\IMS Images\Headshots\CBB\LSU\_.png | S10: ="D:\IMS Images\ActionShots\CBB\"&'Team Info'!$B$12&"\"&D10&"_"&C10&".png" -> D:\IMS Images\ActionShots\CBB\LSU\_.png | T10: =C10&" "&D10 | U10: =LEFT(C10,1)&". "&D10 -> . | V10: =IF($J10="SR", "SR", IF($J10=4,"SR",IF($J10="JR", "JR", IF($J10=3,"JR",IF($J10="SO", "SO", IF($J10=2,"SO",IF($J10="FR", "FR",IF($J10=1,"FR","")))))))) | W10: =UPPER(T10) | X10: =UPPER(C10) | Y10: =UPPER(D10) | Z10: =UPPER(Q10)
A11: 8 | B11: 8 | O11: =INT(YEARFRAC($H11, TODAY())) -> 125 | P11: =IF($E11="G", "Guard", IF($E11="F", "Forward", IF($E11="C", "Center", ""))) | Q11: =IF($J11="SR", "Senior", IF($J11=4,"Senior",IF($J11="JR", "Junior", IF($J11=3,"Junior",IF($J11="SO", "Sophomore", IF($J11=2,"Sophomore",IF($J11="FR", "Freshman",IF($J11=1,"Freshman","")))))))) | R11: ="D:\IMS Images\Headshots\CBB\"&'Team Info'!$B$12&"\"&D11&"_"&C11&".png" -> D:\IMS Images\Headshots\CBB\LSU\_.png | S11: ="D:\IMS Images\ActionShots\CBB\"&'Team Info'!$B$12&"\"&D11&"_"&C11&".png" -> D:\IMS Images\ActionShots\CBB\LSU\_.png | T11: =C11&" "&D11 | U11: =LEFT(C11,1)&". "&D11 -> . | V11: =IF($J11="SR", "SR", IF($J11=4,"SR",IF($J11="JR", "JR", IF($J11=3,"JR",IF($J11="SO", "SO", IF($J11=2,"SO",IF($J11="FR", "FR",IF($J11=1,"FR","")))))))) | W11: =UPPER(T11) | X11: =UPPER(C11) | Y11: =UPPER(D11) | Z11: =UPPER(Q11)
A12: 9 | B12: 9 | O12: =INT(YEARFRAC($H12, TODAY())) -> 125 | P12: =IF($E12="G", "Guard", IF($E12="F", "Forward", IF($E12="C", "Center", ""))) | Q12: =IF($J12="SR", "Senior", IF($J12=4,"Senior",IF($J12="JR", "Junior", IF($J12=3,"Junior",IF($J12="SO", "Sophomore", IF($J12=2,"Sophomore",IF($J12="FR", "Freshman",IF($J12=1,"Freshman","")))))))) | R12: ="D:\IMS Images\Headshots\CBB\"&'Team Info'!$B$12&"\"&D12&"_"&C12&".png" -> D:\IMS Images\Headshots\CBB\LSU\_.png | S12: ="D:\IMS Images\ActionShots\CBB\"&'Team Info'!$B$12&"\"&D12&"_"&C12&".png" -> D:\IMS Images\ActionShots\CBB\LSU\_.png | T12: =C12&" "&D12 | U12: =LEFT(C12,1)&". "&D12 -> . | V12: =IF($J12="SR", "SR", IF($J12=4,"SR",IF($J12="JR", "JR", IF($J12=3,"JR",IF($J12="SO", "SO", IF($J12=2,"SO",IF($J12="FR", "FR",IF($J12=1,"FR","")))))))) | W12: =UPPER(T12) | X12: =UPPER(C12) | Y12: =UPPER(D12) | Z12: =UPPER(Q12)
A13: 10 | B13: 10 | O13: =INT(YEARFRAC($H13, TODAY())) -> 125 | P13: =IF($E13="G", "Guard", IF($E13="F", "Forward", IF($E13="C", "Center", ""))) | Q13: =IF($J13="SR", "Senior", IF($J13=4,"Senior",IF($J13="JR", "Junior", IF($J13=3,"Junior",IF($J13="SO", "Sophomore", IF($J13=2,"Sophomore",IF($J13="FR", "Freshman",IF($J13=1,"Freshman","")))))))) | R13: ="D:\IMS Images\Headshots\CBB\"&'Team Info'!$B$12&"\"&D13&"_"&C13&".png" -> D:\IMS Images\Headshots\CBB\LSU\_.png | S13: ="D:\IMS Images\ActionShots\CBB\"&'Team Info'!$B$12&"\"&D13&"_"&C13&".png" -> D:\IMS Images\ActionShots\CBB\LSU\_.png | T13: =C13&" "&D13 | U13: =LEFT(C13,1)&". "&D13 -> . | V13: =IF($J13="SR", "SR", IF($J13=4,"SR",IF($J13="JR", "JR", IF($J13=3,"JR",IF($J13="SO", "SO", IF($J13=2,"SO",IF($J13="FR", "FR",IF($J13=1,"FR","")))))))) | W13: =UPPER(T13) | X13: =UPPER(C13) | Y13: =UPPER(D13) | Z13: =UPPER(Q13)
A14: 11 | B14: 11 | O14: =INT(YEARFRAC($H14, TODAY())) -> 125 | P14: =IF($E14="G", "Guard", IF($E14="F", "Forward", IF($E14="C", "Center", ""))) | Q14: =IF($J14="SR", "Senior", IF($J14=4,"Senior",IF($J14="JR", "Junior", IF($J14=3,"Junior",IF($J14="SO", "Sophomore", IF($J14=2,"Sophomore",IF($J14="FR", "Freshman",IF($J14=1,"Freshman","")))))))) | R14: ="D:\IMS Images\Headshots\CBB\"&'Team Info'!$B$12&"\"&D14&"_"&C14&".png" -> D:\IMS Images\Headshots\CBB\LSU\_.png | S14: ="D:\IMS Images\ActionShots\CBB\"&'Team Info'!$B$12&"\"&D14&"_"&C14&".png" -> D:\IMS Images\ActionShots\CBB\LSU\_.png | T14: =C14&" "&D14 | U14: =LEFT(C14,1)&". "&D14 -> . | V14: =IF($J14="SR", "SR", IF($J14=4,"SR",IF($J14="JR", "JR", IF($J14=3,"JR",IF($J14="SO", "SO", IF($J14=2,"SO",IF($J14="FR", "FR",IF($J14=1,"FR","")))))))) | W14: =UPPER(T14) | X14: =UPPER(C14) | Y14: =UPPER(D14) | Z14: =UPPER(Q14)
A15: 12 | B15: 12 | O15: =INT(YEARFRAC($H15, TODAY())) -> 125 | P15: =IF($E15="G", "Guard", IF($E15="F", "Forward", IF($E15="C", "Center", ""))) | Q15: =IF($J15="SR", "Senior", IF($J15=4,"Senior",IF($J15="JR", "Junior", IF($J15=3,"Junior",IF($J15="SO", "Sophomore", IF($J15=2,"Sophomore",IF($J15="FR", "Freshman",IF($J15=1,"Freshman","")))))))) | R15: ="D:\IMS Images\Headshots\CBB\"&'Team Info'!$B$12&"\"&D15&"_"&C15&".png" -> D:\IMS Images\Headshots\CBB\LSU\_.png | S15: ="D:\IMS Images\ActionShots\CBB\"&'Team Info'!$B$12&"\"&D15&"_"&C15&".png" -> D:\IMS Images\ActionShots\CBB\LSU\_.png | T15: =C15&" "&D15 | U15: =LEFT(C15,1)&". "&D15 -> . | V15: =IF($J15="SR", "SR", IF($J15=4,"SR",IF($J15="JR", "JR", IF($J15=3,"JR",IF($J15="SO", "SO", IF($J15=2,"SO",IF($J15="FR", "FR",IF($J15=1,"FR","")))))))) | W15: =UPPER(T15) | X15: =UPPER(C15) | Y15: =UPPER(D15) | Z15: =UPPER(Q15)
A16: 13 | B16: 13 | O16: =INT(YEARFRAC($H16, TODAY())) -> 125 | P16: =IF($E16="G", "Guard", IF($E16="F", "Forward", IF($E16="C", "Center", ""))) | Q16: =IF($J16="SR", "Senior", IF($J16=4,"Senior",IF($J16="JR", "Junior", IF($J16=3,"Junior",IF($J16="SO", "Sophomore", IF($J16=2,"Sophomore",IF($J16="FR", "Freshman",IF($J16=1,"Freshman","")))))))) | R16: ="D:\IMS Images\Headshots\CBB\"&'Team Info'!$B$12&"\"&D16&"_"&C16&".png" -> D:\IMS Images\Headshots\CBB\LSU\_.png | S16: ="D:\IMS Images\ActionShots\CBB\"&'Team Info'!$B$12&"\"&D16&"_"&C16&".png" -> D:\IMS Images\ActionShots\CBB\LSU\_.png | T16: =C16&" "&D16 | U16: =LEFT(C16,1)&". "&D16 -> . | V16: =IF($J16="SR", "SR", IF($J16=4,"SR",IF($J16="JR", "JR", IF($J16=3,"JR",IF($J16="SO", "SO", IF($J16=2,"SO",IF($J16="FR", "FR",IF($J16=1,"FR","")))))))) | W16: =UPPER(T16) | X16: =UPPER(C16) | Y16: =UPPER(D16) | Z16: =UPPER(Q16)
A17: 14 | B17: 14 | O17: =INT(YEARFRAC($H17, TODAY())) -> 125 | P17: =IF($E17="G", "Guard", IF($E17="F", "Forward", IF($E17="C", "Center", ""))) | Q17: =IF($J17="SR", "Senior", IF($J17=4,"Senior",IF($J17="JR", "Junior", IF($J17=3,"Junior",IF($J17="SO", "Sophomore", IF($J17=2,"Sophomore",IF($J17="FR", "Freshman",IF($J17=1,"Freshman","")))))))) | R17: ="D:\IMS Images\Headshots\CBB\"&'Team Info'!$B$12&"\"&D17&"_"&C17&".png" -> D:\IMS Images\Headshots\CBB\LSU\_.png | S17: ="D:\IMS Images\ActionShots\CBB\"&'Team Info'!$B$12&"\"&D17&"_"&C17&".png" -> D:\IMS Images\ActionShots\CBB\LSU\_.png | T17: =C17&" "&D17 | U17: =LEFT(C17,1)&". "&D17 -> . | V17: =IF($J17="SR", "SR", IF($J17=4,"SR",IF($J17="JR", "JR", IF($J17=3,"JR",IF($J17="SO", "SO", IF($J17=2,"SO",IF($J17="FR", "FR",IF($J17=1,"FR","")))))))) | W17: =UPPER(T17) | X17: =UPPER(C17) | Y17: =UPPER(D17) | Z17: =UPPER(Q17)
A18: 15 | B18: 15 | O18: =INT(YEARFRAC($H18, TODAY())) -> 125 | P18: =IF($E18="G", "Guard", IF($E18="F", "Forward", IF($E18="C", "Center", ""))) | Q18: =IF($J18="SR", "Senior", IF($J18=4,"Senior",IF($J18="JR", "Junior", IF($J18=3,"Junior",IF($J18="SO", "Sophomore", IF($J18=2,"Sophomore",IF($J18="FR", "Freshman",IF($J18=1,"Freshman","")))))))) | R18: ="D:\IMS Images\Headshots\CBB\"&'Team Info'!$B$12&"\"&D18&"_"&C18&".png" -> D:\IMS Images\Headshots\CBB\LSU\_.png | S18: ="D:\IMS Images\ActionShots\CBB\"&'Team Info'!$B$12&"\"&D18&"_"&C18&".png" -> D:\IMS Images\ActionShots\CBB\LSU\_.png | T18: =C18&" "&D18 | U18: =LEFT(C18,1)&". "&D18 -> . | V18: =IF($J18="SR", "SR", IF($J18=4,"SR",IF($J18="JR", "JR", IF($J18=3,"JR",IF($J18="SO", "SO", IF($J18=2,"SO",IF($J18="FR", "FR",IF($J18=1,"FR","")))))))) | W18: =UPPER(T18) | X18: =UPPER(C18) | Y18: =UPPER(D18) | Z18: =UPPER(Q18)
A19: 16 | B19: 16 | O19: =INT(YEARFRAC($H19, TODAY())) -> 125 | P19: =IF($E19="G", "Guard", IF($E19="F", "Forward", IF($E19="C", "Center", ""))) | Q19: =IF($J19="SR", "Senior", IF($J19=4,"Senior",IF($J19="JR", "Junior", IF($J19=3,"Junior",IF($J19="SO", "Sophomore", IF($J19=2,"Sophomore",IF($J19="FR", "Freshman",IF($J19=1,"Freshman","")))))))) | R19: ="D:\IMS Images\Headshots\CBB\"&'Team Info'!$B$12&"\"&D19&"_"&C19&".png" -> D:\IMS Images\Headshots\CBB\LSU\_.png | S19: ="D:\IMS Images\ActionShots\CBB\"&'Team Info'!$B$12&"\"&D19&"_"&C19&".png" -> D:\IMS Images\ActionShots\CBB\LSU\_.png | T19: =C19&" "&D19 | U19: =LEFT(C19,1)&". "&D19 -> . | V19: =IF($J19="SR", "SR", IF($J19=4,"SR",IF($J19="JR", "JR", IF($J19=3,"JR",IF($J19="SO", "SO", IF($J19=2,"SO",IF($J19="FR", "FR",IF($J19=1,"FR","")))))))) | W19: =UPPER(T19) | X19: =UPPER(C19) | Y19: =UPPER(D19) | Z19: =UPPER(Q19)
A20: 17 | B20: 17 | O20: =INT(YEARFRAC($H20, TODAY())) -> 125 | P20: =IF($E20="G", "Guard", IF($E20="F", "Forward", IF($E20="C", "Center", ""))) | Q20: =IF($J20="SR", "Senior", IF($J20=4,"Senior",IF($J20="JR", "Junior", IF($J20=3,"Junior",IF($J20="SO", "Sophomore", IF($J20=2,"Sophomore",IF($J20="FR", "Freshman",IF($J20=1,"Freshman","")))))))) | R20: ="D:\IMS Images\Headshots\CBB\"&'Team Info'!$B$12&"\"&D20&"_"&C20&".png" -> D:\IMS Images\Headshots\CBB\LSU\_.png | S20: ="D:\IMS Images\ActionShots\CBB\"&'Team Info'!$B$12&"\"&D20&"_"&C20&".png" -> D:\IMS Images\ActionShots\CBB\LSU\_.png | T20: =C20&" "&D20 | U20: =LEFT(C20,1)&". "&D20 -> . | V20: =IF($J20="SR", "SR", IF($J20=4,"SR",IF($J20="JR", "JR", IF($J20=3,"JR",IF($J20="SO", "SO", IF($J20=2,"SO",IF($J20="FR", "FR",IF($J20=1,"FR","")))))))) | W20: =UPPER(T20) | X20: =UPPER(C20) | Y20: =UPPER(D20) | Z20: =UPPER(Q20)
A21: 18 | B21: 18 | O21: =INT(YEARFRAC($H21, TODAY())) -> 125 | P21: =IF($E21="G", "Guard", IF($E21="F", "Forward", IF($E21="C", "Center", ""))) | Q21: =IF($J21="SR", "Senior", IF($J21=4,"Senior",IF($J21="JR", "Junior", IF($J21=3,"Junior",IF($J21="SO", "Sophomore", IF($J21=2,"Sophomore",IF($J21="FR", "Freshman",IF($J21=1,"Freshman","")))))))) | R21: ="D:\IMS Images\Headshots\CBB\"&'Team Info'!$B$12&"\"&D21&"_"&C21&".png" -> D:\IMS Images\Headshots\CBB\LSU\_.png | S21: ="D:\IMS Images\ActionShots\CBB\"&'Team Info'!$B$12&"\"&D21&"_"&C21&".png" -> D:\IMS Images\ActionShots\CBB\LSU\_.png | T21: =C21&" "&D21 | U21: =LEFT(C21,1)&". "&D21 -> . | V21: =IF($J21="SR", "SR", IF($J21=4,"SR",IF($J21="JR", "JR", IF($J21=3,"JR",IF($J21="SO", "SO", IF($J21=2,"SO",IF($J21="FR", "FR",IF($J21=1,"FR","")))))))) | W21: =UPPER(T21) | X21: =UPPER(C21) | Y21: =UPPER(D21) | Z21: =UPPER(Q21)
... A92: 89 | B92: 89 | O92: =INT(YEARFRAC($H92, TODAY())) -> 125 | P92: =IF($E92="G", "Guard", IF($E92="F", "Forward", IF($E92="C", "Center", ""))) | Q92: =IF($J92="SR", "Senior", IF($J92=4,"Senior",IF($J92="JR", "Junior", IF($J92=3,"Junior",IF($J92="SO", "Sophomore", IF($J92=2,"Sophomore",IF($J92="FR", "Freshman",IF($J92=1,"Freshman","")))))))) | R92: ="D:\IMS Images\Headshots\CBB\"&'Team Info'!$B$12&"\"&D92&"_"&C92&".png" -> D:\IMS Images\Headshots\CBB\LSU\_.png | S92: ="D:\IMS Images\ActionShots\CBB\"&'Team Info'!$B$12&"\"&D92&"_"&C92&".png" -> D:\IMS Images\ActionShots\CBB\LSU\_.png | T92: =C92&" "&D92 | U92: =LEFT(C92,1)&". "&D92 -> . | V92: =IF($J92="SR", "SR", IF($J92=4,"SR",IF($J92="JR", "JR", IF($J92=3,"JR",IF($J92="SO", "SO", IF($J92=2,"SO",IF($J92="FR", "FR",IF($J92=1,"FR","")))))))) | W92: =UPPER(T92) | X92: =UPPER(C92) | Y92: =UPPER(D92) | Z92: =UPPER(Q92)
A93: 90 | B93: 0 | C93: =IF(C$104=0,"",C$104) | D93: =IF(D$104=0,"",D$104) | E93: =IF(E$104=0,"",E$104) | F93: =IF(F$104=0,"",F$104) | G93: =IF(G$104=0,"",G$104) | H93: =IF(H$104=0,"",H$104) | I93: =IF(I$104=0,"",I$104) | J93: =IF(J$104=0,"",J$104) | ... M93: =IF(M$104=0,"",M$104) | O93: =INT(YEARFRAC($H93, TODAY())) -> #VALUE! | P93: =IF($E93="G", "Guard", IF($E93="F", "Forward", IF($E93="C", "Center", ""))) | Q93: =IF($J93="SR", "Senior", IF($J93=4,"Senior",IF($J93="JR", "Junior", IF($J93=3,"Junior",IF($J93="SO", "Sophomore", IF($J93=2,"Sophomore",IF($J93="FR", "Freshman",IF($J93=1,"Freshman","")))))))) | R93: ="D:\IMS Images\Headshots\CBB\"&'Team Info'!$B$12&"\"&D93&"_"&C93&".png" -> D:\IMS Images\Headshots\CBB\LSU\_.png | S93: ="D:\IMS Images\ActionShots\CBB\"&'Team Info'!$B$12&"\"&D93&"_"&C93&".png" -> D:\IMS Images\ActionShots\CBB\LSU\_.png | T93: =C93&" "&D93 | U93: =LEFT(C93,1)&". "&D93 -> . | V93: =IF($J93="SR", "SR", IF($J93=4,"SR",IF($J93="JR", "JR", IF($J93=3,"JR",IF($J93="SO", "SO", IF($J93=2,"SO",IF($J93="FR", "FR",IF($J93=1,"FR","")))))))) | W93: =UPPER(T93) | X93: =UPPER(C93) | Y93: =UPPER(D93) | Z93: =UPPER(Q93)
A94: 91 | B94: 91 | O94: =INT(YEARFRAC($H94, TODAY())) -> 125 | P94: =IF($E94="G", "Guard", IF($E94="F", "Forward", IF($E94="C", "Center", ""))) | Q94: =IF($J94="SR", "Senior", IF($J94=4,"Senior",IF($J94="JR", "Junior", IF($J94=3,"Junior",IF($J94="SO", "Sophomore", IF($J94=2,"Sophomore",IF($J94="FR", "Freshman",IF($J94=1,"Freshman","")))))))) | R94: ="D:\IMS Images\Headshots\CBB\"&'Team Info'!$B$12&"\"&D94&"_"&C94&".png" -> D:\IMS Images\Headshots\CBB\LSU\_.png | S94: ="D:\IMS Images\ActionShots\CBB\"&'Team Info'!$B$12&"\"&D94&"_"&C94&".png" -> D:\IMS Images\ActionShots\CBB\LSU\_.png | T94: =C94&" "&D94 | U94: =LEFT(C94,1)&". "&D94 -> . | V94: =IF($J94="SR", "SR", IF($J94=4,"SR",IF($J94="JR", "JR", IF($J94=3,"JR",IF($J94="SO", "SO", IF($J94=2,"SO",IF($J94="FR", "FR",IF($J94=1,"FR","")))))))) | W94: =UPPER(T94) | X94: =UPPER(C94) | Y94: =UPPER(D94) | Z94: =UPPER(Q94)
A95: 92 | B95: 92 | O95: =INT(YEARFRAC($H95, TODAY())) -> 125 | P95: =IF($E95="G", "Guard", IF($E95="F", "Forward", IF($E95="C", "Center", ""))) | Q95: =IF($J95="SR", "Senior", IF($J95=4,"Senior",IF($J95="JR", "Junior", IF($J95=3,"Junior",IF($J95="SO", "Sophomore", IF($J95=2,"Sophomore",IF($J95="FR", "Freshman",IF($J95=1,"Freshman","")))))))) | R95: ="D:\IMS Images\Headshots\CBB\"&'Team Info'!$B$12&"\"&D95&"_"&C95&".png" -> D:\IMS Images\Headshots\CBB\LSU\_.png | S95: ="D:\IMS Images\ActionShots\CBB\"&'Team Info'!$B$12&"\"&D95&"_"&C95&".png" -> D:\IMS Images\ActionShots\CBB\LSU\_.png | T95: =C95&" "&D95 | U95: =LEFT(C95,1)&". "&D95 -> . | V95: =IF($J95="SR", "SR", IF($J95=4,"SR",IF($J95="JR", "JR", IF($J95=3,"JR",IF($J95="SO", "SO", IF($J95=2,"SO",IF($J95="FR", "FR",IF($J95=1,"FR","")))))))) | W95: =UPPER(T95) | X95: =UPPER(C95) | Y95: =UPPER(D95) | Z95: =UPPER(Q95)
A96: 93 | B96: 93 | O96: =INT(YEARFRAC($H96, TODAY())) -> 125 | P96: =IF($E96="G", "Guard", IF($E96="F", "Forward", IF($E96="C", "Center", ""))) | Q96: =IF($J96="SR", "Senior", IF($J96=4,"Senior",IF($J96="JR", "Junior", IF($J96=3,"Junior",IF($J96="SO", "Sophomore", IF($J96=2,"Sophomore",IF($J96="FR", "Freshman",IF($J96=1,"Freshman","")))))))) | R96: ="D:\IMS Images\Headshots\CBB\"&'Team Info'!$B$12&"\"&D96&"_"&C96&".png" -> D:\IMS Images\Headshots\CBB\LSU\_.png | S96: ="D:\IMS Images\ActionShots\CBB\"&'Team Info'!$B$12&"\"&D96&"_"&C96&".png" -> D:\IMS Images\ActionShots\CBB\LSU\_.png | T96: =C96&" "&D96 | U96: =LEFT(C96,1)&". "&D96 -> . | V96: =IF($J96="SR", "SR", IF($J96=4,"SR",IF($J96="JR", "JR", IF($J96=3,"JR",IF($J96="SO", "SO", IF($J96=2,"SO",IF($J96="FR", "FR",IF($J96=1,"FR","")))))))) | W96: =UPPER(T96) | X96: =UPPER(C96) | Y96: =UPPER(D96) | Z96: =UPPER(Q96)
A97: 94 | B97: 94 | O97: =INT(YEARFRAC($H97, TODAY())) -> 125 | P97: =IF($E97="G", "Guard", IF($E97="F", "Forward", IF($E97="C", "Center", ""))) | Q97: =IF($J97="SR", "Senior", IF($J97=4,"Senior",IF($J97="JR", "Junior", IF($J97=3,"Junior",IF($J97="SO", "Sophomore", IF($J97=2,"Sophomore",IF($J97="FR", "Freshman",IF($J97=1,"Freshman","")))))))) | R97: ="D:\IMS Images\Headshots\CBB\"&'Team Info'!$B$12&"\"&D97&"_"&C97&".png" -> D:\IMS Images\Headshots\CBB\LSU\_.png | S97: ="D:\IMS Images\ActionShots\CBB\"&'Team Info'!$B$12&"\"&D97&"_"&C97&".png" -> D:\IMS Images\ActionShots\CBB\LSU\_.png | T97: =C97&" "&D97 | U97: =LEFT(C97,1)&". "&D97 -> . | V97: =IF($J97="SR", "SR", IF($J97=4,"SR",IF($J97="JR", "JR", IF($J97=3,"JR",IF($J97="SO", "SO", IF($J97=2,"SO",IF($J97="FR", "FR",IF($J97=1,"FR","")))))))) | W97: =UPPER(T97) | X97: =UPPER(C97) | Y97: =UPPER(D97) | Z97: =UPPER(Q97)
A98: 95 | B98: 95 | O98: =INT(YEARFRAC($H98, TODAY())) -> 125 | P98: =IF($E98="G", "Guard", IF($E98="F", "Forward", IF($E98="C", "Center", ""))) | Q98: =IF($J98="SR", "Senior", IF($J98=4,"Senior",IF($J98="JR", "Junior", IF($J98=3,"Junior",IF($J98="SO", "Sophomore", IF($J98=2,"Sophomore",IF($J98="FR", "Freshman",IF($J98=1,"Freshman","")))))))) | R98: ="D:\IMS Images\Headshots\CBB\"&'Team Info'!$B$12&"\"&D98&"_"&C98&".png" -> D:\IMS Images\Headshots\CBB\LSU\_.png | S98: ="D:\IMS Images\ActionShots\CBB\"&'Team Info'!$B$12&"\"&D98&"_"&C98&".png" -> D:\IMS Images\ActionShots\CBB\LSU\_.png | T98: =C98&" "&D98 | U98: =LEFT(C98,1)&". "&D98 -> . | V98: =IF($J98="SR", "SR", IF($J98=4,"SR",IF($J98="JR", "JR", IF($J98=3,"JR",IF($J98="SO", "SO", IF($J98=2,"SO",IF($J98="FR", "FR",IF($J98=1,"FR","")))))))) | W98: =UPPER(T98) | X98: =UPPER(C98) | Y98: =UPPER(D98) | Z98: =UPPER(Q98)
A99: 96 | B99: 96 | O99: =INT(YEARFRAC($H99, TODAY())) -> 125 | P99: =IF($E99="G", "Guard", IF($E99="F", "Forward", IF($E99="C", "Center", ""))) | Q99: =IF($J99="SR", "Senior", IF($J99=4,"Senior",IF($J99="JR", "Junior", IF($J99=3,"Junior",IF($J99="SO", "Sophomore", IF($J99=2,"Sophomore",IF($J99="FR", "Freshman",IF($J99=1,"Freshman","")))))))) | R99: ="D:\IMS Images\Headshots\CBB\"&'Team Info'!$B$12&"\"&D99&"_"&C99&".png" -> D:\IMS Images\Headshots\CBB\LSU\_.png | S99: ="D:\IMS Images\ActionShots\CBB\"&'Team Info'!$B$12&"\"&D99&"_"&C99&".png" -> D:\IMS Images\ActionShots\CBB\LSU\_.png | T99: =C99&" "&D99 | U99: =LEFT(C99,1)&". "&D99 -> . | V99: =IF($J99="SR", "SR", IF($J99=4,"SR",IF($J99="JR", "JR", IF($J99=3,"JR",IF($J99="SO", "SO", IF($J99=2,"SO",IF($J99="FR", "FR",IF($J99=1,"FR","")))))))) | W99: =UPPER(T99) | X99: =UPPER(C99) | Y99: =UPPER(D99) | Z99: =UPPER(Q99)
A100: 97 | B100: 97 | O100: =INT(YEARFRAC($H100, TODAY())) -> 125 | P100: =IF($E100="G", "Guard", IF($E100="F", "Forward", IF($E100="C", "Center", ""))) | Q100: =IF($J100="SR", "Senior", IF($J100=4,"Senior",IF($J100="JR", "Junior", IF($J100=3,"Junior",IF($J100="SO", "Sophomore", IF($J100=2,"Sophomore",IF($J100="FR", "Freshman",IF($J100=1,"Freshman","")))))))) | R100: ="D:\IMS Images\Headshots\CBB\"&'Team Info'!$B$12&"\"&D100&"_"&C100&".png" -> D:\IMS Images\Headshots\CBB\LSU\_.png | S100: ="D:\IMS Images\ActionShots\CBB\"&'Team Info'!$B$12&"\"&D100&"_"&C100&".png" -> D:\IMS Images\ActionShots\CBB\LSU\_.png | T100: =C100&" "&D100 | U100: =LEFT(C100,1)&". "&D100 -> . | V100: =IF($J100="SR", "SR", IF($J100=4,"SR",IF($J100="JR", "JR", IF($J100=3,"JR",IF($J100="SO", "SO", IF($J100=2,"SO",IF($J100="FR", "FR",IF($J100=1,"FR","")))))))) | W100: =UPPER(T100) | X100: =UPPER(C100) | Y100: =UPPER(D100) | Z100: =UPPER(Q100)
A101: 98 | B101: 98 | O101: =INT(YEARFRAC($H101, TODAY())) -> 125 | P101: =IF($E101="G", "Guard", IF($E101="F", "Forward", IF($E101="C", "Center", ""))) | Q101: =IF($J101="SR", "Senior", IF($J101=4,"Senior",IF($J101="JR", "Junior", IF($J101=3,"Junior",IF($J101="SO", "Sophomore", IF($J101=2,"Sophomore",IF($J101="FR", "Freshman",IF($J101=1,"Freshman","")))))))) | R101: ="D:\IMS Images\Headshots\CBB\"&'Team Info'!$B$12&"\"&D101&"_"&C101&".png" -> D:\IMS Images\Headshots\CBB\LSU\_.png | S101: ="D:\IMS Images\ActionShots\CBB\"&'Team Info'!$B$12&"\"&D101&"_"&C101&".png" -> D:\IMS Images\ActionShots\CBB\LSU\_.png | T101: =C101&" "&D101 | U101: =LEFT(C101,1)&". "&D101 -> . | V101: =IF($J101="SR", "SR", IF($J101=4,"SR",IF($J101="JR", "JR", IF($J101=3,"JR",IF($J101="SO", "SO", IF($J101=2,"SO",IF($J101="FR", "FR",IF($J101=1,"FR","")))))))) | W101: =UPPER(T101) | X101: =UPPER(C101) | Y101: =UPPER(D101) | Z101: =UPPER(Q101)
A102: 99 | B102: 00 | C102: =IF(C$104=0,"",C$104) | D102: =IF(D$104=0,"",D$104) | E102: =IF(E$104=0,"",E$104) | F102: =IF(F$104=0,"",F$104) | G102: =IF(G$104=0,"",G$104) | H102: =IF(H$104=0,"",H$104) | I102: =IF(I$104=0,"",I$104) | J102: =IF(J$104=0,"",J$104) | ... M102: =IF(M$104=0,"",M$104) | O102: =INT(YEARFRAC($H102, TODAY())) -> #VALUE! | P102: =IF($E102="G", "Guard", IF($E102="F", "Forward", IF($E102="C", "Center", ""))) | Q102: =IF($J102="SR", "Senior", IF($J102=4,"Senior",IF($J102="JR", "Junior", IF($J102=3,"Junior",IF($J102="SO", "Sophomore", IF($J102=2,"Sophomore",IF($J102="FR", "Freshman",IF($J102=1,"Freshman","")))))))) | R102: ="D:\IMS Images\Headshots\CBB\"&'Team Info'!$B$12&"\"&D102&"_"&C102&".png" -> D:\IMS Images\Headshots\CBB\LSU\_.png | S102: ="D:\IMS Images\ActionShots\CBB\"&'Team Info'!$B$12&"\"&D102&"_"&C102&".png" -> D:\IMS Images\ActionShots\CBB\LSU\_.png | T102: =C102&" "&D102 | U102: =LEFT(C102,1)&". "&D102 -> . | V102: =IF($J102="SR", "SR", IF($J102=4,"SR",IF($J102="JR", "JR", IF($J102=3,"JR",IF($J102="SO", "SO", IF($J102=2,"SO",IF($J102="FR", "FR",IF($J102=1,"FR","")))))))) | W102: =UPPER(T102) | X102: =UPPER(C102) | Y102: =UPPER(D102) | Z102: =UPPER(Q102)
A103: Enter Player 0/00 info below. It will autofill rows 90 & 99. | Q103: =IF($J103="SR", "Senior", IF($J103=4,"Senior",IF($J103="JR", "Junior", IF($J103=3,"Junior",IF($J103="SO", "Sophomore", IF($J103=2,"Sophomore",IF($J103="FR", "Freshman",IF($J103=1,"Freshman",""))))))))
B104: 0 | Q104: =IF($J104="SR", "Senior", IF($J104=4,"Senior",IF($J104="JR", "Junior", IF($J104=3,"Junior",IF($J104="SO", "Sophomore", IF($J104=2,"Sophomore",IF($J104="FR", "Freshman",IF($J104=1,"Freshman",""))))))))

Sheet Lineup
B1: JERSEY NUMBER | C1: FIRST NAME | D1: LAST NAME | E1: FULL NAME | F1: POS | G1: POS SHORT | H1: YEAR | I1: HEIGHT | J1: FULL YEAR | K1: HOMETOWN | L1: HEADSHOT
A2: 1 | B2: 1 | C2: =IF(B2=0,VLOOKUP(90,ROSTER,3,FALSE),VLOOKUP(B2,ROSTER,3,FALSE)) -> First | D2: =IF(B2=0,VLOOKUP(90,ROSTER,4,FALSE),VLOOKUP(B2,ROSTER,4,FALSE)) -> Last | E2: =IF(B2=0,VLOOKUP(90,ROSTER,20,FALSE),VLOOKUP(B2,ROSTER,20,FALSE)) -> First Last | F2: =IF(B2=0,VLOOKUP(90,ROSTER,16,FALSE),VLOOKUP(B2,ROSTER,16,FALSE)) -> Guard | G2: =IF(B2=0,VLOOKUP(90,ROSTER,5,FALSE),VLOOKUP(B2,ROSTER,5,FALSE)) -> G | H2: =IF(B2=0,VLOOKUP(90,ROSTER,22,FALSE),VLOOKUP(B2,ROSTER,22,FALSE)) -> FR | I2: =IF(B2=0,VLOOKUP(90,ROSTER,6,FALSE),VLOOKUP(B2,ROSTER,6,FALSE)) -> 5'10" | J2: =IF(B2=0,VLOOKUP(90,ROSTER,17,FALSE),VLOOKUP(B2,ROSTER,17,FALSE)) -> Freshman | K2: =IF(B2=0,VLOOKUP(90,ROSTER,9,FALSE),VLOOKUP(B2,ROSTER,9,FALSE)) -> Charlotte, NC | L2: ="D:\IMS Images\Headshots\CBB\"&'Team Info'!$B$12&"\"&D2&"_"&C2&".png" -> D:\IMS Images\Headshots\CBB\LSU\Last_First.png
A3: 2 | B3: 2 | C3: =IF(B3=0,VLOOKUP(90,ROSTER,3,FALSE),VLOOKUP(B3,ROSTER,3,FALSE)) -> 0 | D3: =IF(B3=0,VLOOKUP(90,ROSTER,4,FALSE),VLOOKUP(B3,ROSTER,4,FALSE)) -> 0 | E3: =IF(B3=0,VLOOKUP(90,ROSTER,20,FALSE),VLOOKUP(B3,ROSTER,20,FALSE)) | F3: =IF(B3=0,VLOOKUP(90,ROSTER,16,FALSE),VLOOKUP(B3,ROSTER,16,FALSE)) | G3: =IF(B3=0,VLOOKUP(90,ROSTER,5,FALSE),VLOOKUP(B3,ROSTER,5,FALSE)) -> 0 | H3: =IF(B3=0,VLOOKUP(90,ROSTER,22,FALSE),VLOOKUP(B3,ROSTER,22,FALSE)) | I3: =IF(B3=0,VLOOKUP(90,ROSTER,6,FALSE),VLOOKUP(B3,ROSTER,6,FALSE)) -> 0 | J3: =IF(B3=0,VLOOKUP(90,ROSTER,17,FALSE),VLOOKUP(B3,ROSTER,17,FALSE)) | K3: =IF(B3=0,VLOOKUP(90,ROSTER,9,FALSE),VLOOKUP(B3,ROSTER,9,FALSE)) -> 0 | L3: ="D:\IMS Images\Headshots\CBB\"&'Team Info'!$B$12&"\"&D3&"_"&C3&".png" -> D:\IMS Images\Headshots\CBB\LSU\0_0.png
A4: 3 | B4: 3 | C4: =IF(B4=0,VLOOKUP(90,ROSTER,3,FALSE),VLOOKUP(B4,ROSTER,3,FALSE)) -> 0 | D4: =IF(B4=0,VLOOKUP(90,ROSTER,4,FALSE),VLOOKUP(B4,ROSTER,4,FALSE)) -> 0 | E4: =IF(B4=0,VLOOKUP(90,ROSTER,20,FALSE),VLOOKUP(B4,ROSTER,20,FALSE)) | F4: =IF(B4=0,VLOOKUP(90,ROSTER,16,FALSE),VLOOKUP(B4,ROSTER,16,FALSE)) | G4: =IF(B4=0,VLOOKUP(90,ROSTER,5,FALSE),VLOOKUP(B4,ROSTER,5,FALSE)) -> 0 | H4: =IF(B4=0,VLOOKUP(90,ROSTER,22,FALSE),VLOOKUP(B4,ROSTER,22,FALSE)) | I4: =IF(B4=0,VLOOKUP(90,ROSTER,6,FALSE),VLOOKUP(B4,ROSTER,6,FALSE)) -> 0 | J4: =IF(B4=0,VLOOKUP(90,ROSTER,17,FALSE),VLOOKUP(B4,ROSTER,17,FALSE)) | K4: =IF(B4=0,VLOOKUP(90,ROSTER,9,FALSE),VLOOKUP(B4,ROSTER,9,FALSE)) -> 0 | L4: ="D:\IMS Images\Headshots\CBB\"&'Team Info'!$B$12&"\"&D4&"_"&C4&".png" -> D:\IMS Images\Headshots\CBB\LSU\0_0.png
A5: 4 | B5: 4 | C5: =IF(B5=0,VLOOKUP(90,ROSTER,3,FALSE),VLOOKUP(B5,ROSTER,3,FALSE)) -> 0 | D5: =IF(B5=0,VLOOKUP(90,ROSTER,4,FALSE),VLOOKUP(B5,ROSTER,4,FALSE)) -> 0 | E5: =IF(B5=0,VLOOKUP(90,ROSTER,20,FALSE),VLOOKUP(B5,ROSTER,20,FALSE)) | F5: =IF(B5=0,VLOOKUP(90,ROSTER,16,FALSE),VLOOKUP(B5,ROSTER,16,FALSE)) | G5: =IF(B5=0,VLOOKUP(90,ROSTER,5,FALSE),VLOOKUP(B5,ROSTER,5,FALSE)) -> 0 | H5: =IF(B5=0,VLOOKUP(90,ROSTER,22,FALSE),VLOOKUP(B5,ROSTER,22,FALSE)) | I5: =IF(B5=0,VLOOKUP(90,ROSTER,6,FALSE),VLOOKUP(B5,ROSTER,6,FALSE)) -> 0 | J5: =IF(B5=0,VLOOKUP(90,ROSTER,17,FALSE),VLOOKUP(B5,ROSTER,17,FALSE)) | K5: =IF(B5=0,VLOOKUP(90,ROSTER,9,FALSE),VLOOKUP(B5,ROSTER,9,FALSE)) -> 0 | L5: ="D:\IMS Images\Headshots\CBB\"&'Team Info'!$B$12&"\"&D5&"_"&C5&".png" -> D:\IMS Images\Headshots\CBB\LSU\0_0.png
A6: 5 | B6: 5 | C6: =IF(B6=0,VLOOKUP(90,ROSTER,3,FALSE),VLOOKUP(B6,ROSTER,3,FALSE)) -> 0 | D6: =IF(B6=0,VLOOKUP(90,ROSTER,4,FALSE),VLOOKUP(B6,ROSTER,4,FALSE)) -> 0 | E6: =IF(B6=0,VLOOKUP(90,ROSTER,20,FALSE),VLOOKUP(B6,ROSTER,20,FALSE)) | F6: =IF(B6=0,VLOOKUP(90,ROSTER,16,FALSE),VLOOKUP(B6,ROSTER,16,FALSE)) | G6: =IF(B6=0,VLOOKUP(90,ROSTER,5,FALSE),VLOOKUP(B6,ROSTER,5,FALSE)) -> 0 | H6: =IF(B6=0,VLOOKUP(90,ROSTER,22,FALSE),VLOOKUP(B6,ROSTER,22,FALSE)) | I6: =IF(B6=0,VLOOKUP(90,ROSTER,6,FALSE),VLOOKUP(B6,ROSTER,6,FALSE)) -> 0 | J6: =IF(B6=0,VLOOKUP(90,ROSTER,17,FALSE),VLOOKUP(B6,ROSTER,17,FALSE)) | K6: =IF(B6=0,VLOOKUP(90,ROSTER,9,FALSE),VLOOKUP(B6,ROSTER,9,FALSE)) -> 0 | L6: ="D:\IMS Images\Headshots\CBB\"&'Team Info'!$B$12&"\"&D6&"_"&C6&".png" -> D:\IMS Images\Headshots\CBB\LSU\0_0.png
B8: ONLY FILL IN THE JERSEY NUMBER. ALL OTHER INFORMATION WILL POPULATE BASED OFF JERSEY NUMBER. | L8: Headshot Path for XPression Only

Sheet Player Stats
A1: ALL STAT INFORMATION WILL POPULATE DROP-DOWN MENUS ON THE SEASON TAB. ON THE SEASON TAB JUST PICK THE THREE CATEGORIES TO POPULATE
A2: Jersey | B2: Display Jersey | C2: Player Name | D2: POINTS | E2: FIELD GOALS | F2: 3PT% | G2: FT% | H2: REBOUNDS | I2: ASSISTS | J2: BLOCKS | K2: STEALS | L2: MINUTES
A3: =Roster!$A4 -> 1 | B3: =Roster!B4 -> 1 | C3: =Roster!$T4 -> First Last | D3: 1.3 | E3: 47% | F3: 33% | G3: 100% | H3: 1.3 | I3: 1.1 | J3: 0.0 | K3: 0.3
A4: =Roster!$A5 -> 2 | B4: =Roster!B5 -> 2 | C4: =Roster!$T5
A5: =Roster!$A6 -> 3 | B5: =Roster!B6 -> 3 | C5: =Roster!$T6
A6: =Roster!$A7 -> 4 | B6: =Roster!B7 -> 4 | C6: =Roster!$T7
A7: =Roster!$A8 -> 5 | B7: =Roster!B8 -> 5 | C7: =Roster!$T8
A8: =Roster!$A9 -> 6 | B8: =Roster!B9 -> 6 | C8: =Roster!$T9
A9: =Roster!$A10 -> 7 | B9: =Roster!B10 -> 7 | C9: =Roster!$T10
A10: =Roster!$A11 -> 8 | B10: =Roster!B11 -> 8 | C10: =Roster!$T11
A11: =Roster!$A12 -> 9 | B11: =Roster!B12 -> 9 | C11: =Roster!$T12
A12: =Roster!$A13 -> 10 | B12: =Roster!B13 -> 10 | C12: =Roster!$T13
A13: =Roster!$A14 -> 11 | B13: =Roster!B14 -> 11 | C13: =Roster!$T14
A14: =Roster!$A15 -> 12 | B14: =Roster!B15 -> 12 | C14: =Roster!$T15
A15: =Roster!$A16 -> 13 | B15: =Roster!B16 -> 13 | C15: =Roster!$T16
... A91: =Roster!$A92 -> 89 | B91: =Roster!B92 -> 89 | C91: =Roster!$T92
A92: =Roster!$A93 -> 90 | B92: =Roster!B93 -> 0 | C92: =C104 | D92: =D104 -> 0 | E92: =E104 -> 0 | F92: =F104 -> 0 | G92: =G104 -> 0 | H92: =H104 -> 0 | I92: =I104 -> 0 | J92: =J104 -> 0 | ... L92: =L104 -> 0
A93: =Roster!$A94 -> 91 | B93: =Roster!B94 -> 91 | C93: =Roster!$T94
A94: =Roster!$A95 -> 92 | B94: =Roster!B95 -> 92 | C94: =Roster!$T95
A95: =Roster!$A96 -> 93 | B95: =Roster!B96 -> 93 | C95: =Roster!$T96
A96: =Roster!$A97 -> 94 | B96: =Roster!B97 -> 94 | C96: =Roster!$T97
A97: =Roster!$A98 -> 95 | B97: =Roster!B98 -> 95 | C97: =Roster!$T98
A98: =Roster!$A99 -> 96 | B98: =Roster!B99 -> 96 | C98: =Roster!$T99
A99: =Roster!$A100 -> 97 | B99: =Roster!B100 -> 97 | C99: =Roster!$T100
A100: =Roster!$A101 -> 98 | B100: =Roster!B101 -> 98 | C100: =Roster!$T101
A101: =Roster!$A102 -> 99 | B101: =Roster!B102 -> 00 | C101: =C104 | D101: =D104 -> 0 | E101: =E104 -> 0 | F101: =F104 -> 0 | G101: =G104 -> 0 | H101: =H104 -> 0 | I101: =I104 -> 0 | J101: =J104 -> 0 | ... L101: =L104 -> 0
A103: Enter Player 0/00 info below. It will autofill rows 90 & 99.
A104: =Roster!$A105 -> 0 | B104: =Roster!B105 -> 0 | C104: =Roster!$T102

Sheet Season Stats
A1: Jersey | B1: Display Jersey | C1: Player Name | D1: CAT1 | E1: CAT1 HILITE | F1: CAT2 | G1: CAT2 HILITE | H1: CAT3 | I1: CAT3 HILITE | J1: STAT HILITE NOTE | L1: PTS STAT | M1: FG STAT | N1: 3PT% STAT | O1: FT% STAT | P1: REBS STAT | Q1: ASSTS STAT | R1: BLOCKS STAT | S1: STEALS STAT | T1: MINUTES STAT | U1: AVERAGE STAT | W1: USER CAT1 | X1: USER CAT2 | Y1: SEASON + FT STAT | Z1: SEASON + 3PT% | AB1: POINTS | AC1: FG | AD1: 3PT% | AE1: FT% | AF1: REBOUNDS | AG1: ASSISTS | AH1: BLOCKS | AI1: STEALS | AJ1: MINUTES
A2: =Roster!$A4 -> 1 | B2: =Roster!B4 -> 1 | C2: =Roster!$T4 -> First Last | D2: 4.2 PPG | E2: X | F2: 45% FG | G2: X | H2: 33% 3-PT FG | I2: X | J2: Stat Note Here zz | L2: ='Player Stats'!D3 -> 1.3 | M2: ='Player Stats'!E3 -> 47% | N2: ='Player Stats'!F3 -> 33% | O2: ='Player Stats'!G3 -> 100% | P2: ='Player Stats'!H3 -> 1.3 | Q2: ='Player Stats'!I3 -> 1.1 | R2: ='Player Stats'!J3 -> 0.0 | S2: ='Player Stats'!K3 -> 0.3 | T2: ='Player Stats'!L3 -> 0 | U2: 0 | W2: 4.2 PPG | X2: 45% FG | Y2: ='Team Info'!$B$20&": "&O2&"" -> Last Season: 100% | Z2: ='Team Info'!$B$20&": "&N2&"" -> Last Season: 33% | AB2: =L2&" PPG" -> 1.3 PPG | AC2: =M2&" FG" -> 47% FG | AD2: =N2&" 3-PT FG" -> 33% 3-PT FG | AE2: =O2&" FT" -> 100% FT | AF2: =P2&" RPG" -> 1.3 RPG | AG2: =Q2&" APG" -> 1.1 APG | AH2: =R2&" BPG" -> 0.0 BPG | AI2: =S2&" SPG" -> 0.3 SPG | AJ2: =T2&" MPG" -> 0 MPG
A3: 2 | B3: 2 | C3: =Roster!$T5 | L3: ='Player Stats'!D4 -> 0 | M3: ='Player Stats'!E4 -> 0 | N3: ='Player Stats'!F4 -> 0 | O3: ='Player Stats'!G4 -> 0 | P3: ='Player Stats'!H4 -> 0 | Q3: ='Player Stats'!I4 -> 0 | R3: ='Player Stats'!J4 -> 0 | S3: ='Player Stats'!K4 -> 0 | T3: ='Player Stats'!L4 -> 0 | U3: 0 | Y3: ='Team Info'!$B$20&": "&O3&"" -> Last Season: 0 | Z3: ='Team Info'!$B$20&": "&N3&"" -> Last Season: 0 | AB3: =L3&" PPG" -> 0 PPG | AC3: =M3&" FG" -> 0 FG | AD3: =N3&" 3-PT FG" -> 0 3-PT FG | AE3: =O3&" FT" -> 0 FT | AF3: =P3&" RPG" -> 0 RPG | AG3: =Q3&" APG" -> 0 APG | AH3: =R3&" BPG" -> 0 BPG | AI3: =S3&" SPG" -> 0 SPG | AJ3: =T3&" MPG" -> 0 MPG
A4: 3 | B4: 3 | C4: =Roster!$T6 | L4: ='Player Stats'!D5 -> 0 | M4: ='Player Stats'!E5 -> 0 | N4: ='Player Stats'!F5 -> 0 | O4: ='Player Stats'!G5 -> 0 | P4: ='Player Stats'!H5 -> 0 | Q4: ='Player Stats'!I5 -> 0 | R4: ='Player Stats'!J5 -> 0 | S4: ='Player Stats'!K5 -> 0 | ... U4: ='Player Stats'!M5 -> 0 | Y4: ='Team Info'!$B$20&": "&O4&"" -> Last Season: 0 | Z4: ='Team Info'!$B$20&": "&N4&"" -> Last Season: 0 | AB4: =L4&" PPG" -> 0 PPG | AC4: =M4&" FG" -> 0 FG | AD4: =N4&" 3-PT FG" -> 0 3-PT FG | AE4: =O4&" FT" -> 0 FT | AF4: =P4&" RPG" -> 0 RPG | AG4: =Q4&" APG" -> 0 APG | AH4: =R4&" BPG" -> 0 BPG | AI4: =S4&" SPG" -> 0 SPG | AJ4: =T4&" MPG" -> 0 MPG
A5: 4 | B5: 4 | C5: =Roster!$T7 | L5: ='Player Stats'!D6 -> 0 | M5: ='Player Stats'!E6 -> 0 | N5: ='Player Stats'!F6 -> 0 | O5: ='Player Stats'!G6 -> 0 | P5: ='Player Stats'!H6 -> 0 | Q5: ='Player Stats'!I6 -> 0 | R5: ='Player Stats'!J6 -> 0 | S5: ='Player Stats'!K6 -> 0 | ... U5: ='Player Stats'!M6 -> 0 | Y5: ='Team Info'!$B$20&": "&O5&"" -> Last Season: 0 | Z5: ='Team Info'!$B$20&": "&N5&"" -> Last Season: 0 | AB5: =L5&" PPG" -> 0 PPG | AC5: =M5&" FG" -> 0 FG | AD5: =N5&" 3-PT FG" -> 0 3-PT FG | AE5: =O5&" FT" -> 0 FT | AF5: =P5&" RPG" -> 0 RPG | AG5: =Q5&" APG" -> 0 APG | AH5: =R5&" BPG" -> 0 BPG | AI5: =S5&" SPG" -> 0 SPG | AJ5: =T5&" MPG" -> 0 MPG
A6: 5 | B6: 5 | C6: =Roster!$T8 | L6: ='Player Stats'!D7 -> 0 | M6: ='Player Stats'!E7 -> 0 | N6: ='Player Stats'!F7 -> 0 | O6: ='Player Stats'!G7 -> 0 | P6: ='Player Stats'!H7 -> 0 | Q6: ='Player Stats'!I7 -> 0 | R6: ='Player Stats'!J7 -> 0 | S6: ='Player Stats'!K7 -> 0 | ... U6: ='Player Stats'!M7 -> 0 | Y6: ='Team Info'!$B$20&": "&O6&"" -> Last Season: 0 | Z6: ='Team Info'!$B$20&": "&N6&"" -> Last Season: 0 | AB6: =L6&" PPG" -> 0 PPG | AC6: =M6&" FG" -> 0 FG | AD6: =N6&" 3-PT FG" -> 0 3-PT FG | AE6: =O6&" FT" -> 0 FT | AF6: =P6&" RPG" -> 0 RPG | AG6: =Q6&" APG" -> 0 APG | AH6: =R6&" BPG" -> 0 BPG | AI6: =S6&" SPG" -> 0 SPG | AJ6: =T6&" MPG" -> 0 MPG
A7: 6 | B7: 6 | C7: =Roster!$T9 | L7: ='Player Stats'!D8 -> 0 | M7: ='Player Stats'!E8 -> 0 | N7: ='Player Stats'!F8 -> 0 | O7: ='Player Stats'!G8 -> 0 | P7: ='Player Stats'!H8 -> 0 | Q7: ='Player Stats'!I8 -> 0 | R7: ='Player Stats'!J8 -> 0 | S7: ='Player Stats'!K8 -> 0 | ... U7: ='Player Stats'!M8 -> 0 | Y7: ='Team Info'!$B$20&": "&O7&"" -> Last Season: 0 | Z7: ='Team Info'!$B$20&": "&N7&"" -> Last Season: 0 | AB7: =L7&" PPG" -> 0 PPG | AC7: =M7&" FG" -> 0 FG | AD7: =N7&" 3-PT FG" -> 0 3-PT FG | AE7: =O7&" FT" -> 0 FT | AF7: =P7&" RPG" -> 0 RPG | AG7: =Q7&" APG" -> 0 APG | AH7: =R7&" BPG" -> 0 BPG | AI7: =S7&" SPG" -> 0 SPG | AJ7: =T7&" MPG" -> 0 MPG
A8: 7 | B8: 7 | C8: =Roster!$T10 | L8: ='Player Stats'!D9 -> 0 | M8: ='Player Stats'!E9 -> 0 | N8: ='Player Stats'!F9 -> 0 | O8: ='Player Stats'!G9 -> 0 | P8: ='Player Stats'!H9 -> 0 | Q8: ='Player Stats'!I9 -> 0 | R8: ='Player Stats'!J9 -> 0 | S8: ='Player Stats'!K9 -> 0 | ... U8: ='Player Stats'!M9 -> 0 | Y8: ='Team Info'!$B$20&": "&O8&"" -> Last Season: 0 | Z8: ='Team Info'!$B$20&": "&N8&"" -> Last Season: 0 | AB8: =L8&" PPG" -> 0 PPG | AC8: =M8&" FG" -> 0 FG | AD8: =N8&" 3-PT FG" -> 0 3-PT FG | AE8: =O8&" FT" -> 0 FT | AF8: =P8&" RPG" -> 0 RPG | AG8: =Q8&" APG" -> 0 APG | AH8: =R8&" BPG" -> 0 BPG | AI8: =S8&" SPG" -> 0 SPG | AJ8: =T8&" MPG" -> 0 MPG
A9: 8 | B9: 8 | C9: =Roster!$T11 | L9: ='Player Stats'!D10 -> 0 | M9: ='Player Stats'!E10 -> 0 | N9: ='Player Stats'!F10 -> 0 | O9: ='Player Stats'!G10 -> 0 | P9: ='Player Stats'!H10 -> 0 | Q9: ='Player Stats'!I10 -> 0 | R9: ='Player Stats'!J10 -> 0 | S9: ='Player Stats'!K10 -> 0 | ... U9: ='Player Stats'!M10 -> 0 | Y9: ='Team Info'!$B$20&": "&O9&"" -> Last Season: 0 | Z9: ='Team Info'!$B$20&": "&N9&"" -> Last Season: 0 | AB9: =L9&" PPG" -> 0 PPG | AC9: =M9&" FG" -> 0 FG | AD9: =N9&" 3-PT FG" -> 0 3-PT FG | AE9: =O9&" FT" -> 0 FT | AF9: =P9&" RPG" -> 0 RPG | AG9: =Q9&" APG" -> 0 APG | AH9: =R9&" BPG" -> 0 BPG | AI9: =S9&" SPG" -> 0 SPG | AJ9: =T9&" MPG" -> 0 MPG
A10: 9 | B10: 9 | C10: =Roster!$T12 | L10: ='Player Stats'!D11 -> 0 | M10: ='Player Stats'!E11 -> 0 | N10: ='Player Stats'!F11 -> 0 | O10: ='Player Stats'!G11 -> 0 | P10: ='Player Stats'!H11 -> 0 | Q10: ='Player Stats'!I11 -> 0 | R10: ='Player Stats'!J11 -> 0 | S10: ='Player Stats'!K11 -> 0 | ... U10: ='Player Stats'!M11 -> 0 | Y10: ='Team Info'!$B$20&": "&O10&"" -> Last Season: 0 | Z10: ='Team Info'!$B$20&": "&N10&"" -> Last Season: 0 | AB10: =L10&" PPG" -> 0 PPG | AC10: =M10&" FG" -> 0 FG | AD10: =N10&" 3-PT FG" -> 0 3-PT FG | AE10: =O10&" FT" -> 0 FT | AF10: =P10&" RPG" -> 0 RPG | AG10: =Q10&" APG" -> 0 APG | AH10: =R10&" BPG" -> 0 BPG | AI10: =S10&" SPG" -> 0 SPG | AJ10: =T10&" MPG" -> 0 MPG
A11: 10 | B11: 10 | C11: =Roster!$T13 | L11: ='Player Stats'!D12 -> 0 | M11: ='Player Stats'!E12 -> 0 | N11: ='Player Stats'!F12 -> 0 | O11: ='Player Stats'!G12 -> 0 | P11: ='Player Stats'!H12 -> 0 | Q11: ='Player Stats'!I12 -> 0 | R11: ='Player Stats'!J12 -> 0 | S11: ='Player Stats'!K12 -> 0 | ... U11: ='Player Stats'!M12 -> 0 | Y11: ='Team Info'!$B$20&": "&O11&"" -> Last Season: 0 | Z11: ='Team Info'!$B$20&": "&N11&"" -> Last Season: 0 | AB11: =L11&" PPG" -> 0 PPG | AC11: =M11&" FG" -> 0 FG | AD11: =N11&" 3-PT FG" -> 0 3-PT FG | AE11: =O11&" FT" -> 0 FT | AF11: =P11&" RPG" -> 0 RPG | AG11: =Q11&" APG" -> 0 APG | AH11: =R11&" BPG" -> 0 BPG | AI11: =S11&" SPG" -> 0 SPG | AJ11: =T11&" MPG" -> 0 MPG
A12: 11 | B12: 11 | C12: =Roster!$T14 | L12: ='Player Stats'!D13 -> 0 | M12: ='Player Stats'!E13 -> 0 | N12: ='Player Stats'!F13 -> 0 | O12: ='Player Stats'!G13 -> 0 | P12: ='Player Stats'!H13 -> 0 | Q12: ='Player Stats'!I13 -> 0 | R12: ='Player Stats'!J13 -> 0 | S12: ='Player Stats'!K13 -> 0 | ... U12: ='Player Stats'!M13 -> 0 | Y12: ='Team Info'!$B$20&": "&O12&"" -> Last Season: 0 | Z12: ='Team Info'!$B$20&": "&N12&"" -> Last Season: 0 | AB12: =L12&" PPG" -> 0 PPG | AC12: =M12&" FG" -> 0 FG | AD12: =N12&" 3-PT FG" -> 0 3-PT FG | AE12: =O12&" FT" -> 0 FT | AF12: =P12&" RPG" -> 0 RPG | AG12: =Q12&" APG" -> 0 APG | AH12: =R12&" BPG" -> 0 BPG | AI12: =S12&" SPG" -> 0 SPG | AJ12: =T12&" MPG" -> 0 MPG
A13: 12 | B13: 12 | C13: =Roster!$T15 | L13: ='Player Stats'!D14 -> 0 | M13: ='Player Stats'!E14 -> 0 | N13: ='Player Stats'!F14 -> 0 | O13: ='Player Stats'!G14 -> 0 | P13: ='Player Stats'!H14 -> 0 | Q13: ='Player Stats'!I14 -> 0 | R13: ='Player Stats'!J14 -> 0 | S13: ='Player Stats'!K14 -> 0 | ... U13: ='Player Stats'!M14 -> 0 | Y13: ='Team Info'!$B$20&": "&O13&"" -> Last Season: 0 | Z13: ='Team Info'!$B$20&": "&N13&"" -> Last Season: 0 | AB13: =L13&" PPG" -> 0 PPG | AC13: =M13&" FG" -> 0 FG | AD13: =N13&" 3-PT FG" -> 0 3-PT FG | AE13: =O13&" FT" -> 0 FT | AF13: =P13&" RPG" -> 0 RPG | AG13: =Q13&" APG" -> 0 APG | AH13: =R13&" BPG" -> 0 BPG | AI13: =S13&" SPG" -> 0 SPG | AJ13: =T13&" MPG" -> 0 MPG
A14: 13 | B14: 13 | C14: =Roster!$T16 | L14: ='Player Stats'!D15 -> 0 | M14: ='Player Stats'!E15 -> 0 | N14: ='Player Stats'!F15 -> 0 | O14: ='Player Stats'!G15 -> 0 | P14: ='Player Stats'!H15 -> 0 | Q14: ='Player Stats'!I15 -> 0 | R14: ='Player Stats'!J15 -> 0 | S14: ='Player Stats'!K15 -> 0 | ... U14: ='Player Stats'!M15 -> 0 | Y14: ='Team Info'!$B$20&": "&O14&"" -> Last Season: 0 | Z14: ='Team Info'!$B$20&": "&N14&"" -> Last Season: 0 | AB14: =L14&" PPG" -> 0 PPG | AC14: =M14&" FG" -> 0 FG | AD14: =N14&" 3-PT FG" -> 0 3-PT FG | AE14: =O14&" FT" -> 0 FT | AF14: =P14&" RPG" -> 0 RPG | AG14: =Q14&" APG" -> 0 APG | AH14: =R14&" BPG" -> 0 BPG | AI14: =S14&" SPG" -> 0 SPG | AJ14: =T14&" MPG" -> 0 MPG
A15: 14 | B15: 14 | C15: =Roster!$T17 | L15: ='Player Stats'!D16 -> 0 | M15: ='Player Stats'!E16 -> 0 | N15: ='Player Stats'!F16 -> 0 | O15: ='Player Stats'!G16 -> 0 | P15: ='Player Stats'!H16 -> 0 | Q15: ='Player Stats'!I16 -> 0 | R15: ='Player Stats'!J16 -> 0 | S15: ='Player Stats'!K16 -> 0 | ... U15: ='Player Stats'!M16 -> 0 | Y15: ='Team Info'!$B$20&": "&O15&"" -> Last Season: 0 | Z15: ='Team Info'!$B$20&": "&N15&"" -> Last Season: 0 | AB15: =L15&" PPG" -> 0 PPG | AC15: =M15&" FG" -> 0 FG | AD15: =N15&" 3-PT FG" -> 0 3-PT FG | AE15: =O15&" FT" -> 0 FT | AF15: =P15&" RPG" -> 0 RPG | AG15: =Q15&" APG" -> 0 APG | AH15: =R15&" BPG" -> 0 BPG | AI15: =S15&" SPG" -> 0 SPG | AJ15: =T15&" MPG" -> 0 MPG
... A75: 74 | B75: 74 | C75: =Roster!$T77 | L75: ='Player Stats'!D76 -> 0 | M75: ='Player Stats'!E76 -> 0 | N75: ='Player Stats'!F76 -> 0 | O75: ='Player Stats'!G76 -> 0 | P75: ='Player Stats'!H76 -> 0 | Q75: ='Player Stats'!I76 -> 0 | R75: ='Player Stats'!J76 -> 0 | S75: ='Player Stats'!K76 -> 0 | ... U75: ='Player Stats'!M76 -> 0 | Y75: ='Team Info'!$B$20&": "&O75&"" -> Last Season: 0 | Z75: ='Team Info'!$B$20&": "&N75&"" -> Last Season: 0 | AB75: =L75&" PPG" -> 0 PPG | AC75: =M75&" FG" -> 0 FG | AD75: =N75&" 3-PT FG" -> 0 3-PT FG | AE75: =O75&" FT" -> 0 FT | AF75: =P75&" RPG" -> 0 RPG | AG75: =Q75&" APG" -> 0 APG | AH75: =R75&" BPG" -> 0 BPG | AI75: =S75&" SPG" -> 0 SPG | AJ75: =T75&" MPG" -> 0 MPG
A76: 75 | B76: 75 | C76: =Roster!$T78 | L76: 0 | M76: 0 | N76: ='Player Stats'!F77 -> 0 | O76: 0 | P76: ='Player Stats'!H77 -> 0 | Q76: 0 | R76: ='Player Stats'!J77 -> 0 | S76: 0 | T76: ='Player Stats'!L77 -> 0 | U76: ='Player Stats'!M77 -> 0 | Y76: ='Team Info'!$B$20&": "&O76&"" -> Last Season: 0 | Z76: ='Team Info'!$B$20&": "&N76&"" -> Last Season: 0 | AB76: =L76&" PPG" -> 0 PPG | AC76: =M76&" FG" -> 0 FG | AD76: =N76&" 3-PT FG" -> 0 3-PT FG | AE76: =O76&" FT" -> 0 FT | AF76: =P76&" RPG" -> 0 RPG | AG76: =Q76&" APG" -> 0 APG | AH76: =R76&" BPG" -> 0 BPG | AI76: =S76&" SPG" -> 0 SPG | AJ76: =T76&" MPG" -> 0 MPG
A77: 76 | B77: 76 | C77: =Roster!$T79 | L77: ='Player Stats'!D78 -> 0 | M77: ='Player Stats'!E78 -> 0 | N77: ='Player Stats'!F78 -> 0 | O77: ='Player Stats'!G78 -> 0 | P77: ='Player Stats'!H78 -> 0 | Q77: ='Player Stats'!I78 -> 0 | R77: ='Player Stats'!J78 -> 0 | S77: ='Player Stats'!K78 -> 0 | ... U77: ='Player Stats'!M78 -> 0 | Y77: ='Team Info'!$B$20&": "&O77&"" -> Last Season: 0 | Z77: ='Team Info'!$B$20&": "&N77&"" -> Last Season: 0 | AB77: =L77&" PPG" -> 0 PPG | AC77: =M77&" FG" -> 0 FG | AD77: =N77&" 3-PT FG" -> 0 3-PT FG | AE77: =O77&" FT" -> 0 FT | AF77: =P77&" RPG" -> 0 RPG | AG77: =Q77&" APG" -> 0 APG | AH77: =R77&" BPG" -> 0 BPG | AI77: =S77&" SPG" -> 0 SPG | AJ77: =T77&" MPG" -> 0 MPG
A78: 77 | B78: 77 | C78: =Roster!$T80 | L78: ='Player Stats'!D79 -> 0 | M78: ='Player Stats'!E79 -> 0 | N78: ='Player Stats'!F79 -> 0 | O78: ='Player Stats'!G79 -> 0 | P78: ='Player Stats'!H79 -> 0 | Q78: ='Player Stats'!I79 -> 0 | R78: ='Player Stats'!J79 -> 0 | S78: ='Player Stats'!K79 -> 0 | ... U78: ='Player Stats'!M79 -> 0 | Y78: ='Team Info'!$B$20&": "&O78&"" -> Last Season: 0 | Z78: ='Team Info'!$B$20&": "&N78&"" -> Last Season: 0 | AB78: =L78&" PPG" -> 0 PPG | AC78: =M78&" FG" -> 0 FG | AD78: =N78&" 3-PT FG" -> 0 3-PT FG | AE78: =O78&" FT" -> 0 FT | AF78: =P78&" RPG" -> 0 RPG | AG78: =Q78&" APG" -> 0 APG | AH78: =R78&" BPG" -> 0 BPG | AI78: =S78&" SPG" -> 0 SPG | AJ78: =T78&" MPG" -> 0 MPG
A79: 78 | B79: 78 | C79: =Roster!$T81 | L79: ='Player Stats'!D80 -> 0 | M79: ='Player Stats'!E80 -> 0 | N79: ='Player Stats'!F80 -> 0 | O79: ='Player Stats'!G80 -> 0 | P79: ='Player Stats'!H80 -> 0 | Q79: ='Player Stats'!I80 -> 0 | R79: ='Player Stats'!J80 -> 0 | S79: ='Player Stats'!K80 -> 0 | ... U79: ='Player Stats'!M80 -> 0 | Y79: ='Team Info'!$B$20&": "&O79&"" -> Last Season: 0 | Z79: ='Team Info'!$B$20&": "&N79&"" -> Last Season: 0 | AB79: =L79&" PPG" -> 0 PPG | AC79: =M79&" FG" -> 0 FG | AD79: =N79&" 3-PT FG" -> 0 3-PT FG | AE79: =O79&" FT" -> 0 FT | AF79: =P79&" RPG" -> 0 RPG | AG79: =Q79&" APG" -> 0 APG | AH79: =R79&" BPG" -> 0 BPG | AI79: =S79&" SPG" -> 0 SPG | AJ79: =T79&" MPG" -> 0 MPG
A80: 79 | B80: 79 | C80: =Roster!$T82 | L80: ='Player Stats'!D81 -> 0 | M80: ='Player Stats'!E81 -> 0 | N80: ='Player Stats'!F81 -> 0 | O80: ='Player Stats'!G81 -> 0 | P80: ='Player Stats'!H81 -> 0 | Q80: ='Player Stats'!I81 -> 0 | R80: ='Player Stats'!J81 -> 0 | S80: ='Player Stats'!K81 -> 0 | ... U80: ='Player Stats'!M81 -> 0 | Y80: ='Team Info'!$B$20&": "&O80&"" -> Last Season: 0 | Z80: ='Team Info'!$B$20&": "&N80&"" -> Last Season: 0 | AB80: =L80&" PPG" -> 0 PPG | AC80: =M80&" FG" -> 0 FG | AD80: =N80&" 3-PT FG" -> 0 3-PT FG | AE80: =O80&" FT" -> 0 FT | AF80: =P80&" RPG" -> 0 RPG | AG80: =Q80&" APG" -> 0 APG | AH80: =R80&" BPG" -> 0 BPG | AI80: =S80&" SPG" -> 0 SPG | AJ80: =T80&" MPG" -> 0 MPG
A81: 80 | B81: 80 | C81: =Roster!$T83 | L81: ='Player Stats'!D82 -> 0 | M81: ='Player Stats'!E82 -> 0 | N81: ='Player Stats'!F82 -> 0 | O81: ='Player Stats'!G82 -> 0 | P81: ='Player Stats'!H82 -> 0 | Q81: ='Player Stats'!I82 -> 0 | R81: ='Player Stats'!J82 -> 0 | S81: ='Player Stats'!K82 -> 0 | ... U81: ='Player Stats'!M82 -> 0 | Y81: ='Team Info'!$B$20&": "&O81&"" -> Last Season: 0 | Z81: ='Team Info'!$B$20&": "&N81&"" -> Last Season: 0 | AB81: =L81&" PPG" -> 0 PPG | AC81: =M81&" FG" -> 0 FG | AD81: =N81&" 3-PT FG" -> 0 3-PT FG | AE81: =O81&" FT" -> 0 FT | AF81: =P81&" RPG" -> 0 RPG | AG81: =Q81&" APG" -> 0 APG | AH81: =R81&" BPG" -> 0 BPG | AI81: =S81&" SPG" -> 0 SPG | AJ81: =T81&" MPG" -> 0 MPG
A82: 81 | B82: 81 | C82: =Roster!$T84 | L82: ='Player Stats'!D83 -> 0 | M82: ='Player Stats'!E83 -> 0 | N82: ='Player Stats'!F83 -> 0 | O82: ='Player Stats'!G83 -> 0 | P82: ='Player Stats'!H83 -> 0 | Q82: ='Player Stats'!I83 -> 0 | R82: ='Player Stats'!J83 -> 0 | S82: ='Player Stats'!K83 -> 0 | ... U82: ='Player Stats'!M83 -> 0 | Y82: ='Team Info'!$B$20&": "&O82&"" -> Last Season: 0 | Z82: ='Team Info'!$B$20&": "&N82&"" -> Last Season: 0 | AB82: =L82&" PPG" -> 0 PPG | AC82: =M82&" FG" -> 0 FG | AD82: =N82&" 3-PT FG" -> 0 3-PT FG | AE82: =O82&" FT" -> 0 FT | AF82: =P82&" RPG" -> 0 RPG | AG82: =Q82&" APG" -> 0 APG | AH82: =R82&" BPG" -> 0 BPG | AI82: =S82&" SPG" -> 0 SPG | AJ82: =T82&" MPG" -> 0 MPG
