Workbook
Name ACTIONSHOT: Roster!$V$3:$V$102
Name AGE: Roster!$Q$3:$Q$102
Name AGE_TEXT: Roster!$R$3:$R$102
Name ah: Roster!$BD$3
Name BA: Roster!$S$3:$S$102
Name BATS: Roster!$F$3:$F$104
Name BIO_HEADER: Roster!$P$3:$P$4
Name CAT_1: Stats!$D$1:$D$100
Name CAT_1_HILITE: Stats!$E$1:$E$100
Name CAT_2: Stats!$F$1:$F$100
Name CAT_2_HILITE: Stats!$G$1:$G$100
Name CAT_3: Stats!$H$1:$H$100
Name CAT_3_HILITE: Stats!$I$1:$I$100
Name CAT_4: Stats!$J$1:$J$100
Name CAT_4_HILITE: Stats!$K$1:$K$100
Name COACH_DEF_FIRST: 'Team Personnel'!$B$13:$B$23
Name COACH_DEF_LAST: 'Team Personnel'!$C$13:$C$23
Name COACH_DEF_TEXT: 'Team Personnel'!$E$13:$E$23
Name COACH_HEAD_DROP: 'Team Personnel'!$F$2:$F$12
Name COACH_HEAD_FIRST: 'Team Personnel'!$B$2:$B$12
Name COACH_HEAD_FULL: 'Team Personnel'!$I$2:$I$23
Name COACH_HEAD_HEADER: 'Team Personnel'!$D$2:$D$12
Name COACH_HEAD_LAST: 'Team Personnel'!$C$2:$C$12
Name COACH_HEAD_TEXT: 'Team Personnel'!$E$2:$E$12
Name COACH_OFF_DROP: 'Team Personnel'!$F$8:$F$12
Name COACH_OFF_FIRST: 'Team Personnel'!$B$8:$B$12
Name COACH_OFF_HEADER: 'Team Personnel'!$D$8:$D$12
Name COACH_OFF_LAST: 'Team Personnel'!$C$8:$C$12
Name COACH_OFF_TEXT: 'Team Personnel'!$E$8:$E$12
Name COACH_RESUME_DROP: 'Team Personnel'!$K$20:$K$21
Name COACH_RESUME_LINE1: 'Team Personnel'!$K$8:$K$9
Name COACH_RESUME_LINE2: 'Team Personnel'!$K$11:$K$12
Name COACH_RESUME_LINE3: 'Team Personnel'!$K$14:$K$15
Name COACH_RESUME_LINE4: 'Team Personnel'!$K$17:$K$18
Name COACH_RESUME_ROWS: 'Team Personnel'!$K$23:$K$24
Name COACH_RESUME_SUBTITLE: 'Team Personnel'!$K$5:$K$6
Name COACH_RESUME_TITLE: 'Team Personnel'!$K$2:$K$3
Name CONFERENCE_LOGOS: LOGOS!$C$1:$C$50
Name ESPN100: Roster!$O$3:$O$102
Name HEADER: Roster!$N$3:$N$102
Name HEADSHOT: Roster!$U$3:$U$102
Name HEIGHT: Roster!$H$3:$H$102
Name HERO_1_DROP: 'Player Heroes'!$J$2:$J$101
Name HERO_1_HEADER: 'Player Heroes'!$G$2:$G$101
Name HERO_1_INFO: 'Player Heroes'!$I$2:$I$101
Name HERO_USER: 'Player Users'!$F$2:$F$101
Name HERO_USER2: 'Player Users'!$H$2:$H$101
Name HOMETOWN: Roster!$K$3:$K$102
Name HR_NEXT: Roster!$AI$3:$AI$102
Name HR_TOTAL: Roster!$T$3:$T$102
Name INNINGS: [1]Roster!$W$17:$X$18
Name INPUT_RANGE: MAIN!$C$4:$CM$104
Name JERSEY: Roster!$B$3:$B$102
Name LU_Firstname: #REF!
Name LU_Fullname: #REF!
Name LU_Headshot: #REF!
Name LU_Height: #REF!
Name LU_Hometown: #REF!
Name LU_Lastname: #REF!
Name LU_Position: #REF!

Sheet Team Info
A1: ESPN Team Sheet | B1: 46051 | D1: TEAM INFO | F1: TODAY_TONIGHT_SEL | H1: SWATCH SEL
A2: TEAM INFO | B2: Home | D2: TEAM_RANK | F2: =$B$17 -> Tonight | H2: 0
A3: Team Rank | D3: =$B$3 | F3: =UPPER(F2) -> TONIGHT | H3: 1
A4: Team College | B4: North Carolina | H4: 2
A5: Team Nickname | B5: Tar Heels | D5: TEAM_CITY_COLLEGE | F5: SEASON_SEL | H5: 3
A6: Team Tricode | B6: UNC | D6: =$B$4 -> North Carolina | F6: =$B$18 -> Season
A7: Team Dashboard Name (CAPS) | B7: NORTH CAROLINA | D7: =UPPER(D6) -> NORTH CAROLINA | F7: =UPPER(F6) -> SEASON | H7: TODAY/SEASON SEL
A8: Team Record (CAPS) | B8: 0-0 | D8: TEAM_NICKNAME | F8: TODAY_TONIGHT_SEL_COLON | H8: Last Season
D9: =$B$5 -> Tar Heels | F9: =$F$2&":" -> Tonight: | H9: Season
A10: TEAM LOGOS / SWATCH / HEADSHOTS | D10: =UPPER(D9) -> TAR HEELS | F10: =UPPER($F$2&":") -> TONIGHT: | H10: Today
A11: LOGO / SWATCH / HEADSHOT / ACTION | B11: GENERIC_BASEBALL | F11: SEASON_SEL_COLON | H11: Tonight
A12: Swatch Selector | B12: 0 | C12: =H15 -> LOGO | D12: TEAM_TRICODE | F12: =$F$6&":" -> Season:
A13: Dashboard Swatch Selector | B13: 1 | C13: =H20 -> PRIMARY | D13: =$B$6 -> UNC | F13: =UPPER($F$6&":") -> SEASON: | H13: SWATCH_SELECT
A14: Headshots On/Off (0=Off, 1=On) | B14: 0 | C14: =F21 -> Off | H14: =B$12 -> 0
D15: TEAM_FULL_NAME | F15: AWAY/HOME SEL | H15: =IF(H14=1,"PRIMARY",IF(H14=2,"SECONDARY",IF(H14=3,"BOTTOMLINE",IF(H14=0,"LOGO")))) -> LOGO
A16: TODAY / SEASON SELECTION | D16: =B4&" "&B5 -> North Carolina Tar Heels | F16: Away
A17: Today / Tonight Selection | B17: Tonight | D17: =UPPER(D16) -> NORTH CAROLINA TAR HEELS | F17: Home
A18: Season / Last Season | B18: Season | H18: DASH_SWATCH_SELECT
D19: TEAM_DASH_NAME | F19: HEADSHOT_ONOFF | H19: =$B$13 -> 1
A20: SPORT SELECTION | D20: =$B$7 -> NORTH CAROLINA | F20: =$B$14 -> 0 | H20: =IF(H19=1,"PRIMARY",IF(H19=2,"SECONDARY",IF(H19=3,"BOTTOMLINE",IF(H19=0,"LOGO")))) -> PRIMARY
A21: Baseball / Softball / LLWS Selection | B21: Baseball | F21: =IF(F20=1,"On","Off") -> Off
D22: TEAM_RANK_NAME
D23: =D3&" "&D6 -> North Carolina | F23: On/Off | H23: SPORT_SELECT
A24: INSTRUCTIONS | D24: =UPPER(D23) -> NORTH CAROLINA | F24: 0 | H24: =$B$21 -> Baseball
A25: Fill out information in BLUE cells only. Select Away/Home in cell B2 and make your Sport Selection in B21 | F25: 1 | H25: =IF(H24="Baseball",9,IF(H24="Softball",7,IF(H24="Little League",6))) -> 9
A26: Fill out player information on the MAIN tab. This will populate the information into the Roster tab. | D26: TEAM_RANK_NAME_NICKNAME
A27: Stats have been predetermined by production. Enter optional hilite note in Stats tab | D27: =D3&" "&D6&" "&D9 -> North Carolina Tar Heels | F27: SPORT_SEL
D28: =UPPER(D27) -> NORTH CAROLINA TAR HEELS | F28: Baseball
A29: ** For Xpression ** | F29: Softball
A30: If you select the GENERIC_BASEBALL or GENERIC_SOFTBALL option: | D30: TEAM_RANK_NAME_RECORD | F30: Little League
A31: Find a swatch with the colors of the team you need, make a copy of that swatch, | D31: =D3&" "&D6&" "& "(" & D38 &")" -> North Carolina (0-0)
A32: and rename it to GENERIC_BASEBALL or GENERIC_SOFTBALL | D32: =UPPER(D31) -> NORTH CAROLINA (0-0)
D34: TEAM_LOGOTEXT
D35: =$B$11 -> GENERIC_BASEBALL
D37: TEAM_RECORD_OVERALL
D38: =B8 -> 0-0
D40: TEAM_SPLIT
D41: =#REF! -> #REF!

Sheet MAIN
A1: Roster | B1: For "2-way" players enter position as Pitching/Hitting: LHP/SS or LHP/SS/C | M1: ACCN & SECN Teams = Major | CN1: BattingSeries | DK1: PitchingSeries
D2: For Pitchers: Enter LHP or RHP into Position | K2: Year (1-FR, 2-SO, 3-JR, 4-SR/GR) | L2: Enter as MM/DD/YY | M2: ALL CAPS | O2: Optional | BB2: BattingSeason | BY2: Pitching Season | CN2: AB | CO2: R | CP2: H | CQ2: 2B | CR2: 3B | CS2: HR | CT2: RBI | CU2: HBP | CV2: BB | CW2: SO | CX2: SH | CY2: SF | CZ2: SB | DA2: CS | DB2: GDP | DC2: RISPAB | DD2: RISPH | DE2: RISPHR | DF2: RISPRBI | DG2: BasesLoadedAB | DH2: BasesLoadedH | DI2: BasesLoadedHR | DJ2: BasesLoadedRBI | DK2: G | DL2: GS | DM2: CG | DN2: SHO | DO2: Win | DP2: Loss | DQ2: SV | DR2: IP | DS2: H | DT2: HR | DU2: R | DV2: ER | DW2: HBP | DX2: BB | DY2: SO
A3: LastName | B3: Firstname | C3: Number | D3: Position | E3: Bats | F3: Throws | G3: Hometown | H3: State | I3: Height | J3: Weight | K3: Year | L3: Age | M3: Major/Header | N3: Fact | O3: Etc | AA3: 27 | AB3: 28 | AC3: 29 | AD3: 30 | AI3: 35 | AN3: 40 | AS3: 45 | AU3: 1B | AV3: SLG % | AW3: OPS | AX3: 50 | BB3: AB | BC3: R | BD3: H | BE3: 2B | BF3: 3B | BG3: HR | BH3: RBI | BI3: BB | BJ3: HBP | BK3: SO | BL3: GDP | BM3: SF | BN3: SH | BO3: SB | BP3: CS | BQ3: RISPAB | BR3: RISPH | BS3: RISPHR | BT3: RISPRBI | BU3: BasesLoadedAB | BV3: BasesLoadedH | BW3: BasesLoadedHR | BX3: BasesLoadedRBI | BY3: Win | BZ3: Loss | CA3: G | CB3: GS | CC3: CG | CD3: SHO | CE3: SV | CF3: IP | CG3: H | CH3: R | CI3: ER | CJ3: BB | CK3: SO | CL3: HR | CM3: HBP
A4: Lastname | B4: Firstname | C4: 1 | D4: P | F4: RHP | G4: Callahan | H4: FL | I4: 6'2" | K4: 1 | L4: 37447 | AU4: =SUM(BE4:BG4)-BD4 -> -5 | AV4: =(AU4+(BE4*2)+(BF4*3)+(BG4*4))/BB4 -> 0.6 | BB4: 15 | BC4: 2 | BD4: 10 | BE4: 2 | BF4: 2 | BG4: 1 | BH4: 12 | BI4: 3 | BJ4: 1 | BK4: 1 | BL4: 2 | BM4: 2 | BN4: 1 | BY4: 1 | BZ4: 0 | CA4: 5 | CB4: 1 | CC4: 0 | CD4: 0/1 | CE4: 0 | CF4: 11.2 | CG4: 7 | CH4: 0 | CI4: 0 | CJ4: 3 | CK4: 17 | CL4: 0 | CM4: 1
A5: LastName | B5: Firstname | C5: 2 | D5: SS | E5: R | F5: R | G5: Charlotte | H5: NC | I5: 6'1" | K5: 4 | L5: 36957 | BB5: 27 | BC5: 3 | BD5: 7 | BE5: 2 | BF5: 0 | BG5: 1 | BH5: 7 | BI5: 1 | BJ5: 0 | BK5: 5 | BL5: 0 | BM5: 1 | BN5: 0 | BO5: 0 | BP5: 0 | BY5: 2 | BZ5: 0 | CA5: 9 | CB5: 0 | CC5: 0 | CD5: 0/0 | CE5: 3 | CF5: 12.0 | CG5: 6 | CH5: 2 | CI5: 1 | CJ5: 4 | CK5: 18 | CL5: 0 | CM5: 2
D6: P | BY6: 2 | BZ6: 0 | CA6: 7 | CB6: 0 | CC6: 0 | CD6: 0/0 | CE6: 0 | CF6: 15.0 | CG6: 11 | CH6: 2 | CI6: 2 | CJ6: 6 | CK6: 16 | CL6: 0 | CM6: 0
AX7: 50

Sheet Team Personnel
B1: CAPS | C1: CAPS | D1: CAPS | E1: CAPS | F1: CAPS (IF NEEDED)
A2: Save # | B2: First Name CAPS | C2: Last Name CAPS | D2: Header | E2: Line 1 Text | F2: Dropline Text | I2: COACH_HEAD_FULL | K2: COACH_RESUME_TITLE
A3: =IF('Team Info'!$B$2 = "Away",4180,4280) -> 4280 | B3: COACH | C3: COACH | D3: HEAD COACH | E3: 3RD SEASON | F3: Sticker only - no dropline | I3: =B3 &" " & C3 -> COACH COACH | K3: =B26 -> COACHING RÉSUMÉ
A4: =A3+1 -> 4281 | B4: =B3 -> COACH | C4: =C3 -> COACH | I4: =B4 &" " & C4 -> COACH COACH
A5: =A4+1 -> 4282 | B5: ASST | C5: LAST2 | I5: =B5 &" " & C5 -> ASST LAST2 | K5: COACH_RESUME_SUBTITLE
A6: =A5+1 -> 4283 | B6: ASST2 | C6: LAST2 | I6: =B6 &" " & C6 -> ASST2 LAST2
A7: =A6+1 -> 4284 | B7: ASST3 | C7: LAST3 | I7: =B7 &" " & C7 -> ASST3 LAST3
A8: =A7+1 -> 4285 | B8: ASST4 | C8: LAST4 | I8: =B8 &" " & C8 -> ASST4 LAST4 | K8: COACH_RESUME_LINE1
A9: =A8+1 -> 4286 | B9: ASST5 | C9: LAST5 | I9: =B9 &" " & C9 -> ASST5 LAST5 | K9: =B30 -> LINE 1 TEXT HERE LINE 2 TEXT HERE
A10: =A9+1 -> 4287 | B10: ASST6 | C10: LAST6 | I10: =B10 &" " & C10 -> ASST6 LAST6
A11: =A10+1 -> 4288 | B11: ASST7 | C11: LAST7 | I11: =B11 &" " & C11 -> ASST7 LAST7 | K11: COACH_RESUME_LINE2
A12: =A11+1 -> 4289 | B12: ASST8 | C12: LAST8 | I12: =B12 &" " & C12 -> ASST8 LAST8 | K12: =B32 -> LINE2 TEST LINE 2A
A13: Save # | B13: First Name CAPS | C13: Last Name CAPS | E13: Line 1 Text (Upper/Lower) | F13: Stickers only | I13: =B13 &" " & C13 -> First Name CAPS Last Name CAPS
A14: =IF('Team Info'!$B$2 = "Away",190,290) -> 290 | B14: MIKE | C14: STOOPS | E14: Defensive Coordinator | I14: COACH_OFF_FULL | K14: COACH_RESUME_LINE3
A15: =A14+1 -> 291 | B15: RUFFIN | C15: McNEIL | E15: Assistant Head Coach/Defensive Tackles Coach | I15: =B15 &" " & C15 -> RUFFIN McNEIL | K15: =B34 -> LINE 3 TEST LINE 3A
A16: =A14+2 -> 292 | B16: DEF. COACH | C16: DEF. COACH | I16: =B16 &" " & C16 -> DEF. COACH DEF. COACH
A17: =A14+3 -> 293 | B17: DEF. COACH | C17: DEF. COACH | I17: =B17 &" " & C17 -> DEF. COACH DEF. COACH | K17: COACH_RESUME_LINE4
A18: =A14+4 -> 294 | B18: DEF. COACH | C18: DEF. COACH | I18: =B18 &" " & C18 -> DEF. COACH DEF. COACH | K18: =B36 -> LINE 4 TEST LINE 4A
A19: =A14+5 -> 295 | B19: DEF. COACH | C19: DEF. COACH | I19: =B19 &" " & C19 -> DEF. COACH DEF. COACH
A20: =A14+6 -> 296 | B20: DEF. COACH | C20: DEF. COACH | I20: =B20 &" " & C20 -> DEF. COACH DEF. COACH | K20: COACH_RESUME_DROP
A21: =A14+7 -> 297 | B21: DEF. COACH | C21: DEF. COACH | I21: =B21 &" " & C21 -> DEF. COACH DEF. COACH | K21: =B38 -> DROPLINE HERE
A22: =A14+8 -> 298 | B22: DEF. COACH | C22: DEF. COACH | I22: =B22 &" " & C22 -> DEF. COACH DEF. COACH
A23: =A14+9 -> 299 | B23: DEF. COACH | C23: DEF. COACH | I23: =B23 &" " & C23 -> DEF. COACH DEF. COACH | K23: COACH_RESUME_ROWS
A24: ** MAKE SURE YOU SELECT AWAY OR HOME ON THE TEAM INFO TAB (CELL B2) ** | I24: =B24 &" " & C24 | K24: =B27 -> 3
A25: Coach Resume: | B25: =IF('Team Info'!$B$2 = "Away",4179,4279) -> 4279
A26: Title | B26: COACHING RÉSUMÉ | D26: Head Coach: Fill in first/last name in cells B3/C3. This will copy to the row 4 coach shells.
A27: Num Rows (1-4) | B27: 3 | D27: Remaining rows are for coaches 2-8
A28: First Name (CAPS) | B28: =B3 -> COACH
A29: Last Name (CAPS) | B29: =C3 -> COACH
A30: Line1 | B30: LINE 1 TEXT HERE LINE 2 TEXT HERE
A32: Line2 | B32: LINE2 TEST LINE 2A
A34: Line3 | B34: LINE 3 TEST LINE 3A
A36: Line4 | B36: LINE 4 TEST LINE 4A
A38: Drop | B38: DROPLINE HERE
A41: Note: press ALT-ENTER to break into multiple lines

Sheet Roster
A1: Roster | B1: All information on this tab fills in from the "MAIN" tab so you should not need to fill anything out here. Use this tab to check to make sure things are coming over correctly | U1: =IF('Team Info'!$B$21="BASEBALL","SBALL","CBASE") -> SBALL
M2: ALL CAPS | O2: Optional
A3: Jersey | B3: Display | C3: First Name | D3: Last Name | E3: POS | F3: Bats | G3: Throws | H3: Height | I3: Weight | J3: Birthday | K3: Hometown | L3: Year | M3: Major | N3: Bio Dropline | O3: ESPN 100 Rank | P3: HEADER | Q3: Age | R3: Age Text | S3: BA | T3: HR | U3: Headshot | V3: Actionshot | W3: Num Name | X3: Full Name | Y3: Full Name CAPS | Z3: Initial Name | AA3: First Name CAPS | AB3: Last Name CAPS | AC3: Year | AD3: Year | AE3: Year CAPS | AF3: Weight LBS | AG3: Major Full | AH3: Num Name | AI3: Next HR
A4: 1 | B4: 1 | C4: =IFERROR(INDEX(NAME_RANGE,MATCH(B4,NUM_RANGE,FALSE),2),"-") -> Firstname | D4: =IFERROR(INDEX(NAME_RANGE,MATCH(B4,NUM_RANGE,FALSE),1),"-") -> Lastname | E4: =IFERROR(VLOOKUP($B4,INPUT_RANGE,2,FALSE),"-") -> P | F4: =IFERROR(VLOOKUP($B4,INPUT_RANGE,3,FALSE),"-") -> 0 | G4: =IFERROR(VLOOKUP($B4,INPUT_RANGE,4,FALSE),"-") -> RHP | H4: =IFERROR(VLOOKUP($B4,INPUT_RANGE,7,FALSE),"-") -> 6'2" | I4: =IFERROR(VLOOKUP($B4,INPUT_RANGE,8,FALSE),"-") -> 0 | K4: =IFERROR(VLOOKUP($B4,INPUT_RANGE,5,FALSE)&", "&VLOOKUP($B4,INPUT_RANGE,6,FALSE),"-") -> Callahan, FL | L4: =IFERROR(VLOOKUP($B4,INPUT_RANGE,9,FALSE),"-") -> 1 | M4: =IFERROR(VLOOKUP($B4,INPUT_RANGE,11,FALSE),"-") -> 0 | N4: =IFERROR(VLOOKUP($B4,INPUT_RANGE,12,FALSE),"-") | P4: =IF(M3="Header", 0, 1) -> 1 | Q4: =IF(J4="","",INT(YEARFRAC($J4, TODAY()))) | R4: =IF(Q4="","","Age: " & Q4) | S4: =RIGHT(ROUND(VLOOKUP(B4,INPUT_RANGE,54,FALSE)/VLOOKUP(B4,INPUT_RANGE,52,FALSE),3),4) -> .667 | T4: =VLOOKUP($B4,INPUT_RANGE,57,FALSE) -> 1 | U4: ="D:\IMS Images\Headshots\"&IF('Team Info'!$B$21="BASEBALL","CBASE","SBALL")&"\"&'Team Info'!$B$11&"\"&D4&"_"&C4&".png" -> D:\IMS Images\Headshots\CBASE\GENERIC_BASEBALL\Lastname_Firstname.png | V4: ="D:\IMS Images\ActionShots\"&IF('Team Info'!$B$21="BASEBALL","CBASE","SBALL")&"\"&'Team Info'!$B$11&"\"&D4&"_"&C4&".png" -> D:\IMS Images\ActionShots\CBASE\GENERIC_BASEBALL\Lastname_Firstname.png | W4: =B4 & " " & X4 -> 1 Firstname Lastname | X4: =C4&" "&D4 -> Firstname Lastname | Y4: =UPPER(X4) -> FIRSTNAME LASTNAME | Z4: =LEFT(C4,1)&". "&D4 -> F. Lastname | AA4: =UPPER(C4) -> FIRSTNAME | AB4: =UPPER(D4) -> LASTNAME | AC4: =IF($L4=4,"Senior",IF($L4=3,"Junior",IF($L4=2,"Sophomore",IF($L4=1,"Freshman","")))) -> Freshman | AD4: =IF($L4=4,"SR",IF($L4=3,"JR",IF($L4=2,"SO",IF($L4=1,"FR","")))) -> FR | AE4: =UPPER(AC4) -> FRESHMAN | AF4: =$I4 & " lbs" -> 0 lbs | AG4: ="MAJOR: " & UPPER(M4) -> MAJOR: 0 | AH4: =B4 & " " & UPPER(X4) -> 1 FIRSTNAME LASTNAME | AI4: =IF(T4=0,"1st",$T4+1&IF(AND(MOD(ABS($T4+1),100)>10,MOD(ABS($T4+1),100)<14),"th",CHOOSE(MOD(ABS($T4+1),10)+1,"th","st","nd","rd","th","th","th","th","th","th"))) -> 2nd
A5: 2 | B5: 2 | C5: =IFERROR(INDEX(NAME_RANGE,MATCH(B5,NUM_RANGE,FALSE),2),"-") -> Firstname | D5: =IFERROR(INDEX(NAME_RANGE,MATCH(B5,NUM_RANGE,FALSE),1),"-") -> LastName | E5: =IFERROR(VLOOKUP($B5,INPUT_RANGE,2,FALSE),"-") -> SS | F5: =IFERROR(VLOOKUP($B5,INPUT_RANGE,3,FALSE),"-") -> R | G5: =IFERROR(VLOOKUP($B5,INPUT_RANGE,4,FALSE),"-") -> R | H5: =IFERROR(VLOOKUP($B5,INPUT_RANGE,7,FALSE),"-") -> 6'1" | I5: =IFERROR(VLOOKUP($B5,INPUT_RANGE,8,FALSE),"-") -> 0 | K5: =IFERROR(VLOOKUP($B5,INPUT_RANGE,5,FALSE)&", "&VLOOKUP($B5,INPUT_RANGE,6,FALSE),"-") -> Charlotte, NC | L5: =IFERROR(VLOOKUP($B5,INPUT_RANGE,9,FALSE),"-") -> 4 | M5: =IFERROR(VLOOKUP($B5,INPUT_RANGE,11,FALSE),"-") -> 0 | N5: =IFERROR(VLOOKUP($B5,INPUT_RANGE,12,FALSE),"-") | Q5: =IF(J5="","",INT(YEARFRAC($J5, TODAY()))) | R5: =IF(Q5="","","Age: " & Q5) | S5: =RIGHT(ROUND(VLOOKUP(B5,INPUT_RANGE,54,FALSE)/VLOOKUP(B5,INPUT_RANGE,52,FALSE),3),4) -> .259 | T5: =VLOOKUP($B5,INPUT_RANGE,57,FALSE) -> 1 | U5: ="D:\IMS Images\Headshots\"&IF('Team Info'!$B$21="BASEBALL","CBASE","SBALL")&"\"&'Team Info'!$B$11&"\"&D5&"_"&C5&".png" -> D:\IMS Images\Headshots\CBASE\GENERIC_BASEBALL\LastName_Firstname.png | V5: ="D:\IMS Images\ActionShots\"&IF('Team Info'!$B$21="BASEBALL","CBASE","SBALL")&"\"&'Team Info'!$B$11&"\"&D5&"_"&C5&".png" -> D:\IMS Images\ActionShots\CBASE\GENERIC_BASEBALL\LastName_Firstname.png | W5: =B5 & " " & X5 -> 2 Firstname LastName | X5: =C5&" "&D5 -> Firstname LastName | Y5: =UPPER(X5) -> FIRSTNAME LASTNAME | Z5: =LEFT(C5,1)&". "&D5 -> F. LastName | AA5: =UPPER(C5) -> FIRSTNAME | AB5: =UPPER(D5) -> LASTNAME | AC5: =IF($L5=4,"Senior",IF($L5=3,"Junior",IF($L5=2,"Sophomore",IF($L5=1,"Freshman","")))) -> Senior | AD5: =IF($L5=4,"SR",IF($L5=3,"JR",IF($L5=2,"SO",IF($L5=1,"FR","")))) -> SR | AE5: =UPPER(AC5) -> SENIOR | AF5: =$I5 & " lbs" -> 0 lbs | AG5: ="MAJOR: " & UPPER(M5) -> MAJOR: 0 | AH5: =B5 & " " & UPPER(X5) -> 2 FIRSTNAME LASTNAME | AI5: =IF(T5=0,"1st",$T5+1&IF(AND(MOD(ABS($T5+1),100)>10,MOD(ABS($T5+1),100)<14),"th",CHOOSE(MOD(ABS($T5+1),10)+1,"th","st","nd","rd","th","th","th","th","th","th"))) -> 2nd
A6: 3 | B6: 3 | C6: =IFERROR(INDEX(NAME_RANGE,MATCH(B6,NUM_RANGE,FALSE),2),"-") -> - | D6: =IFERROR(INDEX(NAME_RANGE,MATCH(B6,NUM_RANGE,FALSE),1),"-") -> - | E6: =IFERROR(VLOOKUP($B6,INPUT_RANGE,2,FALSE),"-") -> - | F6: =IFERROR(VLOOKUP($B6,INPUT_RANGE,3,FALSE),"-") -> - | G6: =IFERROR(VLOOKUP($B6,INPUT_RANGE,4,FALSE),"-") -> - | H6: =IFERROR(VLOOKUP($B6,INPUT_RANGE,7,FALSE),"-") -> - | I6: =IFERROR(VLOOKUP($B6,INPUT_RANGE,8,FALSE),"-") -> - | K6: =IFERROR(VLOOKUP($B6,INPUT_RANGE,5,FALSE)&", "&VLOOKUP($B6,INPUT_RANGE,6,FALSE),"-") -> - | L6: =IFERROR(VLOOKUP($B6,INPUT_RANGE,9,FALSE),"-") -> - | M6: =IFERROR(VLOOKUP($B6,INPUT_RANGE,11,FALSE),"-") -> - | N6: =IFERROR(VLOOKUP($B6,INPUT_RANGE,12,FALSE),"-") -> - | Q6: =IF(J6="","",INT(YEARFRAC($J6, TODAY()))) | R6: =IF(Q6="","","Age: " & Q6) | S6: =RIGHT(ROUND(VLOOKUP(B6,INPUT_RANGE,54,FALSE)/VLOOKUP(B6,INPUT_RANGE,52,FALSE),3),4) -> #N/A | T6: =VLOOKUP($B6,INPUT_RANGE,57,FALSE) -> #N/A | U6: ="D:\IMS Images\Headshots\"&IF('Team Info'!$B$21="BASEBALL","CBASE","SBALL")&"\"&'Team Info'!$B$11&"\"&D6&"_"&C6&".png" -> D:\IMS Images\Headshots\CBASE\GENERIC_BASEBALL\-_-.png | V6: ="D:\IMS Images\ActionShots\"&IF('Team Info'!$B$21="BASEBALL","CBASE","SBALL")&"\"&'Team Info'!$B$11&"\"&D6&"_"&C6&".png" -> D:\IMS Images\ActionShots\CBASE\GENERIC_BASEBALL\-_-.png | W6: =B6 & " " & X6 -> 3 - - | X6: =C6&" "&D6 -> - - | Y6: =UPPER(X6) -> - - | Z6: =LEFT(C6,1)&". "&D6 -> -. - | AA6: =UPPER(C6) -> - | AB6: =UPPER(D6) -> - | AC6: =IF($L6=4,"Senior",IF($L6=3,"Junior",IF($L6=2,"Sophomore",IF($L6=1,"Freshman","")))) | AD6: =IF($L6=4,"SR",IF($L6=3,"JR",IF($L6=2,"SO",IF($L6=1,"FR","")))) | AE6: =UPPER(AC6) | AF6: =$I6 & " lbs" -> - lbs | AG6: ="MAJOR: " & UPPER(M6) -> MAJOR: - | AH6: =B6 & " " & UPPER(X6) -> 3 - - | AI6: =IF(T6=0,"1st",$T6+1&IF(AND(MOD(ABS($T6+1),100)>10,MOD(ABS($T6+1),100)<14),"th",CHOOSE(MOD(ABS($T6+1),10)+1,"th","st","nd","rd","th","th","th","th","th","th"))) -> #N/A
A7: 4 | B7: 4 | C7: =IFERROR(INDEX(NAME_RANGE,MATCH(B7,NUM_RANGE,FALSE),2),"-") -> - | D7: =IFERROR(INDEX(NAME_RANGE,MATCH(B7,NUM_RANGE,FALSE),1),"-") -> - | E7: =IFERROR(VLOOKUP($B7,INPUT_RANGE,2,FALSE),"-") -> - | F7: =IFERROR(VLOOKUP($B7,INPUT_RANGE,3,FALSE),"-") -> - | G7: =IFERROR(VLOOKUP($B7,INPUT_RANGE,4,FALSE),"-") -> - | H7: =IFERROR(VLOOKUP($B7,INPUT_RANGE,7,FALSE),"-") -> - | I7: =IFERROR(VLOOKUP($B7,INPUT_RANGE,8,FALSE),"-") -> - | K7: =IFERROR(VLOOKUP($B7,INPUT_RANGE,5,FALSE)&", "&VLOOKUP($B7,INPUT_RANGE,6,FALSE),"-") -> - | L7: =IFERROR(VLOOKUP($B7,INPUT_RANGE,9,FALSE),"-") -> - | M7: =IFERROR(VLOOKUP($B7,INPUT_RANGE,11,FALSE),"-") -> - | N7: =IFERROR(VLOOKUP($B7,INPUT_RANGE,12,FALSE),"-") -> - | P7: HDR_SEL | Q7: =IF(J7="","",INT(YEARFRAC($J7, TODAY()))) | R7: =IF(Q7="","","Age: " & Q7) | S7: =RIGHT(ROUND(VLOOKUP(B7,INPUT_RANGE,54,FALSE)/VLOOKUP(B7,INPUT_RANGE,52,FALSE),3),4) -> #N/A | T7: =VLOOKUP($B7,INPUT_RANGE,57,FALSE) -> #N/A | U7: ="D:\IMS Images\Headshots\"&IF('Team Info'!$B$21="BASEBALL","CBASE","SBALL")&"\"&'Team Info'!$B$11&"\"&D7&"_"&C7&".png" -> D:\IMS Images\Headshots\CBASE\GENERIC_BASEBALL\-_-.png | V7: ="D:\IMS Images\ActionShots\"&IF('Team Info'!$B$21="BASEBALL","CBASE","SBALL")&"\"&'Team Info'!$B$11&"\"&D7&"_"&C7&".png" -> D:\IMS Images\ActionShots\CBASE\GENERIC_BASEBALL\-_-.png | W7: =B7 & " " & X7 -> 4 - - | X7: =C7&" "&D7 -> - - | Y7: =UPPER(X7) -> - - | Z7: =LEFT(C7,1)&". "&D7 -> -. - | AA7: =UPPER(C7) -> - | AB7: =UPPER(D7) -> - | AC7: =IF($L7=4,"Senior",IF($L7=3,"Junior",IF($L7=2,"Sophomore",IF($L7=1,"Freshman","")))) | AD7: =IF($L7=4,"SR",IF($L7=3,"JR",IF($L7=2,"SO",IF($L7=1,"FR","")))) | AE7: =UPPER(AC7) | AF7: =$I7 & " lbs" -> - lbs | AG7: ="MAJOR: " & UPPER(M7) -> MAJOR: - | AH7: =B7 & " " & UPPER(X7) -> 4 - - | AI7: =IF(T7=0,"1st",$T7+1&IF(AND(MOD(ABS($T7+1),100)>10,MOD(ABS($T7+1),100)<14),"th",CHOOSE(MOD(ABS($T7+1),10)+1,"th","st","nd","rd","th","th","th","th","th","th"))) -> #N/A
A8: 5 | B8: 5 | C8: =IFERROR(INDEX(NAME_RANGE,MATCH(B8,NUM_RANGE,FALSE),2),"-") -> - | D8: =IFERROR(INDEX(NAME_RANGE,MATCH(B8,NUM_RANGE,FALSE),1),"-") -> - | E8: =IFERROR(VLOOKUP($B8,INPUT_RANGE,2,FALSE),"-") -> - | F8: =IFERROR(VLOOKUP($B8,INPUT_RANGE,3,FALSE),"-") -> - | G8: =IFERROR(VLOOKUP($B8,INPUT_RANGE,4,FALSE),"-") -> - | H8: =IFERROR(VLOOKUP($B8,INPUT_RANGE,7,FALSE),"-") -> - | I8: =IFERROR(VLOOKUP($B8,INPUT_RANGE,8,FALSE),"-") -> - | K8: =IFERROR(VLOOKUP($B8,INPUT_RANGE,5,FALSE)&", "&VLOOKUP($B8,INPUT_RANGE,6,FALSE),"-") -> - | L8: =IFERROR(VLOOKUP($B8,INPUT_RANGE,9,FALSE),"-") -> - | M8: =IFERROR(VLOOKUP($B8,INPUT_RANGE,11,FALSE),"-") -> - | N8: =IFERROR(VLOOKUP($B8,INPUT_RANGE,12,FALSE),"-") -> - | P8: Header | Q8: =IF(J8="","",INT(YEARFRAC($J8, TODAY()))) | R8: =IF(Q8="","","Age: " & Q8) | S8: =RIGHT(ROUND(VLOOKUP(B8,INPUT_RANGE,54,FALSE)/VLOOKUP(B8,INPUT_RANGE,52,FALSE),3),4) -> #N/A | T8: =VLOOKUP($B8,INPUT_RANGE,57,FALSE) -> #N/A | U8: ="D:\IMS Images\Headshots\"&IF('Team Info'!$B$21="BASEBALL","CBASE","SBALL")&"\"&'Team Info'!$B$11&"\"&D8&"_"&C8&".png" -> D:\IMS Images\Headshots\CBASE\GENERIC_BASEBALL\-_-.png | V8: ="D:\IMS Images\ActionShots\"&IF('Team Info'!$B$21="BASEBALL","CBASE","SBALL")&"\"&'Team Info'!$B$11&"\"&D8&"_"&C8&".png" -> D:\IMS Images\ActionShots\CBASE\GENERIC_BASEBALL\-_-.png | W8: =B8 & " " & X8 -> 5 - - | X8: =C8&" "&D8 -> - - | Y8: =UPPER(X8) -> - - | Z8: =LEFT(C8,1)&". "&D8 -> -. - | AA8: =UPPER(C8) -> - | AB8: =UPPER(D8) -> - | AC8: =IF($L8=4,"Senior",IF($L8=3,"Junior",IF($L8=2,"Sophomore",IF($L8=1,"Freshman","")))) | AD8: =IF($L8=4,"SR",IF($L8=3,"JR",IF($L8=2,"SO",IF($L8=1,"FR","")))) | AE8: =UPPER(AC8) | AF8: =$I8 & " lbs" -> - lbs | AG8: ="MAJOR: " & UPPER(M8) -> MAJOR: - | AH8: =B8 & " " & UPPER(X8) -> 5 - - | AI8: =IF(T8=0,"1st",$T8+1&IF(AND(MOD(ABS($T8+1),100)>10,MOD(ABS($T8+1),100)<14),"th",CHOOSE(MOD(ABS($T8+1),10)+1,"th","st","nd","rd","th","th","th","th","th","th"))) -> #N/A
A9: 6 | B9: 6 | C9: =IFERROR(INDEX(NAME_RANGE,MATCH(B9,NUM_RANGE,FALSE),2),"-") -> - | D9: =IFERROR(INDEX(NAME_RANGE,MATCH(B9,NUM_RANGE,FALSE),1),"-") -> - | E9: =IFERROR(VLOOKUP($B9,INPUT_RANGE,2,FALSE),"-") -> - | F9: =IFERROR(VLOOKUP($B9,INPUT_RANGE,3,FALSE),"-") -> - | G9: =IFERROR(VLOOKUP($B9,INPUT_RANGE,4,FALSE),"-") -> - | H9: =IFERROR(VLOOKUP($B9,INPUT_RANGE,7,FALSE),"-") -> - | I9: =IFERROR(VLOOKUP($B9,INPUT_RANGE,8,FALSE),"-") -> - | K9: =IFERROR(VLOOKUP($B9,INPUT_RANGE,5,FALSE)&", "&VLOOKUP($B9,INPUT_RANGE,6,FALSE),"-") -> - | L9: =IFERROR(VLOOKUP($B9,INPUT_RANGE,9,FALSE),"-") -> - | M9: =IFERROR(VLOOKUP($B9,INPUT_RANGE,11,FALSE),"-") -> - | N9: =IFERROR(VLOOKUP($B9,INPUT_RANGE,12,FALSE),"-") -> - | P9: Major | Q9: =IF(J9="","",INT(YEARFRAC($J9, TODAY()))) | R9: =IF(Q9="","","Age: " & Q9) | S9: =RIGHT(ROUND(VLOOKUP(B9,INPUT_RANGE,54,FALSE)/VLOOKUP(B9,INPUT_RANGE,52,FALSE),3),4) -> #N/A | T9: =VLOOKUP($B9,INPUT_RANGE,57,FALSE) -> #N/A | U9: ="D:\IMS Images\Headshots\"&IF('Team Info'!$B$21="BASEBALL","CBASE","SBALL")&"\"&'Team Info'!$B$11&"\"&D9&"_"&C9&".png" -> D:\IMS Images\Headshots\CBASE\GENERIC_BASEBALL\-_-.png | V9: ="D:\IMS Images\ActionShots\"&IF('Team Info'!$B$21="BASEBALL","CBASE","SBALL")&"\"&'Team Info'!$B$11&"\"&D9&"_"&C9&".png" -> D:\IMS Images\ActionShots\CBASE\GENERIC_BASEBALL\-_-.png | W9: =B9 & " " & X9 -> 6 - - | X9: =C9&" "&D9 -> - - | Y9: =UPPER(X9) -> - - | Z9: =LEFT(C9,1)&". "&D9 -> -. - | AA9: =UPPER(C9) -> - | AB9: =UPPER(D9) -> - | AC9: =IF($L9=4,"Senior",IF($L9=3,"Junior",IF($L9=2,"Sophomore",IF($L9=1,"Freshman","")))) | AD9: =IF($L9=4,"SR",IF($L9=3,"JR",IF($L9=2,"SO",IF($L9=1,"FR","")))) | AE9: =UPPER(AC9) | AF9: =$I9 & " lbs" -> - lbs | AG9: ="MAJOR: " & UPPER(M9) -> MAJOR: - | AH9: =B9 & " " & UPPER(X9) -> 6 - - | AI9: =IF(T9=0,"1st",$T9+1&IF(AND(MOD(ABS($T9+1),100)>10,MOD(ABS($T9+1),100)<14),"th",CHOOSE(MOD(ABS($T9+1),10)+1,"th","st","nd","rd","th","th","th","th","th","th"))) -> #N/A
A10: 7 | B10: 7 | C10: =IFERROR(INDEX(NAME_RANGE,MATCH(B10,NUM_RANGE,FALSE),2),"-") -> - | D10: =IFERROR(INDEX(NAME_RANGE,MATCH(B10,NUM_RANGE,FALSE),1),"-") -> - | E10: =IFERROR(VLOOKUP($B10,INPUT_RANGE,2,FALSE),"-") -> - | F10: =IFERROR(VLOOKUP($B10,INPUT_RANGE,3,FALSE),"-") -> - | G10: =IFERROR(VLOOKUP($B10,INPUT_RANGE,4,FALSE),"-") -> - | H10: =IFERROR(VLOOKUP($B10,INPUT_RANGE,7,FALSE),"-") -> - | I10: =IFERROR(VLOOKUP($B10,INPUT_RANGE,8,FALSE),"-") -> - | K10: =IFERROR(VLOOKUP($B10,INPUT_RANGE,5,FALSE)&", "&VLOOKUP($B10,INPUT_RANGE,6,FALSE),"-") -> - | L10: =IFERROR(VLOOKUP($B10,INPUT_RANGE,9,FALSE),"-") -> - | M10: =IFERROR(VLOOKUP($B10,INPUT_RANGE,11,FALSE),"-") -> - | N10: =IFERROR(VLOOKUP($B10,INPUT_RANGE,12,FALSE),"-") -> - | Q10: =IF(J10="","",INT(YEARFRAC($J10, TODAY()))) | R10: =IF(Q10="","","Age: " & Q10) | S10: =RIGHT(ROUND(VLOOKUP(B10,INPUT_RANGE,54,FALSE)/VLOOKUP(B10,INPUT_RANGE,52,FALSE),3),4) -> #N/A | T10: =VLOOKUP($B10,INPUT_RANGE,57,FALSE) -> #N/A | U10: ="D:\IMS Images\Headshots\"&IF('Team Info'!$B$21="BASEBALL","CBASE","SBALL")&"\"&'Team Info'!$B$11&"\"&D10&"_"&C10&".png" -> D:\IMS Images\Headshots\CBASE\GENERIC_BASEBALL\-_-.png | V10: ="D:\IMS Images\ActionShots\"&IF('Team Info'!$B$21="BASEBALL","CBASE","SBALL")&"\"&'Team Info'!$B$11&"\"&D10&"_"&C10&".png" -> D:\IMS Images\ActionShots\CBASE\GENERIC_BASEBALL\-_-.png | W10: =B10 & " " & X10 -> 7 - - | X10: =C10&" "&D10 -> - - | Y10: =UPPER(X10) -> - - | Z10: =LEFT(C10,1)&". "&D10 -> -. - | AA10: =UPPER(C10) -> - | AB10: =UPPER(D10) -> - | AC10: =IF($L10=4,"Senior",IF($L10=3,"Junior",IF($L10=2,"Sophomore",IF($L10=1,"Freshman","")))) | AD10: =IF($L10=4,"SR",IF($L10=3,"JR",IF($L10=2,"SO",IF($L10=1,"FR","")))) | AE10: =UPPER(AC10) | AF10: =$I10 & " lbs" -> - lbs | AG10: ="MAJOR: " & UPPER(M10) -> MAJOR: - | AH10: =B10 & " " & UPPER(X10) -> 7 - - | AI10: =IF(T10=0,"1st",$T10+1&IF(AND(MOD(ABS($T10+1),100)>10,MOD(ABS($T10+1),100)<14),"th",CHOOSE(MOD(ABS($T10+1),10)+1,"th","st","nd","rd","th","th","th","th","th","th"))) -> #N/A
A11: 8 | B11: 8 | C11: =IFERROR(INDEX(NAME_RANGE,MATCH(B11,NUM_RANGE,FALSE),2),"-") -> - | D11: =IFERROR(INDEX(NAME_RANGE,MATCH(B11,NUM_RANGE,FALSE),1),"-") -> - | E11: =IFERROR(VLOOKUP($B11,INPUT_RANGE,2,FALSE),"-") -> - | F11: =IFERROR(VLOOKUP($B11,INPUT_RANGE,3,FALSE),"-") -> - | G11: =IFERROR(VLOOKUP($B11,INPUT_RANGE,4,FALSE),"-") -> - | H11: =IFERROR(VLOOKUP($B11,INPUT_RANGE,7,FALSE),"-") -> - | I11: =IFERROR(VLOOKUP($B11,INPUT_RANGE,8,FALSE),"-") -> - | K11: =IFERROR(VLOOKUP($B11,INPUT_RANGE,5,FALSE)&", "&VLOOKUP($B11,INPUT_RANGE,6,FALSE),"-") -> - | L11: =IFERROR(VLOOKUP($B11,INPUT_RANGE,9,FALSE),"-") -> - | M11: =IFERROR(VLOOKUP($B11,INPUT_RANGE,11,FALSE),"-") -> - | N11: =IFERROR(VLOOKUP($B11,INPUT_RANGE,12,FALSE),"-") -> - | Q11: =IF(J11="","",INT(YEARFRAC($J11, TODAY()))) | R11: =IF(Q11="","","Age: " & Q11) | S11: =RIGHT(ROUND(VLOOKUP(B11,INPUT_RANGE,54,FALSE)/VLOOKUP(B11,INPUT_RANGE,52,FALSE),3),4) -> #N/A | T11: =VLOOKUP($B11,INPUT_RANGE,57,FALSE) -> #N/A | U11: ="D:\IMS Images\Headshots\"&IF('Team Info'!$B$21="BASEBALL","CBASE","SBALL")&"\"&'Team Info'!$B$11&"\"&D11&"_"&C11&".png" -> D:\IMS Images\Headshots\CBASE\GENERIC_BASEBALL\-_-.png | V11: ="D:\IMS Images\ActionShots\"&IF('Team Info'!$B$21="BASEBALL","CBASE","SBALL")&"\"&'Team Info'!$B$11&"\"&D11&"_"&C11&".png" -> D:\IMS Images\ActionShots\CBASE\GENERIC_BASEBALL\-_-.png | W11: =B11 & " " & X11 -> 8 - - | X11: =C11&" "&D11 -> - - | Y11: =UPPER(X11) -> - - | Z11: =LEFT(C11,1)&". "&D11 -> -. - | AA11: =UPPER(C11) -> - | AB11: =UPPER(D11) -> - | AC11: =IF($L11=4,"Senior",IF($L11=3,"Junior",IF($L11=2,"Sophomore",IF($L11=1,"Freshman","")))) | AD11: =IF($L11=4,"SR",IF($L11=3,"JR",IF($L11=2,"SO",IF($L11=1,"FR","")))) | AE11: =UPPER(AC11) | AF11: =$I11 & " lbs" -> - lbs | AG11: ="MAJOR: " & UPPER(M11) -> MAJOR: - | AH11: =B11 & " " & UPPER(X11) -> 8 - - | AI11: =IF(T11=0,"1st",$T11+1&IF(AND(MOD(ABS($T11+1),100)>10,MOD(ABS($T11+1),100)<14),"th",CHOOSE(MOD(ABS($T11+1),10)+1,"th","st","nd","rd","th","th","th","th","th","th"))) -> #N/A
A12: 9 | B12: 9 | C12: =IFERROR(INDEX(NAME_RANGE,MATCH(B12,NUM_RANGE,FALSE),2),"-") -> - | D12: =IFERROR(INDEX(NAME_RANGE,MATCH(B12,NUM_RANGE,FALSE),1),"-") -> - | E12: =IFERROR(VLOOKUP($B12,INPUT_RANGE,2,FALSE),"-") -> - | F12: =IFERROR(VLOOKUP($B12,INPUT_RANGE,3,FALSE),"-") -> - | G12: =IFERROR(VLOOKUP($B12,INPUT_RANGE,4,FALSE),"-") -> - | H12: =IFERROR(VLOOKUP($B12,INPUT_RANGE,7,FALSE),"-") -> - | I12: =IFERROR(VLOOKUP($B12,INPUT_RANGE,8,FALSE),"-") -> - | K12: =IFERROR(VLOOKUP($B12,INPUT_RANGE,5,FALSE)&", "&VLOOKUP($B12,INPUT_RANGE,6,FALSE),"-") -> - | L12: =IFERROR(VLOOKUP($B12,INPUT_RANGE,9,FALSE),"-") -> - | M12: =IFERROR(VLOOKUP($B12,INPUT_RANGE,11,FALSE),"-") -> - | N12: =IFERROR(VLOOKUP($B12,INPUT_RANGE,12,FALSE),"-") -> - | Q12: =IF(J12="","",INT(YEARFRAC($J12, TODAY()))) | R12: =IF(Q12="","","Age: " & Q12) | S12: =RIGHT(ROUND(VLOOKUP(B12,INPUT_RANGE,54,FALSE)/VLOOKUP(B12,INPUT_RANGE,52,FALSE),3),4) -> #N/A | T12: =VLOOKUP($B12,INPUT_RANGE,57,FALSE) -> #N/A | U12: ="D:\IMS Images\Headshots\"&IF('Team Info'!$B$21="BASEBALL","CBASE","SBALL")&"\"&'Team Info'!$B$11&"\"&D12&"_"&C12&".png" -> D:\IMS Images\Headshots\CBASE\GENERIC_BASEBALL\-_-.png | V12: ="D:\IMS Images\ActionShots\"&IF('Team Info'!$B$21="BASEBALL","CBASE","SBALL")&"\"&'Team Info'!$B$11&"\"&D12&"_"&C12&".png" -> D:\IMS Images\ActionShots\CBASE\GENERIC_BASEBALL\-_-.png | W12: =B12 & " " & X12 -> 9 - - | X12: =C12&" "&D12 -> - - | Y12: =UPPER(X12) -> - - | Z12: =LEFT(C12,1)&". "&D12 -> -. - | AA12: =UPPER(C12) -> - | AB12: =UPPER(D12) -> - | AC12: =IF($L12=4,"Senior",IF($L12=3,"Junior",IF($L12=2,"Sophomore",IF($L12=1,"Freshman","")))) | AD12: =IF($L12=4,"SR",IF($L12=3,"JR",IF($L12=2,"SO",IF($L12=1,"FR","")))) | AE12: =UPPER(AC12) | AF12: =$I12 & " lbs" -> - lbs | AG12: ="MAJOR: " & UPPER(M12) -> MAJOR: - | AH12: =B12 & " " & UPPER(X12) -> 9 - - | AI12: =IF(T12=0,"1st",$T12+1&IF(AND(MOD(ABS($T12+1),100)>10,MOD(ABS($T12+1),100)<14),"th",CHOOSE(MOD(ABS($T12+1),10)+1,"th","st","nd","rd","th","th","th","th","th","th"))) -> #N/A
A13: 10 | B13: 10 | C13: =IFERROR(INDEX(NAME_RANGE,MATCH(B13,NUM_RANGE,FALSE),2),"-") -> - | D13: =IFERROR(INDEX(NAME_RANGE,MATCH(B13,NUM_RANGE,FALSE),1),"-") -> - | E13: =IFERROR(VLOOKUP($B13,INPUT_RANGE,2,FALSE),"-") -> - | F13: =IFERROR(VLOOKUP($B13,INPUT_RANGE,3,FALSE),"-") -> - | G13: =IFERROR(VLOOKUP($B13,INPUT_RANGE,4,FALSE),"-") -> - | H13: =IFERROR(VLOOKUP($B13,INPUT_RANGE,7,FALSE),"-") -> - | I13: =IFERROR(VLOOKUP($B13,INPUT_RANGE,8,FALSE),"-") -> - | K13: =IFERROR(VLOOKUP($B13,INPUT_RANGE,5,FALSE)&", "&VLOOKUP($B13,INPUT_RANGE,6,FALSE),"-") -> - | L13: =IFERROR(VLOOKUP($B13,INPUT_RANGE,9,FALSE),"-") -> - | M13: =IFERROR(VLOOKUP($B13,INPUT_RANGE,11,FALSE),"-") -> - | N13: =IFERROR(VLOOKUP($B13,INPUT_RANGE,12,FALSE),"-") -> - | Q13: =IF(J13="","",INT(YEARFRAC($J13, TODAY()))) | R13: =IF(Q13="","","Age: " & Q13) | S13: =RIGHT(ROUND(VLOOKUP(B13,INPUT_RANGE,54,FALSE)/VLOOKUP(B13,INPUT_RANGE,52,FALSE),3),4) -> #N/A | T13: =VLOOKUP($B13,INPUT_RANGE,57,FALSE) -> #N/A | U13: ="D:\IMS Images\Headshots\"&IF('Team Info'!$B$21="BASEBALL","CBASE","SBALL")&"\"&'Team Info'!$B$11&"\"&D13&"_"&C13&".png" -> D:\IMS Images\Headshots\CBASE\GENERIC_BASEBALL\-_-.png | V13: ="D:\IMS Images\ActionShots\"&IF('Team Info'!$B$21="BASEBALL","CBASE","SBALL")&"\"&'Team Info'!$B$11&"\"&D13&"_"&C13&".png" -> D:\IMS Images\ActionShots\CBASE\GENERIC_BASEBALL\-_-.png | W13: =B13 & " " & X13 -> 10 - - | X13: =C13&" "&D13 -> - - | Y13: =UPPER(X13) -> - - | Z13: =LEFT(C13,1)&". "&D13 -> -. - | AA13: =UPPER(C13) -> - | AB13: =UPPER(D13) -> - | AC13: =IF($L13=4,"Senior",IF($L13=3,"Junior",IF($L13=2,"Sophomore",IF($L13=1,"Freshman","")))) | AD13: =IF($L13=4,"SR",IF($L13=3,"JR",IF($L13=2,"SO",IF($L13=1,"FR","")))) | AE13: =UPPER(AC13) | AF13: =$I13 & " lbs" -> - lbs | AG13: ="MAJOR: " & UPPER(M13) -> MAJOR: - | AH13: =B13 & " " & UPPER(X13) -> 10 - - | AI13: =IF(T13=0,"1st",$T13+1&IF(AND(MOD(ABS($T13+1),100)>10,MOD(ABS($T13+1),100)<14),"th",CHOOSE(MOD(ABS($T13+1),10)+1,"th","st","nd","rd","th","th","th","th","th","th"))) -> #N/A
A14: 11 | B14: 11 | C14: =IFERROR(INDEX(NAME_RANGE,MATCH(B14,NUM_RANGE,FALSE),2),"-") -> - | D14: =IFERROR(INDEX(NAME_RANGE,MATCH(B14,NUM_RANGE,FALSE),1),"-") -> - | E14: =IFERROR(VLOOKUP($B14,INPUT_RANGE,2,FALSE),"-") -> - | F14: =IFERROR(VLOOKUP($B14,INPUT_RANGE,3,FALSE),"-") -> - | G14: =IFERROR(VLOOKUP($B14,INPUT_RANGE,4,FALSE),"-") -> - | H14: =IFERROR(VLOOKUP($B14,INPUT_RANGE,7,FALSE),"-") -> - | I14: =IFERROR(VLOOKUP($B14,INPUT_RANGE,8,FALSE),"-") -> - | K14: =IFERROR(VLOOKUP($B14,INPUT_RANGE,5,FALSE)&", "&VLOOKUP($B14,INPUT_RANGE,6,FALSE),"-") -> - | L14: =IFERROR(VLOOKUP($B14,INPUT_RANGE,9,FALSE),"-") -> - | M14: =IFERROR(VLOOKUP($B14,INPUT_RANGE,11,FALSE),"-") -> - | N14: =IFERROR(VLOOKUP($B14,INPUT_RANGE,12,FALSE),"-") -> - | Q14: =IF(J14="","",INT(YEARFRAC($J14, TODAY()))) | R14: =IF(Q14="","","Age: " & Q14) | S14: =RIGHT(ROUND(VLOOKUP(B14,INPUT_RANGE,54,FALSE)/VLOOKUP(B14,INPUT_RANGE,52,FALSE),3),4) -> #N/A | T14: =VLOOKUP($B14,INPUT_RANGE,57,FALSE) -> #N/A | U14: ="D:\IMS Images\Headshots\"&IF('Team Info'!$B$21="BASEBALL","CBASE","SBALL")&"\"&'Team Info'!$B$11&"\"&D14&"_"&C14&".png" -> D:\IMS Images\Headshots\CBASE\GENERIC_BASEBALL\-_-.png | V14: ="D:\IMS Images\ActionShots\"&IF('Team Info'!$B$21="BASEBALL","CBASE","SBALL")&"\"&'Team Info'!$B$11&"\"&D14&"_"&C14&".png" -> D:\IMS Images\ActionShots\CBASE\GENERIC_BASEBALL\-_-.png | W14: =B14 & " " & X14 -> 11 - - | X14: =C14&" "&D14 -> - - | Y14: =UPPER(X14) -> - - | Z14: =LEFT(C14,1)&". "&D14 -> -. - | AA14: =UPPER(C14) -> - | AB14: =UPPER(D14) -> - | AC14: =IF($L14=4,"Senior",IF($L14=3,"Junior",IF($L14=2,"Sophomore",IF($L14=1,"Freshman","")))) | AD14: =IF($L14=4,"SR",IF($L14=3,"JR",IF($L14=2,"SO",IF($L14=1,"FR","")))) | AE14: =UPPER(AC14) | AF14: =$I14 & " lbs" -> - lbs | AG14: ="MAJOR: " & UPPER(M14) -> MAJOR: - | AH14: =B14 & " " & UPPER(X14) -> 11 - - | AI14: =IF(T14=0,"1st",$T14+1&IF(AND(MOD(ABS($T14+1),100)>10,MOD(ABS($T14+1),100)<14),"th",CHOOSE(MOD(ABS($T14+1),10)+1,"th","st","nd","rd","th","th","th","th","th","th"))) -> #N/A
A15: 12 | B15: 12 | C15: =IFERROR(INDEX(NAME_RANGE,MATCH(B15,NUM_RANGE,FALSE),2),"-") -> - | D15: =IFERROR(INDEX(NAME_RANGE,MATCH(B15,NUM_RANGE,FALSE),1),"-") -> - | E15: =IFERROR(VLOOKUP($B15,INPUT_RANGE,2,FALSE),"-") -> - | F15: =IFERROR(VLOOKUP($B15,INPUT_RANGE,3,FALSE),"-") -> - | G15: =IFERROR(VLOOKUP($B15,INPUT_RANGE,4,FALSE),"-") -> - | H15: =IFERROR(VLOOKUP($B15,INPUT_RANGE,7,FALSE),"-") -> - | I15: =IFERROR(VLOOKUP($B15,INPUT_RANGE,8,FALSE),"-") -> - | K15: =IFERROR(VLOOKUP($B15,INPUT_RANGE,5,FALSE)&", "&VLOOKUP($B15,INPUT_RANGE,6,FALSE),"-") -> - | L15: =IFERROR(VLOOKUP($B15,INPUT_RANGE,9,FALSE),"-") -> - | M15: =IFERROR(VLOOKUP($B15,INPUT_RANGE,11,FALSE),"-") -> - | N15: =IFERROR(VLOOKUP($B15,INPUT_RANGE,12,FALSE),"-") -> - | Q15: =IF(J15="","",INT(YEARFRAC($J15, TODAY()))) | R15: =IF(Q15="","","Age: " & Q15) | S15: =RIGHT(ROUND(VLOOKUP(B15,INPUT_RANGE,54,FALSE)/VLOOKUP(B15,INPUT_RANGE,52,FALSE),3),4) -> #N/A | T15: =VLOOKUP($B15,INPUT_RANGE,57,FALSE) -> #N/A | U15: ="D:\IMS Images\Headshots\"&IF('Team Info'!$B$21="BASEBALL","CBASE","SBALL")&"\"&'Team Info'!$B$11&"\"&D15&"_"&C15&".png" -> D:\IMS Images\Headshots\CBASE\GENERIC_BASEBALL\-_-.png | V15: ="D:\IMS Images\ActionShots\"&IF('Team Info'!$B$21="BASEBALL","CBASE","SBALL")&"\"&'Team Info'!$B$11&"\"&D15&"_"&C15&".png" -> D:\IMS Images\ActionShots\CBASE\GENERIC_BASEBALL\-_-.png | W15: =B15 & " " & X15 -> 12 - - | X15: =C15&" "&D15 -> - - | Y15: =UPPER(X15) -> - - | Z15: =LEFT(C15,1)&". "&D15 -> -. - | AA15: =UPPER(C15) -> - | AB15: =UPPER(D15) -> - | AC15: =IF($L15=4,"Senior",IF($L15=3,"Junior",IF($L15=2,"Sophomore",IF($L15=1,"Freshman","")))) | AD15: =IF($L15=4,"SR",IF($L15=3,"JR",IF($L15=2,"SO",IF($L15=1,"FR","")))) | AE15: =UPPER(AC15) | AF15: =$I15 & " lbs" -> - lbs | AG15: ="MAJOR: " & UPPER(M15) -> MAJOR: - | AH15: =B15 & " " & UPPER(X15) -> 12 - - | AI15: =IF(T15=0,"1st",$T15+1&IF(AND(MOD(ABS($T15+1),100)>10,MOD(ABS($T15+1),100)<14),"th",CHOOSE(MOD(ABS($T15+1),10)+1,"th","st","nd","rd","th","th","th","th","th","th"))) -> #N/A
A16: 13 | B16: 13 | C16: =IFERROR(INDEX(NAME_RANGE,MATCH(B16,NUM_RANGE,FALSE),2),"-") -> - | D16: =IFERROR(INDEX(NAME_RANGE,MATCH(B16,NUM_RANGE,FALSE),1),"-") -> - | E16: =IFERROR(VLOOKUP($B16,INPUT_RANGE,2,FALSE),"-") -> - | F16: =IFERROR(VLOOKUP($B16,INPUT_RANGE,3,FALSE),"-") -> - | G16: =IFERROR(VLOOKUP($B16,INPUT_RANGE,4,FALSE),"-") -> - | H16: =IFERROR(VLOOKUP($B16,INPUT_RANGE,7,FALSE),"-") -> - | I16: =IFERROR(VLOOKUP($B16,INPUT_RANGE,8,FALSE),"-") -> - | K16: =IFERROR(VLOOKUP($B16,INPUT_RANGE,5,FALSE)&", "&VLOOKUP($B16,INPUT_RANGE,6,FALSE),"-") -> - | L16: =IFERROR(VLOOKUP($B16,INPUT_RANGE,9,FALSE),"-") -> - | M16: =IFERROR(VLOOKUP($B16,INPUT_RANGE,11,FALSE),"-") -> - | N16: =IFERROR(VLOOKUP($B16,INPUT_RANGE,12,FALSE),"-") -> - | Q16: =IF(J16="","",INT(YEARFRAC($J16, TODAY()))) | R16: =IF(Q16="","","Age: " & Q16) | S16: =RIGHT(ROUND(VLOOKUP(B16,INPUT_RANGE,54,FALSE)/VLOOKUP(B16,INPUT_RANGE,52,FALSE),3),4) -> #N/A | T16: =VLOOKUP($B16,INPUT_RANGE,57,FALSE) -> #N/A | U16: ="D:\IMS Images\Headshots\"&IF('Team Info'!$B$21="BASEBALL","CBASE","SBALL")&"\"&'Team Info'!$B$11&"\"&D16&"_"&C16&".png" -> D:\IMS Images\Headshots\CBASE\GENERIC_BASEBALL\-_-.png | V16: ="D:\IMS Images\ActionShots\"&IF('Team Info'!$B$21="BASEBALL","CBASE","SBALL")&"\"&'Team Info'!$B$11&"\"&D16&"_"&C16&".png" -> D:\IMS Images\ActionShots\CBASE\GENERIC_BASEBALL\-_-.png | W16: =B16 & " " & X16 -> 13 - - | X16: =C16&" "&D16 -> - - | Y16: =UPPER(X16) -> - - | Z16: =LEFT(C16,1)&". "&D16 -> -. - | AA16: =UPPER(C16) -> - | AB16: =UPPER(D16) -> - | AC16: =IF($L16=4,"Senior",IF($L16=3,"Junior",IF($L16=2,"Sophomore",IF($L16=1,"Freshman","")))) | AD16: =IF($L16=4,"SR",IF($L16=3,"JR",IF($L16=2,"SO",IF($L16=1,"FR","")))) | AE16: =UPPER(AC16) | AF16: =$I16 & " lbs" -> - lbs | AG16: ="MAJOR: " & UPPER(M16) -> MAJOR: - | AH16: =B16 & " " & UPPER(X16) -> 13 - - | AI16: =IF(T16=0,"1st",$T16+1&IF(AND(MOD(ABS($T16+1),100)>10,MOD(ABS($T16+1),100)<14),"th",CHOOSE(MOD(ABS($T16+1),10)+1,"th","st","nd","rd","th","th","th","th","th","th"))) -> #N/A
A17: 14 | B17: 14 | C17: =IFERROR(INDEX(NAME_RANGE,MATCH(B17,NUM_RANGE,FALSE),2),"-") -> - | D17: =IFERROR(INDEX(NAME_RANGE,MATCH(B17,NUM_RANGE,FALSE),1),"-") -> - | E17: =IFERROR(VLOOKUP($B17,INPUT_RANGE,2,FALSE),"-") -> - | F17: =IFERROR(VLOOKUP($B17,INPUT_RANGE,3,FALSE),"-") -> - | G17: =IFERROR(VLOOKUP($B17,INPUT_RANGE,4,FALSE),"-") -> - | H17: =IFERROR(VLOOKUP($B17,INPUT_RANGE,7,FALSE),"-") -> - | I17: =IFERROR(VLOOKUP($B17,INPUT_RANGE,8,FALSE),"-") -> - | K17: =IFERROR(VLOOKUP($B17,INPUT_RANGE,5,FALSE)&", "&VLOOKUP($B17,INPUT_RANGE,6,FALSE),"-") -> - | L17: =IFERROR(VLOOKUP($B17,INPUT_RANGE,9,FALSE),"-") -> - | M17: =IFERROR(VLOOKUP($B17,INPUT_RANGE,11,FALSE),"-") -> - | N17: =IFERROR(VLOOKUP($B17,INPUT_RANGE,12,FALSE),"-") -> - | Q17: =IF(J17="","",INT(YEARFRAC($J17, TODAY()))) | R17: =IF(Q17="","","Age: " & Q17) | S17: =RIGHT(ROUND(VLOOKUP(B17,INPUT_RANGE,54,FALSE)/VLOOKUP(B17,INPUT_RANGE,52,FALSE),3),4) -> #N/A | T17: =VLOOKUP($B17,INPUT_RANGE,57,FALSE) -> #N/A | U17: ="D:\IMS Images\Headshots\"&IF('Team Info'!$B$21="BASEBALL","CBASE","SBALL")&"\"&'Team Info'!$B$11&"\"&D17&"_"&C17&".png" -> D:\IMS Images\Headshots\CBASE\GENERIC_BASEBALL\-_-.png | V17: ="D:\IMS Images\ActionShots\"&IF('Team Info'!$B$21="BASEBALL","CBASE","SBALL")&"\"&'Team Info'!$B$11&"\"&D17&"_"&C17&".png" -> D:\IMS Images\ActionShots\CBASE\GENERIC_BASEBALL\-_-.png | W17: =B17 & " " & X17 -> 14 - - | X17: =C17&" "&D17 -> - - | Y17: =UPPER(X17) -> - - | Z17: =LEFT(C17,1)&". "&D17 -> -. - | AA17: =UPPER(C17) -> - | AB17: =UPPER(D17) -> - | AC17: =IF($L17=4,"Senior",IF($L17=3,"Junior",IF($L17=2,"Sophomore",IF($L17=1,"Freshman","")))) | AD17: =IF($L17=4,"SR",IF($L17=3,"JR",IF($L17=2,"SO",IF($L17=1,"FR","")))) | AE17: =UPPER(AC17) | AF17: =$I17 & " lbs" -> - lbs | AG17: ="MAJOR: " & UPPER(M17) -> MAJOR: - | AH17: =B17 & " " & UPPER(X17) -> 14 - - | AI17: =IF(T17=0,"1st",$T17+1&IF(AND(MOD(ABS($T17+1),100)>10,MOD(ABS($T17+1),100)<14),"th",CHOOSE(MOD(ABS($T17+1),10)+1,"th","st","nd","rd","th","th","th","th","th","th"))) -> #N/A
A18: 15 | B18: 15 | C18: =IFERROR(INDEX(NAME_RANGE,MATCH(B18,NUM_RANGE,FALSE),2),"-") -> - | D18: =IFERROR(INDEX(NAME_RANGE,MATCH(B18,NUM_RANGE,FALSE),1),"-") -> - | E18: =IFERROR(VLOOKUP($B18,INPUT_RANGE,2,FALSE),"-") -> - | F18: =IFERROR(VLOOKUP($B18,INPUT_RANGE,3,FALSE),"-") -> - | G18: =IFERROR(VLOOKUP($B18,INPUT_RANGE,4,FALSE),"-") -> - | H18: =IFERROR(VLOOKUP($B18,INPUT_RANGE,7,FALSE),"-") -> - | I18: =IFERROR(VLOOKUP($B18,INPUT_RANGE,8,FALSE),"-") -> - | K18: =IFERROR(VLOOKUP($B18,INPUT_RANGE,5,FALSE)&", "&VLOOKUP($B18,INPUT_RANGE,6,FALSE),"-") -> - | L18: =IFERROR(VLOOKUP($B18,INPUT_RANGE,9,FALSE),"-") -> - | M18: =IFERROR(VLOOKUP($B18,INPUT_RANGE,11,FALSE),"-") -> - | N18: =IFERROR(VLOOKUP($B18,INPUT_RANGE,12,FALSE),"-") -> - | Q18: =IF(J18="","",INT(YEARFRAC($J18, TODAY()))) | R18: =IF(Q18="","","Age: " & Q18) | S18: =RIGHT(ROUND(VLOOKUP(B18,INPUT_RANGE,54,FALSE)/VLOOKUP(B18,INPUT_RANGE,52,FALSE),3),4) -> #N/A | T18: =VLOOKUP($B18,INPUT_RANGE,57,FALSE) -> #N/A | U18: ="D:\IMS Images\Headshots\"&IF('Team Info'!$B$21="BASEBALL","CBASE","SBALL")&"\"&'Team Info'!$B$11&"\"&D18&"_"&C18&".png" -> D:\IMS Images\Headshots\CBASE\GENERIC_BASEBALL\-_-.png | V18: ="D:\IMS Images\ActionShots\"&IF('Team Info'!$B$21="BASEBALL","CBASE","SBALL")&"\"&'Team Info'!$B$11&"\"&D18&"_"&C18&".png" -> D:\IMS Images\ActionShots\CBASE\GENERIC_BASEBALL\-_-.png | W18: =B18 & " " & X18 -> 15 - - | X18: =C18&" "&D18 -> - - | Y18: =UPPER(X18) -> - - | Z18: =LEFT(C18,1)&". "&D18 -> -. - | AA18: =UPPER(C18) -> - | AB18: =UPPER(D18) -> - | AC18: =IF($L18=4,"Senior",IF($L18=3,"Junior",IF($L18=2,"Sophomore",IF($L18=1,"Freshman","")))) | AD18: =IF($L18=4,"SR",IF($L18=3,"JR",IF($L18=2,"SO",IF($L18=1,"FR","")))) | AE18: =UPPER(AC18) | AF18: =$I18 & " lbs" -> - lbs | AG18: ="MAJOR: " & UPPER(M18) -> MAJOR: - | AH18: =B18 & " " & UPPER(X18) -> 15 - - | AI18: =IF(T18=0,"1st",$T18+1&IF(AND(MOD(ABS($T18+1),100)>10,MOD(ABS($T18+1),100)<14),"th",CHOOSE(MOD(ABS($T18+1),10)+1,"th","st","nd","rd","th","th","th","th","th","th"))) -> #N/A
A19: 16 | B19: 16 | C19: =IFERROR(INDEX(NAME_RANGE,MATCH(B19,NUM_RANGE,FALSE),2),"-") -> - | D19: =IFERROR(INDEX(NAME_RANGE,MATCH(B19,NUM_RANGE,FALSE),1),"-") -> - | E19: =IFERROR(VLOOKUP($B19,INPUT_RANGE,2,FALSE),"-") -> - | F19: =IFERROR(VLOOKUP($B19,INPUT_RANGE,3,FALSE),"-") -> - | G19: =IFERROR(VLOOKUP($B19,INPUT_RANGE,4,FALSE),"-") -> - | H19: =IFERROR(VLOOKUP($B19,INPUT_RANGE,7,FALSE),"-") -> - | I19: =IFERROR(VLOOKUP($B19,INPUT_RANGE,8,FALSE),"-") -> - | K19: =IFERROR(VLOOKUP($B19,INPUT_RANGE,5,FALSE)&", "&VLOOKUP($B19,INPUT_RANGE,6,FALSE),"-") -> - | L19: =IFERROR(VLOOKUP($B19,INPUT_RANGE,9,FALSE),"-") -> - | M19: =IFERROR(VLOOKUP($B19,INPUT_RANGE,11,FALSE),"-") -> - | N19: =IFERROR(VLOOKUP($B19,INPUT_RANGE,12,FALSE),"-") -> - | Q19: =IF(J19="","",INT(YEARFRAC($J19, TODAY()))) | R19: =IF(Q19="","","Age: " & Q19) | S19: =RIGHT(ROUND(VLOOKUP(B19,INPUT_RANGE,54,FALSE)/VLOOKUP(B19,INPUT_RANGE,52,FALSE),3),4) -> #N/A | T19: =VLOOKUP($B19,INPUT_RANGE,57,FALSE) -> #N/A | U19: ="D:\IMS Images\Headshots\"&IF('Team Info'!$B$21="BASEBALL","CBASE","SBALL")&"\"&'Team Info'!$B$11&"\"&D19&"_"&C19&".png" -> D:\IMS Images\Headshots\CBASE\GENERIC_BASEBALL\-_-.png | V19: ="D:\IMS Images\ActionShots\"&IF('Team Info'!$B$21="BASEBALL","CBASE","SBALL")&"\"&'Team Info'!$B$11&"\"&D19&"_"&C19&".png" -> D:\IMS Images\ActionShots\CBASE\GENERIC_BASEBALL\-_-.png | W19: =B19 & " " & X19 -> 16 - - | X19: =C19&" "&D19 -> - - | Y19: =UPPER(X19) -> - - | Z19: =LEFT(C19,1)&". "&D19 -> -. - | AA19: =UPPER(C19) -> - | AB19: =UPPER(D19) -> - | AC19: =IF($L19=4,"Senior",IF($L19=3,"Junior",IF($L19=2,"Sophomore",IF($L19=1,"Freshman","")))) | AD19: =IF($L19=4,"SR",IF($L19=3,"JR",IF($L19=2,"SO",IF($L19=1,"FR","")))) | AE19: =UPPER(AC19) | AF19: =$I19 & " lbs" -> - lbs | AG19: ="MAJOR: " & UPPER(M19) -> MAJOR: - | AH19: =B19 & " " & UPPER(X19) -> 16 - - | AI19: =IF(T19=0,"1st",$T19+1&IF(AND(MOD(ABS($T19+1),100)>10,MOD(ABS($T19+1),100)<14),"th",CHOOSE(MOD(ABS($T19+1),10)+1,"th","st","nd","rd","th","th","th","th","th","th"))) -> #N/A
A20: 17 | B20: 17 | C20: =IFERROR(INDEX(NAME_RANGE,MATCH(B20,NUM_RANGE,FALSE),2),"-") -> - | D20: =IFERROR(INDEX(NAME_RANGE,MATCH(B20,NUM_RANGE,FALSE),1),"-") -> - | E20: =IFERROR(VLOOKUP($B20,INPUT_RANGE,2,FALSE),"-") -> - | F20: =IFERROR(VLOOKUP($B20,INPUT_RANGE,3,FALSE),"-") -> - | G20: =IFERROR(VLOOKUP($B20,INPUT_RANGE,4,FALSE),"-") -> - | H20: =IFERROR(VLOOKUP($B20,INPUT_RANGE,7,FALSE),"-") -> - | I20: =IFERROR(VLOOKUP($B20,INPUT_RANGE,8,FALSE),"-") -> - | K20: =IFERROR(VLOOKUP($B20,INPUT_RANGE,5,FALSE)&", "&VLOOKUP($B20,INPUT_RANGE,6,FALSE),"-") -> - | L20: =IFERROR(VLOOKUP($B20,INPUT_RANGE,9,FALSE),"-") -> - | M20: =IFERROR(VLOOKUP($B20,INPUT_RANGE,11,FALSE),"-") -> - | N20: =IFERROR(VLOOKUP($B20,INPUT_RANGE,12,FALSE),"-") -> - | Q20: =IF(J20="","",INT(YEARFRAC($J20, TODAY()))) | R20: =IF(Q20="","","Age: " & Q20) | S20: =RIGHT(ROUND(VLOOKUP(B20,INPUT_RANGE,54,FALSE)/VLOOKUP(B20,INPUT_RANGE,52,FALSE),3),4) -> #N/A | T20: =VLOOKUP($B20,INPUT_RANGE,57,FALSE) -> #N/A | U20: ="D:\IMS Images\Headshots\"&IF('Team Info'!$B$21="BASEBALL","CBASE","SBALL")&"\"&'Team Info'!$B$11&"\"&D20&"_"&C20&".png" -> D:\IMS Images\Headshots\CBASE\GENERIC_BASEBALL\-_-.png | V20: ="D:\IMS Images\ActionShots\"&IF('Team Info'!$B$21="BASEBALL","CBASE","SBALL")&"\"&'Team Info'!$B$11&"\"&D20&"_"&C20&".png" -> D:\IMS Images\ActionShots\CBASE\GENERIC_BASEBALL\-_-.png | W20: =B20 & " " & X20 -> 17 - - | X20: =C20&" "&D20 -> - - | Y20: =UPPER(X20) -> - - | Z20: =LEFT(C20,1)&". "&D20 -> -. - | AA20: =UPPER(C20) -> - | AB20: =UPPER(D20) -> - | AC20: =IF($L20=4,"Senior",IF($L20=3,"Junior",IF($L20=2,"Sophomore",IF($L20=1,"Freshman","")))) | AD20: =IF($L20=4,"SR",IF($L20=3,"JR",IF($L20=2,"SO",IF($L20=1,"FR","")))) | AE20: =UPPER(AC20) | AF20: =$I20 & " lbs" -> - lbs | AG20: ="MAJOR: " & UPPER(M20) -> MAJOR: - | AH20: =B20 & " " & UPPER(X20) -> 17 - - | AI20: =IF(T20=0,"1st",$T20+1&IF(AND(MOD(ABS($T20+1),100)>10,MOD(ABS($T20+1),100)<14),"th",CHOOSE(MOD(ABS($T20+1),10)+1,"th","st","nd","rd","th","th","th","th","th","th"))) -> #N/A
A21: 18 | B21: 18 | C21: =IFERROR(INDEX(NAME_RANGE,MATCH(B21,NUM_RANGE,FALSE),2),"-") -> - | D21: =IFERROR(INDEX(NAME_RANGE,MATCH(B21,NUM_RANGE,FALSE),1),"-") -> - | E21: =IFERROR(VLOOKUP($B21,INPUT_RANGE,2,FALSE),"-") -> - | F21: =IFERROR(VLOOKUP($B21,INPUT_RANGE,3,FALSE),"-") -> - | G21: =IFERROR(VLOOKUP($B21,INPUT_RANGE,4,FALSE),"-") -> - | H21: =IFERROR(VLOOKUP($B21,INPUT_RANGE,7,FALSE),"-") -> - | I21: =IFERROR(VLOOKUP($B21,INPUT_RANGE,8,FALSE),"-") -> - | K21: =IFERROR(VLOOKUP($B21,INPUT_RANGE,5,FALSE)&", "&VLOOKUP($B21,INPUT_RANGE,6,FALSE),"-") -> - | L21: =IFERROR(VLOOKUP($B21,INPUT_RANGE,9,FALSE),"-") -> - | M21: =IFERROR(VLOOKUP($B21,INPUT_RANGE,11,FALSE),"-") -> - | N21: =IFERROR(VLOOKUP($B21,INPUT_RANGE,12,FALSE),"-") -> - | Q21: =IF(J21="","",INT(YEARFRAC($J21, TODAY()))) | R21: =IF(Q21="","","Age: " & Q21) | S21: =RIGHT(ROUND(VLOOKUP(B21,INPUT_RANGE,54,FALSE)/VLOOKUP(B21,INPUT_RANGE,52,FALSE),3),4) -> #N/A | T21: =VLOOKUP($B21,INPUT_RANGE,57,FALSE) -> #N/A | U21: ="D:\IMS Images\Headshots\"&IF('Team Info'!$B$21="BASEBALL","CBASE","SBALL")&"\"&'Team Info'!$B$11&"\"&D21&"_"&C21&".png" -> D:\IMS Images\Headshots\CBASE\GENERIC_BASEBALL\-_-.png | V21: ="D:\IMS Images\ActionShots\"&IF('Team Info'!$B$21="BASEBALL","CBASE","SBALL")&"\"&'Team Info'!$B$11&"\"&D21&"_"&C21&".png" -> D:\IMS Images\ActionShots\CBASE\GENERIC_BASEBALL\-_-.png | W21: =B21 & " " & X21 -> 18 - - | X21: =C21&" "&D21 -> - - | Y21: =UPPER(X21) -> - - | Z21: =LEFT(C21,1)&". "&D21 -> -. - | AA21: =UPPER(C21) -> - | AB21: =UPPER(D21) -> - | AC21: =IF($L21=4,"Senior",IF($L21=3,"Junior",IF($L21=2,"Sophomore",IF($L21=1,"Freshman","")))) | AD21: =IF($L21=4,"SR",IF($L21=3,"JR",IF($L21=2,"SO",IF($L21=1,"FR","")))) | AE21: =UPPER(AC21) | AF21: =$I21 & " lbs" -> - lbs | AG21: ="MAJOR: " & UPPER(M21) -> MAJOR: - | AH21: =B21 & " " & UPPER(X21) -> 18 - - | AI21: =IF(T21=0,"1st",$T21+1&IF(AND(MOD(ABS($T21+1),100)>10,MOD(ABS($T21+1),100)<14),"th",CHOOSE(MOD(ABS($T21+1),10)+1,"th","st","nd","rd","th","th","th","th","th","th"))) -> #N/A
... A92: 89 | B92: 89 | C92: =IFERROR(INDEX(NAME_RANGE,MATCH(B92,NUM_RANGE,FALSE),2),"-") -> - | D92: =IFERROR(INDEX(NAME_RANGE,MATCH(B92,NUM_RANGE,FALSE),1),"-") -> - | E92: =IFERROR(VLOOKUP($B92,INPUT_RANGE,2,FALSE),"-") -> - | F92: =IFERROR(VLOOKUP($B92,INPUT_RANGE,3,FALSE),"-") -> - | G92: =IFERROR(VLOOKUP($B92,INPUT_RANGE,4,FALSE),"-") -> - | H92: =IFERROR(VLOOKUP($B92,INPUT_RANGE,7,FALSE),"-") -> - | I92: =IFERROR(VLOOKUP($B92,INPUT_RANGE,8,FALSE),"-") -> - | K92: =IFERROR(VLOOKUP($B92,INPUT_RANGE,5,FALSE)&", "&VLOOKUP($B92,INPUT_RANGE,6,FALSE),"-") -> - | L92: =IFERROR(VLOOKUP($B92,INPUT_RANGE,9,FALSE),"-") -> - | M92: =IFERROR(VLOOKUP($B92,INPUT_RANGE,11,FALSE),"-") -> - | N92: =IFERROR(VLOOKUP($B92,INPUT_RANGE,12,FALSE),"-") -> - | Q92: =IF(J92="","",INT(YEARFRAC($J92, TODAY()))) | R92: =IF(Q92="","","Age: " & Q92) | S92: =RIGHT(ROUND(VLOOKUP(B92,INPUT_RANGE,54,FALSE)/VLOOKUP(B92,INPUT_RANGE,52,FALSE),3),4) -> #N/A | T92: =VLOOKUP($B92,INPUT_RANGE,57,FALSE) -> #N/A | U92: ="D:\IMS Images\Headshots\"&IF('Team Info'!$B$21="BASEBALL","CBASE","SBALL")&"\"&'Team Info'!$B$11&"\"&D92&"_"&C92&".png" -> D:\IMS Images\Headshots\CBASE\GENERIC_BASEBALL\-_-.png | V92: ="D:\IMS Images\ActionShots\"&IF('Team Info'!$B$21="BASEBALL","CBASE","SBALL")&"\"&'Team Info'!$B$11&"\"&D92&"_"&C92&".png" -> D:\IMS Images\ActionShots\CBASE\GENERIC_BASEBALL\-_-.png | W92: =B92 & " " & X92 -> 89 - - | X92: =C92&" "&D92 -> - - | Y92: =UPPER(X92) -> - - | Z92: =LEFT(C92,1)&". "&D92 -> -. - | AA92: =UPPER(C92) -> - | AB92: =UPPER(D92) -> - | AC92: =IF($L92=4,"Senior",IF($L92=3,"Junior",IF($L92=2,"Sophomore",IF($L92=1,"Freshman","")))) | AD92: =IF($L92=4,"SR",IF($L92=3,"JR",IF($L92=2,"SO",IF($L92=1,"FR","")))) | AE92: =UPPER(AC92) | AF92: =$I92 & " lbs" -> - lbs | AG92: ="MAJOR: " & UPPER(M92) -> MAJOR: - | AH92: =B92 & " " & UPPER(X92) -> 89 - - | AI92: =IF(T92=0,"1st",$T92+1&IF(AND(MOD(ABS($T92+1),100)>10,MOD(ABS($T92+1),100)<14),"th",CHOOSE(MOD(ABS($T92+1),10)+1,"th","st","nd","rd","th","th","th","th","th","th"))) -> #N/A
A93: 90 | B93: 0 | C93: =IF(C$104=0,"",C$104) -> - | D93: =IF(D$104=0,"",D$104) -> - | E93: =IF(E$104=0,"",E$104) -> - | F93: =IF(F$104=0,"",F$104) -> - | G93: =IF(G$104=0,"",G$104) -> - | H93: =IF(H$104=0,"",H$104) -> - | I93: =IF(I$104=0,"",I$104) -> - | K93: =IF(K$104=0,"",K$104) -> - | L93: =IF(L$104=0,"",L$104) -> - | M93: =IF(M$104=0,"",M$104) -> - | N93: =IF(N$104=0,"",N$104) -> - | O93: =IF(O$104=0,"",O$104) | Q93: =IF(J93="","",INT(YEARFRAC($J93, TODAY()))) | R93: =IF(Q93="","","Age: " & Q93) | S93: =RIGHT(ROUND(VLOOKUP(B93,INPUT_RANGE,54,FALSE)/VLOOKUP(B93,INPUT_RANGE,52,FALSE),3),4) -> #N/A | T93: =VLOOKUP($B93,INPUT_RANGE,57,FALSE) -> #N/A | U93: ="D:\IMS Images\Headshots\"&IF('Team Info'!$B$21="BASEBALL","CBASE","SBALL")&"\"&'Team Info'!$B$11&"\"&D93&"_"&C93&".png" -> D:\IMS Images\Headshots\CBASE\GENERIC_BASEBALL\-_-.png | V93: ="D:\IMS Images\ActionShots\"&IF('Team Info'!$B$21="BASEBALL","CBASE","SBALL")&"\"&'Team Info'!$B$11&"\"&D93&"_"&C93&".png" -> D:\IMS Images\ActionShots\CBASE\GENERIC_BASEBALL\-_-.png | W93: =B93 & " " & X93 -> 0 - - | X93: =C93&" "&D93 -> - - | Y93: =UPPER(X93) -> - - | Z93: =LEFT(C93,1)&". "&D93 -> -. - | AA93: =UPPER(C93) -> - | AB93: =UPPER(D93) -> - | AC93: =IF($L93=4,"Senior",IF($L93=3,"Junior",IF($L93=2,"Sophomore",IF($L93=1,"Freshman","")))) | AD93: =IF($L93=4,"SR",IF($L93=3,"JR",IF($L93=2,"SO",IF($L93=1,"FR","")))) | AE93: =UPPER(AC93) | AF93: =$I93 & " lbs" -> - lbs | AG93: ="MAJOR: " & UPPER(M93) -> MAJOR: - | AH93: =B93 & " " & UPPER(X93) -> 0 - - | AI93: =IF(T93=0,"1st",$T93+1&IF(AND(MOD(ABS($T93+1),100)>10,MOD(ABS($T93+1),100)<14),"th",CHOOSE(MOD(ABS($T93+1),10)+1,"th","st","nd","rd","th","th","th","th","th","th"))) -> #N/A
A94: 91 | B94: 91 | C94: =IFERROR(INDEX(NAME_RANGE,MATCH(B94,NUM_RANGE,FALSE),2),"-") -> - | D94: =IFERROR(INDEX(NAME_RANGE,MATCH(B94,NUM_RANGE,FALSE),1),"-") -> - | E94: =IFERROR(VLOOKUP($B94,INPUT_RANGE,2,FALSE),"-") -> - | F94: =IFERROR(VLOOKUP($B94,INPUT_RANGE,3,FALSE),"-") -> - | G94: =IFERROR(VLOOKUP($B94,INPUT_RANGE,4,FALSE),"-") -> - | H94: =IFERROR(VLOOKUP($B94,INPUT_RANGE,7,FALSE),"-") -> - | I94: =IFERROR(VLOOKUP($B94,INPUT_RANGE,8,FALSE),"-") -> - | K94: =IFERROR(VLOOKUP($B94,INPUT_RANGE,5,FALSE)&", "&VLOOKUP($B94,INPUT_RANGE,6,FALSE),"-") -> - | L94: =IFERROR(VLOOKUP($B94,INPUT_RANGE,9,FALSE),"-") -> - | M94: =IFERROR(VLOOKUP($B94,INPUT_RANGE,11,FALSE),"-") -> - | N94: =IFERROR(VLOOKUP($B94,INPUT_RANGE,12,FALSE),"-") -> - | Q94: =IF(J94="","",INT(YEARFRAC($J94, TODAY()))) | R94: =IF(Q94="","","Age: " & Q94) | S94: =RIGHT(ROUND(VLOOKUP(B94,INPUT_RANGE,54,FALSE)/VLOOKUP(B94,INPUT_RANGE,52,FALSE),3),4) -> #N/A | T94: =VLOOKUP($B94,INPUT_RANGE,57,FALSE) -> #N/A | U94: ="D:\IMS Images\Headshots\"&IF('Team Info'!$B$21="BASEBALL","CBASE","SBALL")&"\"&'Team Info'!$B$11&"\"&D94&"_"&C94&".png" -> D:\IMS Images\Headshots\CBASE\GENERIC_BASEBALL\-_-.png | V94: ="D:\IMS Images\ActionShots\"&IF('Team Info'!$B$21="BASEBALL","CBASE","SBALL")&"\"&'Team Info'!$B$11&"\"&D94&"_"&C94&".png" -> D:\IMS Images\ActionShots\CBASE\GENERIC_BASEBALL\-_-.png | W94: =B94 & " " & X94 -> 91 - - | X94: =C94&" "&D94 -> - - | Y94: =UPPER(X94) -> - - | Z94: =LEFT(C94,1)&". "&D94 -> -. - | AA94: =UPPER(C94) -> - | AB94: =UPPER(D94) -> - | AC94: =IF($L94=4,"Senior",IF($L94=3,"Junior",IF($L94=2,"Sophomore",IF($L94=1,"Freshman","")))) | AD94: =IF($L94=4,"SR",IF($L94=3,"JR",IF($L94=2,"SO",IF($L94=1,"FR","")))) | AE94: =UPPER(AC94) | AF94: =$I94 & " lbs" -> - lbs | AG94: ="MAJOR: " & UPPER(M94) -> MAJOR: - | AH94: =B94 & " " & UPPER(X94) -> 91 - - | AI94: =IF(T94=0,"1st",$T94+1&IF(AND(MOD(ABS($T94+1),100)>10,MOD(ABS($T94+1),100)<14),"th",CHOOSE(MOD(ABS($T94+1),10)+1,"th","st","nd","rd","th","th","th","th","th","th"))) -> #N/A
A95: 92 | B95: 92 | C95: =IFERROR(INDEX(NAME_RANGE,MATCH(B95,NUM_RANGE,FALSE),2),"-") -> - | D95: =IFERROR(INDEX(NAME_RANGE,MATCH(B95,NUM_RANGE,FALSE),1),"-") -> - | E95: =IFERROR(VLOOKUP($B95,INPUT_RANGE,2,FALSE),"-") -> - | F95: =IFERROR(VLOOKUP($B95,INPUT_RANGE,3,FALSE),"-") -> - | G95: =IFERROR(VLOOKUP($B95,INPUT_RANGE,4,FALSE),"-") -> - | H95: =IFERROR(VLOOKUP($B95,INPUT_RANGE,7,FALSE),"-") -> - | I95: =IFERROR(VLOOKUP($B95,INPUT_RANGE,8,FALSE),"-") -> - | K95: =IFERROR(VLOOKUP($B95,INPUT_RANGE,5,FALSE)&", "&VLOOKUP($B95,INPUT_RANGE,6,FALSE),"-") -> - | L95: =IFERROR(VLOOKUP($B95,INPUT_RANGE,9,FALSE),"-") -> - | M95: =IFERROR(VLOOKUP($B95,INPUT_RANGE,11,FALSE),"-") -> - | N95: =IFERROR(VLOOKUP($B95,INPUT_RANGE,12,FALSE),"-") -> - | Q95: =IF(J95="","",INT(YEARFRAC($J95, TODAY()))) | R95: =IF(Q95="","","Age: " & Q95) | S95: =RIGHT(ROUND(VLOOKUP(B95,INPUT_RANGE,54,FALSE)/VLOOKUP(B95,INPUT_RANGE,52,FALSE),3),4) -> #N/A | T95: =VLOOKUP($B95,INPUT_RANGE,57,FALSE) -> #N/A | U95: ="D:\IMS Images\Headshots\"&IF('Team Info'!$B$21="BASEBALL","CBASE","SBALL")&"\"&'Team Info'!$B$11&"\"&D95&"_"&C95&".png" -> D:\IMS Images\Headshots\CBASE\GENERIC_BASEBALL\-_-.png | V95: ="D:\IMS Images\ActionShots\"&IF('Team Info'!$B$21="BASEBALL","CBASE","SBALL")&"\"&'Team Info'!$B$11&"\"&D95&"_"&C95&".png" -> D:\IMS Images\ActionShots\CBASE\GENERIC_BASEBALL\-_-.png | W95: =B95 & " " & X95 -> 92 - - | X95: =C95&" "&D95 -> - - | Y95: =UPPER(X95) -> - - | Z95: =LEFT(C95,1)&". "&D95 -> -. - | AA95: =UPPER(C95) -> - | AB95: =UPPER(D95) -> - | AC95: =IF($L95=4,"Senior",IF($L95=3,"Junior",IF($L95=2,"Sophomore",IF($L95=1,"Freshman","")))) | AD95: =IF($L95=4,"SR",IF($L95=3,"JR",IF($L95=2,"SO",IF($L95=1,"FR","")))) | AE95: =UPPER(AC95) | AF95: =$I95 & " lbs" -> - lbs | AG95: ="MAJOR: " & UPPER(M95) -> MAJOR: - | AH95: =B95 & " " & UPPER(X95) -> 92 - - | AI95: =IF(T95=0,"1st",$T95+1&IF(AND(MOD(ABS($T95+1),100)>10,MOD(ABS($T95+1),100)<14),"th",CHOOSE(MOD(ABS($T95+1),10)+1,"th","st","nd","rd","th","th","th","th","th","th"))) -> #N/A
A96: 93 | B96: 93 | C96: =IFERROR(INDEX(NAME_RANGE,MATCH(B96,NUM_RANGE,FALSE),2),"-") -> - | D96: =IFERROR(INDEX(NAME_RANGE,MATCH(B96,NUM_RANGE,FALSE),1),"-") -> - | E96: =IFERROR(VLOOKUP($B96,INPUT_RANGE,2,FALSE),"-") -> - | F96: =IFERROR(VLOOKUP($B96,INPUT_RANGE,3,FALSE),"-") -> - | G96: =IFERROR(VLOOKUP($B96,INPUT_RANGE,4,FALSE),"-") -> - | H96: =IFERROR(VLOOKUP($B96,INPUT_RANGE,7,FALSE),"-") -> - | I96: =IFERROR(VLOOKUP($B96,INPUT_RANGE,8,FALSE),"-") -> - | K96: =IFERROR(VLOOKUP($B96,INPUT_RANGE,5,FALSE)&", "&VLOOKUP($B96,INPUT_RANGE,6,FALSE),"-") -> - | L96: =IFERROR(VLOOKUP($B96,INPUT_RANGE,9,FALSE),"-") -> - | M96: =IFERROR(VLOOKUP($B96,INPUT_RANGE,11,FALSE),"-") -> - | N96: =IFERROR(VLOOKUP($B96,INPUT_RANGE,12,FALSE),"-") -> - | Q96: =IF(J96="","",INT(YEARFRAC($J96, TODAY()))) | R96: =IF(Q96="","","Age: " & Q96) | S96: =RIGHT(ROUND(VLOOKUP(B96,INPUT_RANGE,54,FALSE)/VLOOKUP(B96,INPUT_RANGE,52,FALSE),3),4) -> #N/A | T96: =VLOOKUP($B96,INPUT_RANGE,57,FALSE) -> #N/A | U96: ="D:\IMS Images\Headshots\"&IF('Team Info'!$B$21="BASEBALL","CBASE","SBALL")&"\"&'Team Info'!$B$11&"\"&D96&"_"&C96&".png" -> D:\IMS Images\Headshots\CBASE\GENERIC_BASEBALL\-_-.png | V96: ="D:\IMS Images\ActionShots\"&IF('Team Info'!$B$21="BASEBALL","CBASE","SBALL")&"\"&'Team Info'!$B$11&"\"&D96&"_"&C96&".png" -> D:\IMS Images\ActionShots\CBASE\GENERIC_BASEBALL\-_-.png | W96: =B96 & " " & X96 -> 93 - - | X96: =C96&" "&D96 -> - - | Y96: =UPPER(X96) -> - - | Z96: =LEFT(C96,1)&". "&D96 -> -. - | AA96: =UPPER(C96) -> - | AB96: =UPPER(D96) -> - | AC96: =IF($L96=4,"Senior",IF($L96=3,"Junior",IF($L96=2,"Sophomore",IF($L96=1,"Freshman","")))) | AD96: =IF($L96=4,"SR",IF($L96=3,"JR",IF($L96=2,"SO",IF($L96=1,"FR","")))) | AE96: =UPPER(AC96) | AF96: =$I96 & " lbs" -> - lbs | AG96: ="MAJOR: " & UPPER(M96) -> MAJOR: - | AH96: =B96 & " " & UPPER(X96) -> 93 - - | AI96: =IF(T96=0,"1st",$T96+1&IF(AND(MOD(ABS($T96+1),100)>10,MOD(ABS($T96+1),100)<14),"th",CHOOSE(MOD(ABS($T96+1),10)+1,"th","st","nd","rd","th","th","th","th","th","th"))) -> #N/A
