Workbook
Name ACTIONSHOT: Roster!$P$2:$P$150
Name AGE: Roster!$L$2:$L$152
Name BIO_FACT: Roster!$J$2:$J$152
Name CAREER_STAT_NO: 'Player Stats'!$R$8:$R$156
Name CAREER_STAT1: 'Player Stats'!$S$8:$S$156
Name CAREER_STAT1_HILITE: 'Player Stats'!$T$8:$T$156
Name CAREER_STAT2: 'Player Stats'!$U$8:$U$156
Name CAREER_STAT2_HILITE: 'Player Stats'!$V$8:$V$156
Name CAREER_STAT3: 'Player Stats'!$W$8:$W$156
Name CAREER_STAT3_HILITE: 'Player Stats'!$X$8:$X$156
Name CAREER_STAT4: 'Player Stats'!$Y$8:$Y$156
Name CAREER_STAT4_HILITE: 'Player Stats'!$Z$8:$Z$156
Name CAREER_STAT5: 'Player Stats'!$AA$8:$AA$156
Name CAREER_STAT5_HILITE: 'Player Stats'!ABN$8:$AB$156
Name CAREER_STAT6: 'Player Stats'!$AC$8:$AC$156
Name CAREER_STAT6_HILITE: 'Player Stats'!$AD$8:$AD$156
Name CARRER_STAT_DROP: 'Player Stats'!$AE$8:$AES$156
Name COACH_DEF_FIRST: 'Team Personnel'!$B$23:$B$33
Name COACH_DEF_LAST: 'Team Personnel'!$C$23:$C$33
Name COACH_DEF_TEXT: 'Team Personnel'!$D$23:$D$33
Name COACH_HEAD_DROP: 'Team Personnel'!$E$1:$E$11
Name COACH_HEAD_FIRST: 'Team Personnel'!$B$1:$B$11
Name COACH_HEAD_LAST: 'Team Personnel'!$C$1:$C$11
Name COACH_HEAD_TEXT: 'Team Personnel'!$D$1:$D$11
Name COACH_OFF_FIRST: 'Team Personnel'!$B$12:$B$22
Name COACH_OFF_LAST: 'Team Personnel'!$C$12:$C$22
Name COACH_OFF_TEXT: 'Team Personnel'!$D$12:$D$22
Name COACH_RESUME_DROP: 'Team Personnel'!$I$16:$I$17
Name COACH_RESUME_LINE1: 'Team Personnel'!$I$7:$I$8
Name COACH_RESUME_LINE2: 'Team Personnel'!$I$10:$I$11
Name COACH_RESUME_LINE3: 'Team Personnel'!$I$13:$I$14
Name COACH_RESUME_SUBTITLE: 'Team Personnel'!$I$4:$I$5
Name COACH_RESUME_TITLE: 'Team Personnel'!$I$1:$I$2
Name CONFERENCE_LOGOS: LOGOS!$C$1:$C$50
Name DRAFT_INFO: Roster!#REF!
Name HEADSHOT: Roster!$O$2:$O$152
Name HEIGHT: Roster!$F$2:$F$152
Name HOMETOWN: Roster!$H$2:$H$152
Name JERSEY: Roster!$B$2:$B$152
Name NAME_FINIT: Roster!$R$2:$R$152
Name NAME_FINIT_CAPS: Roster!$S$2:$S$150
Name NAME_FIRST: Roster!$C$2:$C$152
Name NAME_FIRST_CAPS: Roster!$V$2:$V$150
Name NAME_FULL: Roster!$Q$2:$Q$152
Name NAME_FULL_CAPS: Roster!$U$2:$U$150
Name NAME_LAST: Roster!$D$2:$D$152
Name NAME_LAST_CAPS: Roster!$W$2:$W$150
Name NAME_NUM: Roster!$Z$2:$Z$150
Name NAME_NUM_CAPS: Roster!$Y$2:$Y$150
Name NETWORK_LOGOS: LOGOS!$E$1:$E$499
Name POS: Roster!$E$2:$E$152
Name POS_FULL: Roster!$M$2:$M$152
Name PROMO_TOWER: Schedule!$A$12:$C$21
Name ROSTER: Roster!$A$2:$Z$160
Name SCHED_AT_VS: Schedule!$B$2:$B$15
Name SCHED_DATE: Schedule!$D$2:$D$15
Name SCHED_NETWORK: Schedule!$K$1:$K$15
Name SCHED_OPPONENT: Schedule!$C$2:$C$15
Name SCHED_TIME: Schedule!$E$2:$E$15
Name SEASON_SEL: 'Team Info'!$E$5:$E$7

Sheet Team Info
A1: ESPN Team Sheet - v2025.1.0 | B1: Updated 7/29/25 | C1: TEAM INFO | E1: TODAY_TONIGHT_SEL
A2: TEAM INFO | B2: Home | C2: TEAM_RANK | E2: =$B$12 -> Today
A3: Team Rank | B3: 25 | C3: =$B$3 -> 25 | E3: =UPPER($B$12) -> TODAY
A4: Team City / College | B4: VANDERBILT
A5: Team Nickname | B5: COMMODORES | C5: TEAM_CITY_COLLEGE | E5: SEASON_SEL
A6: Team Tricode | B6: VAN | C6: =$B$4 -> VANDERBILT | E6: =$B$13 -> Last Season
A7: Team Dashboard Name | B7: VANDERBILT | E7: =UPPER($B$13) -> LAST SEASON
A8: Logo / Swatch Name | B8: VANDERBILT | C8: TEAM_NICKNAME | H8: TODAY/SEASON SEL
A9: Record | B9: 5-2 | C9: =$B$5 -> COMMODORES | E9: TODAY_TONIGHT_SEL_COLON | H9: Season
E10: =$E$2&":" -> Today: | H10: Last Season
A11: TODAY / SEASON SELECTION | C11: TEAM_TRICODE | E11: =UPPER($E$2&":") -> TODAY:
A12: Today / Tonight Selection | B12: Today | C12: =$B$6 -> VAN | H12: Today
A13: Season / Last Season | B13: Last Season | E13: SEASON_SEL_COLON | H13: Tonight
C14: TEAM_FULL_NAME | E14: =$E$6&":" -> Last Season:
C15: =B4&" "&B5 -> VANDERBILT COMMODORES | E15: =UPPER($E$6&":") -> LAST SEASON:
C17: TEAM_DASH_NAME
C18: =$B$7 -> VANDERBILT | E18: AWAY/HOME SEL
E19: Away
C20: TEAM_RANK_NAME | E20: Home
C21: =C3&" "&C6 -> 25 VANDERBILT
C23: TEAM_RANK_NAME_NICKNAME
C24: =C3&" "&C6&" "&C9 -> 25 VANDERBILT COMMODORES
C26: TEAM_RANK_NAME_RECORD
C27: =C3&" "&C6&" "&C43 -> 25 VANDERBILT
C29: TEAM_LOGOTEXT
C30: =$B$8 -> VANDERBILT
C32: TEAM_RECORD_OVERALL
C33: =$B$9 -> 5-2

Sheet Team Personnel
A1: SAVE | B1: FIRST NAME | C1: LAST NAME | D1: COACH FACT (ALL CAPS FOR CFB // Upper-Lower for SEC) | E1: DROPLINE (ALL CAPS FOR CFB // Upper-Lower for SEC) | I1: COACH_RESUME_TITLE
A2: =IF('Team Info'!$B$2 = "Away",170,270) -> 270 | B2: HEAD | C2: COACH | D2: COACH FACT | E2: STICKER ONLY - NO DROPLINE | I2: =B36 -> 0
A3: =A2+1 -> 271 | B3: =B2 -> HEAD | C3: =C2 -> COACH | D3: COACH FACT | E3: COACH DROPLINE
A4: =A3+1 -> 272 | B4: =B3 -> HEAD | C4: =C3 -> COACH | D4: COACH FACT | E4: COACH DROPLINE | I4: COACH_RESUME_SUBTITLE
A5: =A4+1 -> 273 | B5: =B4 -> HEAD | C5: =C4 -> COACH | D5: COACH FACT | E5: COACH DROPLINE | I5: =B37 -> 0
A6: =A5+1 -> 274 | B6: =B5 -> HEAD | C6: =C5 -> COACH | D6: COACH FACT | E6: COACH DROPLINE
A7: =A6+1 -> 275 | B7: =B6 -> HEAD | C7: =C6 -> COACH | D7: COACH FACT | E7: COACH DROPLINE | I7: COACH_RESUME_LINE1
A8: =A7+1 -> 276 | B8: =B7 -> HEAD | C8: =C7 -> COACH | D8: COACH FACT | E8: COACH DROPLINE | I8: =B38 -> 0
A9: =A8+1 -> 277 | B9: =B8 -> HEAD | C9: =C8 -> COACH | D9: COACH FACT | E9: COACH DROPLINE
A10: =A9+1 -> 278 | B10: =B9 -> HEAD | C10: =C9 -> COACH | D10: COACH FACT | E10: COACH DROPLINE | I10: COACH_RESUME_LINE2
A11: =A10+1 -> 279 | B11: =B10 -> HEAD | C11: =C10 -> COACH | D11: COACH FACT | E11: COACH DROPLINE | I11: =B39 -> 0
A12: SAVE | B12: FIRST NAME | C12: LAST NAME | D12: COACH FACT | E12: STICKER ONLY
A13: =IF('Team Info'!$B$2 = "Away",180,280) -> 280 | B13: OFFENSIVE | C13: COACH | D13: COACH POSITION | I13: COACH_RESUME_LINE3
A14: =A13+1 -> 281 | B14: OFFENSIVE | C14: COACH | D14: COACH POSITION | I14: =B40 -> 0
A15: =A13+2 -> 282 | B15: OFFENSIVE | C15: COACH | D15: COACH POSITION
A16: =A13+3 -> 283 | B16: OFFENSIVE | C16: COACH | D16: COACH POSITION | I16: COACH_RESUME_DROP
A17: =A13+4 -> 284 | B17: OFFENSIVE | C17: COACH | D17: COACH POSITION | I17: =B41 -> 0
A18: =A13+5 -> 285 | B18: OFFENSIVE | C18: COACH | D18: COACH POSITION
A19: =A13+6 -> 286 | B19: OFFENSIVE | C19: COACH | D19: COACH POSITION
A20: =A13+7 -> 287 | B20: OFFENSIVE | C20: COACH | D20: COACH POSITION
A21: =A13+8 -> 288 | B21: OFFENSIVE | C21: COACH | D21: COACH POSITION
A22: =A13+9 -> 289 | B22: OFFENSIVE | C22: COACH | D22: COACH POSITION
A23: SAVE | B23: FIRST NAME | C23: LAST NAME | D23: COACH FACT | E23: STICKER ONLY
A24: =IF('Team Info'!$B$2 = "Away",190,290) -> 290 | B24: DEFENSIVE | C24: COACH | D24: COACH POSITION
A25: =A24+1 -> 291 | B25: DEFENSIVE | C25: COACH | D25: COACH POSITION
A26: =A24+2 -> 292 | B26: DEFENSIVE | C26: COACH | D26: COACH POSITION
A27: =A24+3 -> 293 | B27: DEFENSIVE | C27: COACH | D27: COACH POSITION
A28: =A24+4 -> 294 | B28: DEFENSIVE | C28: COACH | D28: COACH POSITION
A29: =A24+5 -> 295 | B29: DEFENSIVE | C29: COACH | D29: COACH POSITION
A30: =A24+6 -> 296 | B30: DEFENSIVE | C30: COACH | D30: COACH POSITION
A31: =A24+7 -> 297 | B31: DEFENSIVE | C31: COACH | D31: COACH POSITION
A32: =A24+8 -> 298 | B32: DEFENSIVE | C32: COACH | D32: COACH POSITION
A33: =A24+9 -> 299 | B33: DEFENSIVE | C33: COACH | D33: COACH POSITION
A34: AWAY TEAM - SAVE TO 170s, 180s, 190s | D34: HOME TEAM - SAVE TO 270s, 280s, 290s

Sheet Roster
A1: Column A must stay in sequential order from 1-99 for XPN games, jersey #0 must be reassigned to another call-up number in column B; Inactive players are assigned -1 in column A
A2: JERSEY | B2: DISPLAY | C2: FIRST NAME | D2: LAST NAME | E2: POS | F2: HEIGHT | G2: WEIGHT | H2: HOMETOWN | I2: YEAR | J2: Bio Fact (ALL CAPS FOR CFB // Upper-Lower for SEC) | M2: Position | N2: Year | O2: Headshot | P2: Actionshot | Q2: Full Name | R2: Initial Name | S2: Initial Name CAPS | T2: Year | U2: Full Name CAPS | V2: First Name CAPS | W2: Last Name CAPS | X2: Year CAPS | Y2: Num Name CAPS | Z2: Num Name | AB2: Positions | AC2: Upper-Lower | AD2: CAPS
A3: 1 | B3: 1 | C3: First Name | D3: Last Name | E3: WR | F3: 6'1" | G3: 188 | H3: Atlanta, GA | I3: 4 | M3: =VLOOKUP(E3,$AB$3:$AD$36,3,0) -> WIDE RECEIVER | N3: =IF($I3=4,"Senior",IF($I3=3,"Junior",IF($I3=2,"Sophomore",IF($I3=1,"Freshman","")))) -> Senior | O3: ="D:\IMS Images\Headshots\CFB\"&'Team Info'!$B$8&"\"&D3&"_"&C3&".png" -> D:\IMS Images\Headshots\CFB\VANDERBILT\Last Name_First Name.png | P3: ="D:\IMS Images\Actionshots\CFB\"&'Team Info'!$B$8&"\"&D3&"_"&C3&".png" -> D:\IMS Images\Actionshots\CFB\VANDERBILT\Last Name_First Name.png | Q3: =C3&" "&D3 -> First Name Last Name | R3: =LEFT(C3,1)&". "&D3 -> F. Last Name | S3: =UPPER(R3) -> F. LAST NAME | T3: =IF($I3=4,"SR",IF($I3=3,"JR",IF($I3=2,"SO",IF($I3=1,"FR","")))) -> SR | U3: =UPPER(Q3) -> FIRST NAME LAST NAME | V3: =UPPER(C3) -> FIRST NAME | W3: =UPPER(D3) -> LAST NAME | X3: =UPPER(N3) -> SENIOR | Y3: =B3 &" " & U3 -> 1 FIRST NAME LAST NAME | Z3: =B3 &" " & Q3 -> 1 First Name Last Name | AB3: QB | AC3: Quarterback | AD3: =UPPER(AC3) -> QUARTERBACK
A4: 2 | B4: 2 | M4: =VLOOKUP(E4,$AB$3:$AD$36,3,0) -> #N/A | N4: =IF($I4=4,"Senior",IF($I4=3,"Junior",IF($I4=2,"Sophomore",IF($I4=1,"Freshman","")))) | O4: ="D:\IMS Images\Headshots\CFB\"&'Team Info'!$B$8&"\"&D4&"_"&C4&".png" -> D:\IMS Images\Headshots\CFB\VANDERBILT\_.png | P4: ="D:\IMS Images\Actionshots\CFB\"&'Team Info'!$B$8&"\"&D4&"_"&C4&".png" -> D:\IMS Images\Actionshots\CFB\VANDERBILT\_.png | Q4: =C4&" "&D4 | R4: =LEFT(C4,1)&". "&D4 -> . | S4: =UPPER(R4) -> . | T4: =IF($I4=4,"SR",IF($I4=3,"JR",IF($I4=2,"SO",IF($I4=1,"FR","")))) | U4: =UPPER(Q4) | V4: =UPPER(C4) | W4: =UPPER(D4) | X4: =UPPER(N4) | Y4: =B4 &" " & U4 -> 2 | Z4: =B4 &" " & Q4 -> 2 | AB4: WR | AC4: Wide Receiver | AD4: =UPPER(AC4) -> WIDE RECEIVER
A5: 3 | B5: 3 | M5: =VLOOKUP(E5,$AB$3:$AD$36,3,0) -> #N/A | N5: =IF($I5=4,"Senior",IF($I5=3,"Junior",IF($I5=2,"Sophomore",IF($I5=1,"Freshman","")))) | O5: ="D:\IMS Images\Headshots\CFB\"&'Team Info'!$B$8&"\"&D5&"_"&C5&".png" -> D:\IMS Images\Headshots\CFB\VANDERBILT\_.png | P5: ="D:\IMS Images\Actionshots\CFB\"&'Team Info'!$B$8&"\"&D5&"_"&C5&".png" -> D:\IMS Images\Actionshots\CFB\VANDERBILT\_.png | Q5: =C5&" "&D5 | R5: =LEFT(C5,1)&". "&D5 -> . | S5: =UPPER(R5) -> . | T5: =IF($I5=4,"SR",IF($I5=3,"JR",IF($I5=2,"SO",IF($I5=1,"FR","")))) | U5: =UPPER(Q5) | V5: =UPPER(C5) | W5: =UPPER(D5) | X5: =UPPER(N5) | Y5: =B5 &" " & U5 -> 3 | Z5: =B5 &" " & Q5 -> 3 | AB5: TE | AC5: Tight End | AD5: =UPPER(AC5) -> TIGHT END
A6: 4 | B6: 4 | M6: =VLOOKUP(E6,$AB$3:$AD$36,3,0) -> #N/A | N6: =IF($I6=4,"Senior",IF($I6=3,"Junior",IF($I6=2,"Sophomore",IF($I6=1,"Freshman","")))) | O6: ="D:\IMS Images\Headshots\CFB\"&'Team Info'!$B$8&"\"&D6&"_"&C6&".png" -> D:\IMS Images\Headshots\CFB\VANDERBILT\_.png | P6: ="D:\IMS Images\Actionshots\CFB\"&'Team Info'!$B$8&"\"&D6&"_"&C6&".png" -> D:\IMS Images\Actionshots\CFB\VANDERBILT\_.png | Q6: =C6&" "&D6 | R6: =LEFT(C6,1)&". "&D6 -> . | S6: =UPPER(R6) -> . | T6: =IF($I6=4,"SR",IF($I6=3,"JR",IF($I6=2,"SO",IF($I6=1,"FR","")))) | U6: =UPPER(Q6) | V6: =UPPER(C6) | W6: =UPPER(D6) | X6: =UPPER(N6) | Y6: =B6 &" " & U6 -> 4 | Z6: =B6 &" " & Q6 -> 4 | AB6: RB | AC6: Running Back | AD6: =UPPER(AC6) -> RUNNING BACK
A7: 5 | B7: 5 | M7: =VLOOKUP(E7,$AB$3:$AD$36,3,0) -> #N/A | N7: =IF($I7=4,"Senior",IF($I7=3,"Junior",IF($I7=2,"Sophomore",IF($I7=1,"Freshman","")))) | O7: ="D:\IMS Images\Headshots\CFB\"&'Team Info'!$B$8&"\"&D7&"_"&C7&".png" -> D:\IMS Images\Headshots\CFB\VANDERBILT\_.png | P7: ="D:\IMS Images\Actionshots\CFB\"&'Team Info'!$B$8&"\"&D7&"_"&C7&".png" -> D:\IMS Images\Actionshots\CFB\VANDERBILT\_.png | Q7: =C7&" "&D7 | R7: =LEFT(C7,1)&". "&D7 -> . | S7: =UPPER(R7) -> . | T7: =IF($I7=4,"SR",IF($I7=3,"JR",IF($I7=2,"SO",IF($I7=1,"FR","")))) | U7: =UPPER(Q7) | V7: =UPPER(C7) | W7: =UPPER(D7) | X7: =UPPER(N7) | Y7: =B7 &" " & U7 -> 5 | Z7: =B7 &" " & Q7 -> 5 | AB7: FB | AC7: Fullback | AD7: =UPPER(AC7) -> FULLBACK
A8: 6 | B8: 6 | M8: =VLOOKUP(E8,$AB$3:$AD$36,3,0) -> #N/A | N8: =IF($I8=4,"Senior",IF($I8=3,"Junior",IF($I8=2,"Sophomore",IF($I8=1,"Freshman","")))) | O8: ="D:\IMS Images\Headshots\CFB\"&'Team Info'!$B$8&"\"&D8&"_"&C8&".png" -> D:\IMS Images\Headshots\CFB\VANDERBILT\_.png | P8: ="D:\IMS Images\Actionshots\CFB\"&'Team Info'!$B$8&"\"&D8&"_"&C8&".png" -> D:\IMS Images\Actionshots\CFB\VANDERBILT\_.png | Q8: =C8&" "&D8 | R8: =LEFT(C8,1)&". "&D8 -> . | S8: =UPPER(R8) -> . | T8: =IF($I8=4,"SR",IF($I8=3,"JR",IF($I8=2,"SO",IF($I8=1,"FR","")))) | U8: =UPPER(Q8) | V8: =UPPER(C8) | W8: =UPPER(D8) | X8: =UPPER(N8) | Y8: =B8 &" " & U8 -> 6 | Z8: =B8 &" " & Q8 -> 6 | AB8: HB | AC8: Halfback | AD8: =UPPER(AC8) -> HALFBACK
A9: 7 | B9: 7 | M9: =VLOOKUP(E9,$AB$3:$AD$36,3,0) -> #N/A | N9: =IF($I9=4,"Senior",IF($I9=3,"Junior",IF($I9=2,"Sophomore",IF($I9=1,"Freshman","")))) | O9: ="D:\IMS Images\Headshots\CFB\"&'Team Info'!$B$8&"\"&D9&"_"&C9&".png" -> D:\IMS Images\Headshots\CFB\VANDERBILT\_.png | P9: ="D:\IMS Images\Actionshots\CFB\"&'Team Info'!$B$8&"\"&D9&"_"&C9&".png" -> D:\IMS Images\Actionshots\CFB\VANDERBILT\_.png | Q9: =C9&" "&D9 | R9: =LEFT(C9,1)&". "&D9 -> . | S9: =UPPER(R9) -> . | T9: =IF($I9=4,"SR",IF($I9=3,"JR",IF($I9=2,"SO",IF($I9=1,"FR","")))) | U9: =UPPER(Q9) | V9: =UPPER(C9) | W9: =UPPER(D9) | X9: =UPPER(N9) | Y9: =B9 &" " & U9 -> 7 | Z9: =B9 &" " & Q9 -> 7 | AB9: OL | AC9: Offensive Line | AD9: =UPPER(AC9) -> OFFENSIVE LINE
A10: 8 | B10: 8 | M10: =VLOOKUP(E10,$AB$3:$AD$36,3,0) -> #N/A | N10: =IF($I10=4,"Senior",IF($I10=3,"Junior",IF($I10=2,"Sophomore",IF($I10=1,"Freshman","")))) | O10: ="D:\IMS Images\Headshots\CFB\"&'Team Info'!$B$8&"\"&D10&"_"&C10&".png" -> D:\IMS Images\Headshots\CFB\VANDERBILT\_.png | P10: ="D:\IMS Images\Actionshots\CFB\"&'Team Info'!$B$8&"\"&D10&"_"&C10&".png" -> D:\IMS Images\Actionshots\CFB\VANDERBILT\_.png | Q10: =C10&" "&D10 | R10: =LEFT(C10,1)&". "&D10 -> . | S10: =UPPER(R10) -> . | T10: =IF($I10=4,"SR",IF($I10=3,"JR",IF($I10=2,"SO",IF($I10=1,"FR","")))) | U10: =UPPER(Q10) | V10: =UPPER(C10) | W10: =UPPER(D10) | X10: =UPPER(N10) | Y10: =B10 &" " & U10 -> 8 | Z10: =B10 &" " & Q10 -> 8 | AB10: C | AC10: Center | AD10: =UPPER(AC10) -> CENTER
A11: 9 | B11: 9 | M11: =VLOOKUP(E11,$AB$3:$AD$36,3,0) -> #N/A | N11: =IF($I11=4,"Senior",IF($I11=3,"Junior",IF($I11=2,"Sophomore",IF($I11=1,"Freshman","")))) | O11: ="D:\IMS Images\Headshots\CFB\"&'Team Info'!$B$8&"\"&D11&"_"&C11&".png" -> D:\IMS Images\Headshots\CFB\VANDERBILT\_.png | P11: ="D:\IMS Images\Actionshots\CFB\"&'Team Info'!$B$8&"\"&D11&"_"&C11&".png" -> D:\IMS Images\Actionshots\CFB\VANDERBILT\_.png | Q11: =C11&" "&D11 | R11: =LEFT(C11,1)&". "&D11 -> . | S11: =UPPER(R11) -> . | T11: =IF($I11=4,"SR",IF($I11=3,"JR",IF($I11=2,"SO",IF($I11=1,"FR","")))) | U11: =UPPER(Q11) | V11: =UPPER(C11) | W11: =UPPER(D11) | X11: =UPPER(N11) | Y11: =B11 &" " & U11 -> 9 | Z11: =B11 &" " & Q11 -> 9 | AB11: OG | AC11: Offensive Guard | AD11: =UPPER(AC11) -> OFFENSIVE GUARD
A12: 10 | B12: 10 | M12: =VLOOKUP(E12,$AB$3:$AD$36,3,0) -> #N/A | N12: =IF($I12=4,"Senior",IF($I12=3,"Junior",IF($I12=2,"Sophomore",IF($I12=1,"Freshman","")))) | O12: ="D:\IMS Images\Headshots\CFB\"&'Team Info'!$B$8&"\"&D12&"_"&C12&".png" -> D:\IMS Images\Headshots\CFB\VANDERBILT\_.png | P12: ="D:\IMS Images\Actionshots\CFB\"&'Team Info'!$B$8&"\"&D12&"_"&C12&".png" -> D:\IMS Images\Actionshots\CFB\VANDERBILT\_.png | Q12: =C12&" "&D12 | R12: =LEFT(C12,1)&". "&D12 -> . | S12: =UPPER(R12) -> . | T12: =IF($I12=4,"SR",IF($I12=3,"JR",IF($I12=2,"SO",IF($I12=1,"FR","")))) | U12: =UPPER(Q12) | V12: =UPPER(C12) | W12: =UPPER(D12) | X12: =UPPER(N12) | Y12: =B12 &" " & U12 -> 10 | Z12: =B12 &" " & Q12 -> 10 | AB12: OT | AC12: Offensive Tackle | AD12: =UPPER(AC12) -> OFFENSIVE TACKLE
A13: 11 | B13: 11 | M13: =VLOOKUP(E13,$AB$3:$AD$36,3,0) -> #N/A | N13: =IF($I13=4,"Senior",IF($I13=3,"Junior",IF($I13=2,"Sophomore",IF($I13=1,"Freshman","")))) | O13: ="D:\IMS Images\Headshots\CFB\"&'Team Info'!$B$8&"\"&D13&"_"&C13&".png" -> D:\IMS Images\Headshots\CFB\VANDERBILT\_.png | P13: ="D:\IMS Images\Actionshots\CFB\"&'Team Info'!$B$8&"\"&D13&"_"&C13&".png" -> D:\IMS Images\Actionshots\CFB\VANDERBILT\_.png | Q13: =C13&" "&D13 | R13: =LEFT(C13,1)&". "&D13 -> . | S13: =UPPER(R13) -> . | T13: =IF($I13=4,"SR",IF($I13=3,"JR",IF($I13=2,"SO",IF($I13=1,"FR","")))) | U13: =UPPER(Q13) | V13: =UPPER(C13) | W13: =UPPER(D13) | X13: =UPPER(N13) | Y13: =B13 &" " & U13 -> 11 | Z13: =B13 &" " & Q13 -> 11 | AB13: LG | AC13: Left Guard | AD13: =UPPER(AC13) -> LEFT GUARD
A14: 12 | B14: 12 | M14: =VLOOKUP(E14,$AB$3:$AD$36,3,0) -> #N/A | N14: =IF($I14=4,"Senior",IF($I14=3,"Junior",IF($I14=2,"Sophomore",IF($I14=1,"Freshman","")))) | O14: ="D:\IMS Images\Headshots\CFB\"&'Team Info'!$B$8&"\"&D14&"_"&C14&".png" -> D:\IMS Images\Headshots\CFB\VANDERBILT\_.png | P14: ="D:\IMS Images\Actionshots\CFB\"&'Team Info'!$B$8&"\"&D14&"_"&C14&".png" -> D:\IMS Images\Actionshots\CFB\VANDERBILT\_.png | Q14: =C14&" "&D14 | R14: =LEFT(C14,1)&". "&D14 -> . | S14: =UPPER(R14) -> . | T14: =IF($I14=4,"SR",IF($I14=3,"JR",IF($I14=2,"SO",IF($I14=1,"FR","")))) | U14: =UPPER(Q14) | V14: =UPPER(C14) | W14: =UPPER(D14) | X14: =UPPER(N14) | Y14: =B14 &" " & U14 -> 12 | Z14: =B14 &" " & Q14 -> 12 | AB14: LT | AC14: Left Tackle | AD14: =UPPER(AC14) -> LEFT TACKLE
A15: 13 | B15: 13 | M15: =VLOOKUP(E15,$AB$3:$AD$36,3,0) -> #N/A | N15: =IF($I15=4,"Senior",IF($I15=3,"Junior",IF($I15=2,"Sophomore",IF($I15=1,"Freshman","")))) | O15: ="D:\IMS Images\Headshots\CFB\"&'Team Info'!$B$8&"\"&D15&"_"&C15&".png" -> D:\IMS Images\Headshots\CFB\VANDERBILT\_.png | P15: ="D:\IMS Images\Actionshots\CFB\"&'Team Info'!$B$8&"\"&D15&"_"&C15&".png" -> D:\IMS Images\Actionshots\CFB\VANDERBILT\_.png | Q15: =C15&" "&D15 | R15: =LEFT(C15,1)&". "&D15 -> . | S15: =UPPER(R15) -> . | T15: =IF($I15=4,"SR",IF($I15=3,"JR",IF($I15=2,"SO",IF($I15=1,"FR","")))) | U15: =UPPER(Q15) | V15: =UPPER(C15) | W15: =UPPER(D15) | X15: =UPPER(N15) | Y15: =B15 &" " & U15 -> 13 | Z15: =B15 &" " & Q15 -> 13 | AB15: RG | AC15: Right Guard | AD15: =UPPER(AC15) -> RIGHT GUARD
... A35: 33 | B35: 33 | M35: =VLOOKUP(E35,$AB$3:$AD$36,3,0) -> #N/A | N35: =IF($I35=4,"Senior",IF($I35=3,"Junior",IF($I35=2,"Sophomore",IF($I35=1,"Freshman","")))) | O35: ="D:\IMS Images\Headshots\CFB\"&'Team Info'!$B$8&"\"&D35&"_"&C35&".png" -> D:\IMS Images\Headshots\CFB\VANDERBILT\_.png | P35: ="D:\IMS Images\Actionshots\CFB\"&'Team Info'!$B$8&"\"&D35&"_"&C35&".png" -> D:\IMS Images\Actionshots\CFB\VANDERBILT\_.png | Q35: =C35&" "&D35 | R35: =LEFT(C35,1)&". "&D35 -> . | S35: =UPPER(R35) -> . | T35: =IF($I35=4,"SR",IF($I35=3,"JR",IF($I35=2,"SO",IF($I35=1,"FR","")))) | U35: =UPPER(Q35) | V35: =UPPER(C35) | W35: =UPPER(D35) | X35: =UPPER(N35) | Y35: =B35 &" " & U35 -> 33 | Z35: =B35 &" " & Q35 -> 33 | AB35: LB | AC35: Linebacker | AD35: =UPPER(AC35) -> LINEBACKER
A36: 34 | B36: 34 | M36: =VLOOKUP(E36,$AB$3:$AD$36,3,0) -> #N/A | N36: =IF($I36=4,"Senior",IF($I36=3,"Junior",IF($I36=2,"Sophomore",IF($I36=1,"Freshman","")))) | O36: ="D:\IMS Images\Headshots\CFB\"&'Team Info'!$B$8&"\"&D36&"_"&C36&".png" -> D:\IMS Images\Headshots\CFB\VANDERBILT\_.png | P36: ="D:\IMS Images\Actionshots\CFB\"&'Team Info'!$B$8&"\"&D36&"_"&C36&".png" -> D:\IMS Images\Actionshots\CFB\VANDERBILT\_.png | Q36: =C36&" "&D36 | R36: =LEFT(C36,1)&". "&D36 -> . | S36: =UPPER(R36) -> . | T36: =IF($I36=4,"SR",IF($I36=3,"JR",IF($I36=2,"SO",IF($I36=1,"FR","")))) | U36: =UPPER(Q36) | V36: =UPPER(C36) | W36: =UPPER(D36) | X36: =UPPER(N36) | Y36: =B36 &" " & U36 -> 34 | Z36: =B36 &" " & Q36 -> 34
A37: 35 | B37: 35 | M37: =VLOOKUP(E37,$AB$3:$AD$36,3,0) -> #N/A | N37: =IF($I37=4,"Senior",IF($I37=3,"Junior",IF($I37=2,"Sophomore",IF($I37=1,"Freshman","")))) | O37: ="D:\IMS Images\Headshots\CFB\"&'Team Info'!$B$8&"\"&D37&"_"&C37&".png" -> D:\IMS Images\Headshots\CFB\VANDERBILT\_.png | P37: ="D:\IMS Images\Actionshots\CFB\"&'Team Info'!$B$8&"\"&D37&"_"&C37&".png" -> D:\IMS Images\Actionshots\CFB\VANDERBILT\_.png | Q37: =C37&" "&D37 | R37: =LEFT(C37,1)&". "&D37 -> . | S37: =UPPER(R37) -> . | T37: =IF($I37=4,"SR",IF($I37=3,"JR",IF($I37=2,"SO",IF($I37=1,"FR","")))) | U37: =UPPER(Q37) | V37: =UPPER(C37) | W37: =UPPER(D37) | X37: =UPPER(N37) | Y37: =B37 &" " & U37 -> 35 | Z37: =B37 &" " & Q37 -> 35
A38: 36 | B38: 36 | M38: =VLOOKUP(E38,$AB$3:$AD$36,3,0) -> #N/A | N38: =IF($I38=4,"Senior",IF($I38=3,"Junior",IF($I38=2,"Sophomore",IF($I38=1,"Freshman","")))) | O38: ="D:\IMS Images\Headshots\CFB\"&'Team Info'!$B$8&"\"&D38&"_"&C38&".png" -> D:\IMS Images\Headshots\CFB\VANDERBILT\_.png | P38: ="D:\IMS Images\Actionshots\CFB\"&'Team Info'!$B$8&"\"&D38&"_"&C38&".png" -> D:\IMS Images\Actionshots\CFB\VANDERBILT\_.png | Q38: =C38&" "&D38 | R38: =LEFT(C38,1)&". "&D38 -> . | S38: =UPPER(R38) -> . | T38: =IF($I38=4,"SR",IF($I38=3,"JR",IF($I38=2,"SO",IF($I38=1,"FR","")))) | U38: =UPPER(Q38) | V38: =UPPER(C38) | W38: =UPPER(D38) | X38: =UPPER(N38) | Y38: =B38 &" " & U38 -> 36 | Z38: =B38 &" " & Q38 -> 36
A39: 37 | B39: 37 | M39: =VLOOKUP(E39,$AB$3:$AD$36,3,0) -> #N/A | N39: =IF($I39=4,"Senior",IF($I39=3,"Junior",IF($I39=2,"Sophomore",IF($I39=1,"Freshman","")))) | O39: ="D:\IMS Images\Headshots\CFB\"&'Team Info'!$B$8&"\"&D39&"_"&C39&".png" -> D:\IMS Images\Headshots\CFB\VANDERBILT\_.png | P39: ="D:\IMS Images\Actionshots\CFB\"&'Team Info'!$B$8&"\"&D39&"_"&C39&".png" -> D:\IMS Images\Actionshots\CFB\VANDERBILT\_.png | Q39: =C39&" "&D39 | R39: =LEFT(C39,1)&". "&D39 -> . | S39: =UPPER(R39) -> . | T39: =IF($I39=4,"SR",IF($I39=3,"JR",IF($I39=2,"SO",IF($I39=1,"FR","")))) | U39: =UPPER(Q39) | V39: =UPPER(C39) | W39: =UPPER(D39) | X39: =UPPER(N39) | Y39: =B39 &" " & U39 -> 37 | Z39: =B39 &" " & Q39 -> 37
A40: 38 | B40: 38 | M40: =VLOOKUP(E40,$AB$3:$AD$36,3,0) -> #N/A | N40: =IF($I40=4,"Senior",IF($I40=3,"Junior",IF($I40=2,"Sophomore",IF($I40=1,"Freshman","")))) | O40: ="D:\IMS Images\Headshots\CFB\"&'Team Info'!$B$8&"\"&D40&"_"&C40&".png" -> D:\IMS Images\Headshots\CFB\VANDERBILT\_.png | P40: ="D:\IMS Images\Actionshots\CFB\"&'Team Info'!$B$8&"\"&D40&"_"&C40&".png" -> D:\IMS Images\Actionshots\CFB\VANDERBILT\_.png | Q40: =C40&" "&D40 | R40: =LEFT(C40,1)&". "&D40 -> . | S40: =UPPER(R40) -> . | T40: =IF($I40=4,"SR",IF($I40=3,"JR",IF($I40=2,"SO",IF($I40=1,"FR","")))) | U40: =UPPER(Q40) | V40: =UPPER(C40) | W40: =UPPER(D40) | X40: =UPPER(N40) | Y40: =B40 &" " & U40 -> 38 | Z40: =B40 &" " & Q40 -> 38
A41: 39 | B41: 39 | M41: =VLOOKUP(E41,$AB$3:$AD$36,3,0) -> #N/A | N41: =IF($I41=4,"Senior",IF($I41=3,"Junior",IF($I41=2,"Sophomore",IF($I41=1,"Freshman","")))) | O41: ="D:\IMS Images\Headshots\CFB\"&'Team Info'!$B$8&"\"&D41&"_"&C41&".png" -> D:\IMS Images\Headshots\CFB\VANDERBILT\_.png | P41: ="D:\IMS Images\Actionshots\CFB\"&'Team Info'!$B$8&"\"&D41&"_"&C41&".png" -> D:\IMS Images\Actionshots\CFB\VANDERBILT\_.png | Q41: =C41&" "&D41 | R41: =LEFT(C41,1)&". "&D41 -> . | S41: =UPPER(R41) -> . | T41: =IF($I41=4,"SR",IF($I41=3,"JR",IF($I41=2,"SO",IF($I41=1,"FR","")))) | U41: =UPPER(Q41) | V41: =UPPER(C41) | W41: =UPPER(D41) | X41: =UPPER(N41) | Y41: =B41 &" " & U41 -> 39 | Z41: =B41 &" " & Q41 -> 39
A42: 40 | B42: 40 | M42: =VLOOKUP(E42,$AB$3:$AD$36,3,0) -> #N/A | N42: =IF($I42=4,"Senior",IF($I42=3,"Junior",IF($I42=2,"Sophomore",IF($I42=1,"Freshman","")))) | O42: ="D:\IMS Images\Headshots\CFB\"&'Team Info'!$B$8&"\"&D42&"_"&C42&".png" -> D:\IMS Images\Headshots\CFB\VANDERBILT\_.png | P42: ="D:\IMS Images\Actionshots\CFB\"&'Team Info'!$B$8&"\"&D42&"_"&C42&".png" -> D:\IMS Images\Actionshots\CFB\VANDERBILT\_.png | Q42: =C42&" "&D42 | R42: =LEFT(C42,1)&". "&D42 -> . | S42: =UPPER(R42) -> . | T42: =IF($I42=4,"SR",IF($I42=3,"JR",IF($I42=2,"SO",IF($I42=1,"FR","")))) | U42: =UPPER(Q42) | V42: =UPPER(C42) | W42: =UPPER(D42) | X42: =UPPER(N42) | Y42: =B42 &" " & U42 -> 40 | Z42: =B42 &" " & Q42 -> 40
A43: 41 | B43: 41 | M43: =VLOOKUP(E43,$AB$3:$AD$36,3,0) -> #N/A | N43: =IF($I43=4,"Senior",IF($I43=3,"Junior",IF($I43=2,"Sophomore",IF($I43=1,"Freshman","")))) | O43: ="D:\IMS Images\Headshots\CFB\"&'Team Info'!$B$8&"\"&D43&"_"&C43&".png" -> D:\IMS Images\Headshots\CFB\VANDERBILT\_.png | P43: ="D:\IMS Images\Actionshots\CFB\"&'Team Info'!$B$8&"\"&D43&"_"&C43&".png" -> D:\IMS Images\Actionshots\CFB\VANDERBILT\_.png | Q43: =C43&" "&D43 | R43: =LEFT(C43,1)&". "&D43 -> . | S43: =UPPER(R43) -> . | T43: =IF($I43=4,"SR",IF($I43=3,"JR",IF($I43=2,"SO",IF($I43=1,"FR","")))) | U43: =UPPER(Q43) | V43: =UPPER(C43) | W43: =UPPER(D43) | X43: =UPPER(N43) | Y43: =B43 &" " & U43 -> 41 | Z43: =B43 &" " & Q43 -> 41
A44: 42 | B44: 42 | M44: =VLOOKUP(E44,$AB$3:$AD$36,3,0) -> #N/A | N44: =IF($I44=4,"Senior",IF($I44=3,"Junior",IF($I44=2,"Sophomore",IF($I44=1,"Freshman","")))) | O44: ="D:\IMS Images\Headshots\CFB\"&'Team Info'!$B$8&"\"&D44&"_"&C44&".png" -> D:\IMS Images\Headshots\CFB\VANDERBILT\_.png | P44: ="D:\IMS Images\Actionshots\CFB\"&'Team Info'!$B$8&"\"&D44&"_"&C44&".png" -> D:\IMS Images\Actionshots\CFB\VANDERBILT\_.png | Q44: =C44&" "&D44 | R44: =LEFT(C44,1)&". "&D44 -> . | S44: =UPPER(R44) -> . | T44: =IF($I44=4,"SR",IF($I44=3,"JR",IF($I44=2,"SO",IF($I44=1,"FR","")))) | U44: =UPPER(Q44) | V44: =UPPER(C44) | W44: =UPPER(D44) | X44: =UPPER(N44) | Y44: =B44 &" " & U44 -> 42 | Z44: =B44 &" " & Q44 -> 42
A45: 43 | B45: 43 | M45: =VLOOKUP(E45,$AB$3:$AD$36,3,0) -> #N/A | N45: =IF($I45=4,"Senior",IF($I45=3,"Junior",IF($I45=2,"Sophomore",IF($I45=1,"Freshman","")))) | O45: ="D:\IMS Images\Headshots\CFB\"&'Team Info'!$B$8&"\"&D45&"_"&C45&".png" -> D:\IMS Images\Headshots\CFB\VANDERBILT\_.png | P45: ="D:\IMS Images\Actionshots\CFB\"&'Team Info'!$B$8&"\"&D45&"_"&C45&".png" -> D:\IMS Images\Actionshots\CFB\VANDERBILT\_.png | Q45: =C45&" "&D45 | R45: =LEFT(C45,1)&". "&D45 -> . | S45: =UPPER(R45) -> . | T45: =IF($I45=4,"SR",IF($I45=3,"JR",IF($I45=2,"SO",IF($I45=1,"FR","")))) | U45: =UPPER(Q45) | V45: =UPPER(C45) | W45: =UPPER(D45) | X45: =UPPER(N45) | Y45: =B45 &" " & U45 -> 43 | Z45: =B45 &" " & Q45 -> 43
A46: 44 | B46: 44 | M46: =VLOOKUP(E46,$AB$3:$AD$36,3,0) -> #N/A | N46: =IF($I46=4,"Senior",IF($I46=3,"Junior",IF($I46=2,"Sophomore",IF($I46=1,"Freshman","")))) | O46: ="D:\IMS Images\Headshots\CFB\"&'Team Info'!$B$8&"\"&D46&"_"&C46&".png" -> D:\IMS Images\Headshots\CFB\VANDERBILT\_.png | P46: ="D:\IMS Images\Actionshots\CFB\"&'Team Info'!$B$8&"\"&D46&"_"&C46&".png" -> D:\IMS Images\Actionshots\CFB\VANDERBILT\_.png | Q46: =C46&" "&D46 | R46: =LEFT(C46,1)&". "&D46 -> . | S46: =UPPER(R46) -> . | T46: =IF($I46=4,"SR",IF($I46=3,"JR",IF($I46=2,"SO",IF($I46=1,"FR","")))) | U46: =UPPER(Q46) | V46: =UPPER(C46) | W46: =UPPER(D46) | X46: =UPPER(N46) | Y46: =B46 &" " & U46 -> 44 | Z46: =B46 &" " & Q46 -> 44
A47: 45 | B47: 45 | M47: =VLOOKUP(E47,$AB$3:$AD$36,3,0) -> #N/A | N47: =IF($I47=4,"Senior",IF($I47=3,"Junior",IF($I47=2,"Sophomore",IF($I47=1,"Freshman","")))) | O47: ="D:\IMS Images\Headshots\CFB\"&'Team Info'!$B$8&"\"&D47&"_"&C47&".png" -> D:\IMS Images\Headshots\CFB\VANDERBILT\_.png | P47: ="D:\IMS Images\Actionshots\CFB\"&'Team Info'!$B$8&"\"&D47&"_"&C47&".png" -> D:\IMS Images\Actionshots\CFB\VANDERBILT\_.png | Q47: =C47&" "&D47 | R47: =LEFT(C47,1)&". "&D47 -> . | S47: =UPPER(R47) -> . | T47: =IF($I47=4,"SR",IF($I47=3,"JR",IF($I47=2,"SO",IF($I47=1,"FR","")))) | U47: =UPPER(Q47) | V47: =UPPER(C47) | W47: =UPPER(D47) | X47: =UPPER(N47) | Y47: =B47 &" " & U47 -> 45 | Z47: =B47 &" " & Q47 -> 45
... A102: 99 | B102: 99 | M102: =VLOOKUP(E102,$AB$3:$AD$36,3,0) -> #N/A | N102: =IF($I102=4,"Senior",IF($I102=3,"Junior",IF($I102=2,"Sophomore",IF($I102=1,"Freshman","")))) | O102: ="D:\IMS Images\Headshots\CFB\"&'Team Info'!$B$8&"\"&D102&"_"&C102&".png" -> D:\IMS Images\Headshots\CFB\VANDERBILT\_.png | P102: ="D:\IMS Images\Actionshots\CFB\"&'Team Info'!$B$8&"\"&D102&"_"&C102&".png" -> D:\IMS Images\Actionshots\CFB\VANDERBILT\_.png | Q102: =C102&" "&D102 | R102: =LEFT(C102,1)&". "&D102 -> . | S102: =UPPER(R102) -> . | T102: =IF($I102=4,"SR",IF($I102=3,"JR",IF($I102=2,"SO",IF($I102=1,"FR","")))) | U102: =UPPER(Q102) | V102: =UPPER(C102) | W102: =UPPER(D102) | X102: =UPPER(N102) | Y102: =B102 &" " & U102 -> 99 | Z102: =B102 &" " & Q102 -> 99
M103: =VLOOKUP(E103,$AB$3:$AD$36,3,0) -> #N/A | N103: =IF($I103=4,"Senior",IF($I103=3,"Junior",IF($I103=2,"Sophomore",IF($I103=1,"Freshman","")))) | O103: ="D:\IMS Images\Headshots\CFB\"&'Team Info'!$B$8&"\"&D103&"_"&C103&".png" -> D:\IMS Images\Headshots\CFB\VANDERBILT\_.png | P103: ="D:\IMS Images\Actionshots\CFB\"&'Team Info'!$B$8&"\"&D103&"_"&C103&".png" -> D:\IMS Images\Actionshots\CFB\VANDERBILT\_.png | Q103: =C103&" "&D103 | R103: =LEFT(C103,1)&". "&D103 -> . | S103: =UPPER(R103) -> . | T103: =IF($I103=4,"SR",IF($I103=3,"JR",IF($I103=2,"SO",IF($I103=1,"FR","")))) | U103: =UPPER(Q103) | V103: =UPPER(C103) | W103: =UPPER(D103) | X103: =UPPER(N103) | Y103: =B103 &" " & U103 | Z103: =B103 &" " & Q103
A104: -1 | M104: =VLOOKUP(E104,$AB$3:$AD$36,3,0) -> #N/A | N104: =IF($I104=4,"Senior",IF($I104=3,"Junior",IF($I104=2,"Sophomore",IF($I104=1,"Freshman","")))) | O104: ="D:\IMS Images\Headshots\CFB\"&'Team Info'!$B$8&"\"&D104&"_"&C104&".png" -> D:\IMS Images\Headshots\CFB\VANDERBILT\_.png | P104: ="D:\IMS Images\Actionshots\CFB\"&'Team Info'!$B$8&"\"&D104&"_"&C104&".png" -> D:\IMS Images\Actionshots\CFB\VANDERBILT\_.png | Q104: =C104&" "&D104 | R104: =LEFT(C104,1)&". "&D104 -> . | S104: =UPPER(R104) -> . | T104: =IF($I104=4,"SR",IF($I104=3,"JR",IF($I104=2,"SO",IF($I104=1,"FR","")))) | U104: =UPPER(Q104) | V104: =UPPER(C104) | W104: =UPPER(D104) | X104: =UPPER(N104) | Y104: =B104 &" " & U104 | Z104: =B104 &" " & Q104
A105: -1 | M105: =VLOOKUP(E105,$AB$3:$AD$36,3,0) -> #N/A | N105: =IF($I105=4,"Senior",IF($I105=3,"Junior",IF($I105=2,"Sophomore",IF($I105=1,"Freshman","")))) | O105: ="D:\IMS Images\Headshots\CFB\"&'Team Info'!$B$8&"\"&D105&"_"&C105&".png" -> D:\IMS Images\Headshots\CFB\VANDERBILT\_.png | P105: ="D:\IMS Images\Actionshots\CFB\"&'Team Info'!$B$8&"\"&D105&"_"&C105&".png" -> D:\IMS Images\Actionshots\CFB\VANDERBILT\_.png | Q105: =C105&" "&D105 | R105: =LEFT(C105,1)&". "&D105 -> . | S105: =UPPER(R105) -> . | T105: =IF($I105=4,"SR",IF($I105=3,"JR",IF($I105=2,"SO",IF($I105=1,"FR","")))) | U105: =UPPER(Q105) | V105: =UPPER(C105) | W105: =UPPER(D105) | X105: =UPPER(N105) | Y105: =B105 &" " & U105 | Z105: =B105 &" " & Q105
A106: -1 | M106: =VLOOKUP(E106,$AB$3:$AD$36,3,0) -> #N/A | N106: =IF($I106=4,"Senior",IF($I106=3,"Junior",IF($I106=2,"Sophomore",IF($I106=1,"Freshman","")))) | O106: ="D:\IMS Images\Headshots\CFB\"&'Team Info'!$B$8&"\"&D106&"_"&C106&".png" -> D:\IMS Images\Headshots\CFB\VANDERBILT\_.png | P106: ="D:\IMS Images\Actionshots\CFB\"&'Team Info'!$B$8&"\"&D106&"_"&C106&".png" -> D:\IMS Images\Actionshots\CFB\VANDERBILT\_.png | Q106: =C106&" "&D106 | R106: =LEFT(C106,1)&". "&D106 -> . | S106: =UPPER(R106) -> . | T106: =IF($I106=4,"SR",IF($I106=3,"JR",IF($I106=2,"SO",IF($I106=1,"FR","")))) | U106: =UPPER(Q106) | V106: =UPPER(C106) | W106: =UPPER(D106) | X106: =UPPER(N106) | Y106: =B106 &" " & U106 | Z106: =B106 &" " & Q106
A107: -1 | M107: =VLOOKUP(E107,$AB$3:$AD$36,3,0) -> #N/A | N107: =IF($I107=4,"Senior",IF($I107=3,"Junior",IF($I107=2,"Sophomore",IF($I107=1,"Freshman","")))) | O107: ="D:\IMS Images\Headshots\CFB\"&'Team Info'!$B$8&"\"&D107&"_"&C107&".png" -> D:\IMS Images\Headshots\CFB\VANDERBILT\_.png | P107: ="D:\IMS Images\Actionshots\CFB\"&'Team Info'!$B$8&"\"&D107&"_"&C107&".png" -> D:\IMS Images\Actionshots\CFB\VANDERBILT\_.png | Q107: =C107&" "&D107 | R107: =LEFT(C107,1)&". "&D107 -> . | S107: =UPPER(R107) -> . | T107: =IF($I107=4,"SR",IF($I107=3,"JR",IF($I107=2,"SO",IF($I107=1,"FR","")))) | U107: =UPPER(Q107) | V107: =UPPER(C107) | W107: =UPPER(D107) | X107: =UPPER(N107) | Y107: =B107 &" " & U107 | Z107: =B107 &" " & Q107
A108: -1 | M108: =VLOOKUP(E108,$AB$3:$AD$36,3,0) -> #N/A | N108: =IF($I108=4,"Senior",IF($I108=3,"Junior",IF($I108=2,"Sophomore",IF($I108=1,"Freshman","")))) | O108: ="D:\IMS Images\Headshots\CFB\"&'Team Info'!$B$8&"\"&D108&"_"&C108&".png" -> D:\IMS Images\Headshots\CFB\VANDERBILT\_.png | P108: ="D:\IMS Images\Actionshots\CFB\"&'Team Info'!$B$8&"\"&D108&"_"&C108&".png" -> D:\IMS Images\Actionshots\CFB\VANDERBILT\_.png | Q108: =C108&" "&D108 | R108: =LEFT(C108,1)&". "&D108 -> . | S108: =UPPER(R108) -> . | T108: =IF($I108=4,"SR",IF($I108=3,"JR",IF($I108=2,"SO",IF($I108=1,"FR","")))) | U108: =UPPER(Q108) | V108: =UPPER(C108) | W108: =UPPER(D108) | X108: =UPPER(N108) | Y108: =B108 &" " & U108 | Z108: =B108 &" " & Q108
A109: -1 | M109: =VLOOKUP(E109,$AB$3:$AD$36,3,0) -> #N/A | N109: =IF($I109=4,"Senior",IF($I109=3,"Junior",IF($I109=2,"Sophomore",IF($I109=1,"Freshman","")))) | O109: ="D:\IMS Images\Headshots\CFB\"&'Team Info'!$B$8&"\"&D109&"_"&C109&".png" -> D:\IMS Images\Headshots\CFB\VANDERBILT\_.png | P109: ="D:\IMS Images\Actionshots\CFB\"&'Team Info'!$B$8&"\"&D109&"_"&C109&".png" -> D:\IMS Images\Actionshots\CFB\VANDERBILT\_.png | Q109: =C109&" "&D109 | R109: =LEFT(C109,1)&". "&D109 -> . | S109: =UPPER(R109) -> . | T109: =IF($I109=4,"SR",IF($I109=3,"JR",IF($I109=2,"SO",IF($I109=1,"FR","")))) | U109: =UPPER(Q109) | V109: =UPPER(C109) | W109: =UPPER(D109) | X109: =UPPER(N109) | Y109: =B109 &" " & U109 | Z109: =B109 &" " & Q109
A110: -1 | M110: =VLOOKUP(E110,$AB$3:$AD$36,3,0) -> #N/A | N110: =IF($I110=4,"Senior",IF($I110=3,"Junior",IF($I110=2,"Sophomore",IF($I110=1,"Freshman","")))) | O110: ="D:\IMS Images\Headshots\CFB\"&'Team Info'!$B$8&"\"&D110&"_"&C110&".png" -> D:\IMS Images\Headshots\CFB\VANDERBILT\_.png | P110: ="D:\IMS Images\Actionshots\CFB\"&'Team Info'!$B$8&"\"&D110&"_"&C110&".png" -> D:\IMS Images\Actionshots\CFB\VANDERBILT\_.png | Q110: =C110&" "&D110 | R110: =LEFT(C110,1)&". "&D110 -> . | S110: =UPPER(R110) -> . | T110: =IF($I110=4,"SR",IF($I110=3,"JR",IF($I110=2,"SO",IF($I110=1,"FR","")))) | U110: =UPPER(Q110) | V110: =UPPER(C110) | W110: =UPPER(D110) | X110: =UPPER(N110) | Y110: =B110 &" " & U110 | Z110: =B110 &" " & Q110
A111: -1 | M111: =VLOOKUP(E111,$AB$3:$AD$36,3,0) -> #N/A | N111: =IF($I111=4,"Senior",IF($I111=3,"Junior",IF($I111=2,"Sophomore",IF($I111=1,"Freshman","")))) | O111: ="D:\IMS Images\Headshots\CFB\"&'Team Info'!$B$8&"\"&D111&"_"&C111&".png" -> D:\IMS Images\Headshots\CFB\VANDERBILT\_.png | P111: ="D:\IMS Images\Actionshots\CFB\"&'Team Info'!$B$8&"\"&D111&"_"&C111&".png" -> D:\IMS Images\Actionshots\CFB\VANDERBILT\_.png | Q111: =C111&" "&D111 | R111: =LEFT(C111,1)&". "&D111 -> . | S111: =UPPER(R111) -> . | T111: =IF($I111=4,"SR",IF($I111=3,"JR",IF($I111=2,"SO",IF($I111=1,"FR","")))) | U111: =UPPER(Q111) | V111: =UPPER(C111) | W111: =UPPER(D111) | X111: =UPPER(N111) | Y111: =B111 &" " & U111 | Z111: =B111 &" " & Q111
A112: -1 | M112: =VLOOKUP(E112,$AB$3:$AD$36,3,0) -> #N/A | N112: =IF($I112=4,"Senior",IF($I112=3,"Junior",IF($I112=2,"Sophomore",IF($I112=1,"Freshman","")))) | O112: ="D:\IMS Images\Headshots\CFB\"&'Team Info'!$B$8&"\"&D112&"_"&C112&".png" -> D:\IMS Images\Headshots\CFB\VANDERBILT\_.png | P112: ="D:\IMS Images\Actionshots\CFB\"&'Team Info'!$B$8&"\"&D112&"_"&C112&".png" -> D:\IMS Images\Actionshots\CFB\VANDERBILT\_.png | Q112: =C112&" "&D112 | R112: =LEFT(C112,1)&". "&D112 -> . | S112: =UPPER(R112) -> . | T112: =IF($I112=4,"SR",IF($I112=3,"JR",IF($I112=2,"SO",IF($I112=1,"FR","")))) | U112: =UPPER(Q112) | V112: =UPPER(C112) | W112: =UPPER(D112) | X112: =UPPER(N112) | Y112: =B112 &" " & U112 | Z112: =B112 &" " & Q112
A113: -1 | M113: =VLOOKUP(E113,$AB$3:$AD$36,3,0) -> #N/A | N113: =IF($I113=4,"Senior",IF($I113=3,"Junior",IF($I113=2,"Sophomore",IF($I113=1,"Freshman","")))) | O113: ="D:\IMS Images\Headshots\CFB\"&'Team Info'!$B$8&"\"&D113&"_"&C113&".png" -> D:\IMS Images\Headshots\CFB\VANDERBILT\_.png | P113: ="D:\IMS Images\Actionshots\CFB\"&'Team Info'!$B$8&"\"&D113&"_"&C113&".png" -> D:\IMS Images\Actionshots\CFB\VANDERBILT\_.png | Q113: =C113&" "&D113 | R113: =LEFT(C113,1)&". "&D113 -> . | S113: =UPPER(R113) -> . | T113: =IF($I113=4,"SR",IF($I113=3,"JR",IF($I113=2,"SO",IF($I113=1,"FR","")))) | U113: =UPPER(Q113) | V113: =UPPER(C113) | W113: =UPPER(D113) | X113: =UPPER(N113) | Y113: =B113 &" " & U113 | Z113: =B113 &" " & Q113
...

Sheet Player Stats
A1: THIS TAB IS FOR | C1: Passing | E1: xx% (or x/x) | G1: x Yds | I1: x TD | K1: x INT | O1: # OF STATS: Type in 3 or 2 if less than 4 in the graphic
A2: XPRESSION USE ONLY | C2: Rushing | E2: x Rush | G2: x Yds | I2: x Avg | K2: x TD
A3: Datalinked to ranges below | C3: Receiving | E3: x Rec | G3: x Yds | I3: x Avg | K3: x TD | O3: COLUMN HIGHLIGHT: Type in 1 in column right of stat to highlight
A4: Season - 1100-1700 | C4: Punting | E4: x Punts | G4: x Avg | I4: x Long | K4: x Inside 20
A5: Career - 2100-2600 | C5: Field Goal | E5: x/x FG | G5: xx.x% | I5: x Long
C6: Defensive | E6: Tkls | G6: TFL | I6: Sacks | K6: PBU | M6: INT
E7: Values are entered without stat category text, if deviating from the defaults above you'll need to adjust the category text in Xpression
A8: Jersey | B8: Display Jersey | C8: Player Name Here | D8: # OF STATS | E8: SEASON STAT 1 | F8: Hilite1 | G8: SEASON STAT 2 | H8: Hilite2 | I8: SEASON STAT 3 | J8: Hilite3 | K8: SEASON STAT 4 | L8: Hilite4 | M8: SEASON STAT 5 | N8: Hilite5 | O8: SEASON STAT 6 | P8: Hilite6 | Q8: SEASON STAT DROP | R8: # OF STATS | S8: CAREER STAT 1 | T8: Hilite1 | U8: CAREER STAT 2 | V8: Hilite2 | W8: CAREER STAT 3 | X8: Hilite3 | Y8: CAREER STAT 4 | Z8: Hilite4 | AA8: CAREER STAT 5 | AB8: Hilite5 | AC8: CAREER STAT 6 | AD8: Hilite6 | AE8: CAREER STAT DROP
A9: =Roster!$A3 -> 1 | B9: =Roster!$A3 -> 1 | C9: =Roster!$Q3 -> First Name Last Name
A10: =Roster!$A4 -> 2 | B10: =Roster!$A4 -> 2 | C10: =Roster!$Q4
A11: =Roster!$A5 -> 3 | B11: =Roster!$A5 -> 3 | C11: =Roster!$Q5
A12: =Roster!$A6 -> 4 | B12: =Roster!$A6 -> 4 | C12: =Roster!$Q6
A13: =Roster!$A7 -> 5 | B13: =Roster!$A7 -> 5 | C13: =Roster!$Q7
A14: =Roster!$A8 -> 6 | B14: =Roster!$A8 -> 6 | C14: =Roster!$Q8
A15: =Roster!$A9 -> 7 | B15: =Roster!$A9 -> 7 | C15: =Roster!$Q9
A16: =Roster!$A10 -> 8 | B16: =Roster!$A10 -> 8 | C16: =Roster!$Q10
A17: =Roster!$A11 -> 9 | B17: =Roster!$A11 -> 9 | C17: =Roster!$Q11 | Q17: Leads team
A18: =Roster!$A12 -> 10 | B18: =Roster!$A12 -> 10 | C18: =Roster!$Q12
A19: =Roster!$A13 -> 11 | B19: =Roster!$A13 -> 11 | C19: =Roster!$Q13
A20: =Roster!$A14 -> 12 | B20: =Roster!$A14 -> 12 | C20: =Roster!$Q14
A21: =Roster!$A15 -> 13 | B21: =Roster!$A15 -> 13 | C21: =Roster!$Q15
A22: =Roster!$A16 -> 14 | B22: =Roster!$A16 -> 14 | C22: =Roster!$Q16
A23: =Roster!$A17 -> 15 | B23: =Roster!$A17 -> 15 | C23: =Roster!$Q17
A24: =Roster!$A18 -> 16 | B24: =Roster!$A18 -> 16 | C24: =Roster!$Q18
A25: =Roster!$A19 -> 17 | B25: =Roster!$A19 -> 17 | C25: =Roster!$Q19
A26: =Roster!$A20 -> 18 | B26: =Roster!$A20 -> 18 | C26: =Roster!$Q20
A27: =Roster!$A21 -> 19 | B27: =Roster!$A21 -> 19 | C27: =Roster!$Q21
A28: =Roster!$A22 -> 20 | B28: =Roster!$A22 -> 20 | C28: =Roster!$Q22
A29: =Roster!$A23 -> 21 | B29: =Roster!$A23 -> 21 | C29: =Roster!$Q23
... A156: =Roster!$A150 -> 0 | B156: =Roster!$A150 -> 0 | C156: =Roster!$Q150

Sheet Team Stats
A1: TEAM STATS | B1: AVG | C1: FBS OR CONF RANK | E1: SEASON STAT INFO | F1: RANK | G1: COMBINED | I1: SEASON STAT INFO | J1: RANK | K1: COMBINED
A2: Points Per Game | B2: 34.6 | C2: T-26th in FBS | E2: =B2&" PPG" -> 34.6 PPG | F2: ="("&C2&")" -> (T-26th in FBS) | G2: =E2&" "&F2 -> 34.6 PPG (T-26th in FBS) | I2: =UPPER(E2) -> 34.6 PPG | J2: =UPPER(F2) -> (T-26TH IN FBS) | K2: =UPPER(G2) -> 34.6 PPG (T-26TH IN FBS)
A3: Yards Per Game | B3: 345.7 | C3: 6th in SEC | E3: =B3&" YPG" -> 345.7 YPG | F3: ="("&C3&")" -> (6th in SEC) | G3: =E3&" "&F3 -> 345.7 YPG (6th in SEC) | I3: =UPPER(E3) -> 345.7 YPG | J3: =UPPER(F3) -> (6TH IN SEC) | K3: =UPPER(G3) -> 345.7 YPG (6TH IN SEC)
A4: Rush Yds Per Game | E4: YPG | F4: ="("&C4&")" -> () | G4: =E4&" "&F4 -> YPG () | I4: =UPPER(E4) -> YPG | J4: =UPPER(F4) -> () | K4: =UPPER(G4) -> YPG ()
A5: Pass Yds Per Game | E5: YPG | F5: ="("&C5&")" -> () | G5: =E5&" "&F5 -> YPG () | I5: =UPPER(E5) -> YPG | J5: =UPPER(F5) -> () | K5: =UPPER(G5) -> YPG ()
A6: Red Zone scoring (all scores) | E6: =B6 -> 0 | F6: ="("&C6&")" -> () | G6: =E6&" "&F6 -> 0 () | I6: =UPPER(E6) -> 0 | J6: =UPPER(F6) -> () | K6: =UPPER(G6) -> 0 ()
A7: Red Zone Drives | E7: =B7&" poss" -> poss | F7: ="("&C7&")" -> () | G7: =E7&" "&F7 -> poss () | I7: =UPPER(E7) -> POSS | J7: =UPPER(F7) -> () | K7: =UPPER(G7) -> POSS ()
A8: Red Zone FG | E8: =B8&" FG" -> FG | F8: ="("&C8&")" -> () | G8: =E8&" "&F8 -> FG () | I8: =UPPER(E8) -> FG | J8: =UPPER(F8) -> () | K8: =UPPER(G8) -> FG ()
A9: Red Zone TD | E9: =B9&" TD" -> TD | F9: ="("&C9&")" -> () | G9: =E9&" "&F9 -> TD () | I9: =UPPER(E9) -> TD | J9: =UPPER(F9) -> () | K9: =UPPER(G9) -> TD ()
A10: Sacks allowed | E10: =B10 -> 0 | F10: ="("&C10&")" -> () | G10: =E10&" "&F10 -> 0 () | I10: =UPPER(E10) -> 0 | J10: =UPPER(F10) -> () | K10: =UPPER(G10) -> 0 ()
A11: Time of Possession | E11: =B11 -> 0 | F11: ="("&C11&")" -> () | G11: =E11&" "&F11 -> 0 () | I11: =UPPER(E11) -> 0 | J11: =UPPER(F11) -> () | K11: =UPPER(G11) -> 0 ()
A12: 3rd Down Conv | E12: =B12 -> 0 | F12: ="("&C12&")" -> () | G12: =E12&" "&F12 -> 0 () | I12: =UPPER(E12) -> 0 | J12: =UPPER(F12) -> () | K12: =UPPER(G12) -> 0 ()
A13: 4th Down Conv (use "of") | E13: =B13 -> 0 | F13: ="("&C13&")" -> () | G13: =E13&" "&F13 -> 0 () | I13: =UPPER(E13) -> 0 | J13: =UPPER(F13) -> () | K13: =UPPER(G13) -> 0 ()
A14: Turnovers | E14: =B14 -> 0 | F14: ="("&C14&")" -> () | G14: =E14&" "&F14 -> 0 () | I14: =UPPER(E14) -> 0 | J14: =UPPER(F14) -> () | K14: =UPPER(G14) -> 0 ()
A15: Penalty Yds Per Game | E15: YPG | F15: ="("&C15&")" -> () | G15: =E15&" "&F15 -> YPG () | I15: =UPPER(E15) -> YPG | J15: =UPPER(F15) -> () | K15: =UPPER(G15) -> YPG ()
A16: 1st Qtr Points | E16: =B16 -> 0 | F16: ="("&C16&")" -> () | G16: =E16&" "&F16 -> 0 () | I16: =UPPER(E16) -> 0 | J16: =UPPER(F16) -> () | K16: =UPPER(G16) -> 0 ()
A17: 2nd Qtr Points | E17: =B17 -> 0 | F17: ="("&C17&")" -> () | G17: =E17&" "&F17 -> 0 () | I17: =UPPER(E17) -> 0 | J17: =UPPER(F17) -> () | K17: =UPPER(G17) -> 0 ()
A18: 3rd Qtr Points | E18: =B18 -> 0 | F18: ="("&C18&")" -> () | G18: =E18&" "&F18 -> 0 () | I18: =UPPER(E18) -> 0 | J18: =UPPER(F18) -> () | K18: =UPPER(G18) -> 0 ()
A19: 4th Qtr Points | E19: =B19 -> 0 | F19: ="("&C19&")" -> () | G19: =E19&" "&F19 -> 0 () | I19: =UPPER(E19) -> 0 | J19: =UPPER(F19) -> () | K19: =UPPER(G19) -> 0 ()
A20: Opp 1st Qtr Points | E20: =B20 -> 0 | F20: ="("&C20&")" -> () | G20: =E20&" "&F20 -> 0 () | I20: =UPPER(E20) -> 0 | J20: =UPPER(F20) -> () | K20: =UPPER(G20) -> 0 ()
A21: Opp 2nd Qtr Points | E21: =B21 -> 0 | F21: ="("&C21&")" -> () | G21: =E21&" "&F21 -> 0 () | I21: =UPPER(E21) -> 0 | J21: =UPPER(F21) -> () | K21: =UPPER(G21) -> 0 ()
A22: Opp 3rd Qtr Points | E22: =B22 -> 0 | F22: ="("&C22&")" -> () | G22: =E22&" "&F22 -> 0 () | I22: =UPPER(E22) -> 0 | J22: =UPPER(F22) -> () | K22: =UPPER(G22) -> 0 ()
A23: Opp 4th Qtr Points | E23: =B23 -> 0 | F23: ="("&C23&")" -> () | G23: =E23&" "&F23 -> 0 () | I23: =UPPER(E23) -> 0 | J23: =UPPER(F23) -> () | K23: =UPPER(G23) -> 0 ()
A24: Points Allowed Per Game | E24: PPG | F24: ="("&C24&")" -> () | G24: =E24&" "&F24 -> PPG () | I24: =UPPER(E24) -> PPG | J24: =UPPER(F24) -> () | K24: =UPPER(G24) -> PPG ()
A25: Opp Yards Per Game | E25: YPG | F25: ="("&C25&")" -> () | G25: =E25&" "&F25 -> YPG () | I25: =UPPER(E25) -> YPG | J25: =UPPER(F25) -> () | K25: =UPPER(G25) -> YPG ()
A26: Opp Rush Yds Per Game | E26: YPG | F26: ="("&C26&")" -> () | G26: =E26&" "&F26 -> YPG () | I26: =UPPER(E26) -> YPG | J26: =UPPER(F26) -> () | K26: =UPPER(G26) -> YPG ()
A27: Opp Pass Yds Per Game | E27: YPG | F27: ="("&C27&")" -> () | G27: =E27&" "&F27 -> YPG () | I27: =UPPER(E27) -> YPG | J27: =UPPER(F27) -> () | K27: =UPPER(G27) -> YPG ()
A28: Red Zone Def. TD % Allowed | E28: =B28 -> 0 | F28: ="("&C28&")" -> () | G28: =E28&" "&F28 -> 0 () | I28: =UPPER(E28) -> 0 | J28: =UPPER(F28) -> () | K28: =UPPER(G28) -> 0 ()
A29: 3rd Down Defense | E29: =B29 -> 0 | F29: ="("&C29&")" -> () | G29: =E29&" "&F29 -> 0 () | I29: =UPPER(E29) -> 0 | J29: =UPPER(F29) -> () | K29: =UPPER(G29) -> 0 ()
A30: 4th down Defense (use "of") | E30: =B30 -> 0 | F30: ="("&C30&")" -> () | G30: =E30&" "&F30 -> 0 () | I30: =UPPER(E30) -> 0 | J30: =UPPER(F30) -> () | K30: =UPPER(G30) -> 0 ()
A31: Team sacks | E31: =B31 -> 0 | F31: ="("&C31&")" -> () | G31: =E31&" "&F31 -> 0 () | I31: =UPPER(E31) -> 0 | J31: =UPPER(F31) -> () | K31: =UPPER(G31) -> 0 ()
A32: Turnover margin | E32: =B32 -> 0 | F32: ="("&C32&")" -> () | G32: =E32&" "&F32 -> 0 () | I32: =UPPER(E32) -> 0 | J32: =UPPER(F32) -> () | K32: =UPPER(G32) -> 0 ()
A33: Team Interceptions | E33: =B33&" INT" -> INT | F33: ="("&C33&")" -> () | G33: =E33&" "&F33 -> INT () | I33: =UPPER(E33) -> INT | J33: =UPPER(F33) -> () | K33: =UPPER(G33) -> INT ()
A34: Team Takeaways | E34: =B34&" Takeaways" -> Takeaways | F34: ="("&C34&")" -> () | G34: =E34&" "&F34 -> Takeaways () | I34: =UPPER(E34) -> TAKEAWAYS | J34: =UPPER(F34) -> () | K34: =UPPER(G34) -> TAKEAWAYS ()

Sheet Schedule
A1: SCHEDULE - FULLSCREEN | D1: TEMPLATE 9106 | I1: NETWORK_LOGO_PATH | K1: SCHED_NETWORK
A2: WEEK | B2: at | C2: OPPONENT | D2: DATE | E2: TIME | F2: NETWORK LOGO | I2: ="D:\IMS Images\Network\Primary\" -> D:\IMS Images\Network\Primary\ | K2: =$I$2&F3&".png" -> D:\IMS Images\Network\Primary\ABC.png
A3: 1 | B3: at | C3: Florida State | D3: Aug 30 | F3: ABC | K3: =$I$2&F4&".png" -> D:\IMS Images\Network\Primary\SEC_NETWORK.png
A4: 2 | C4: UL Monroe | D4: Sept 6 | F4: SEC_NETWORK | K4: =$I$2&F5&".png" -> D:\IMS Images\Network\Primary\BLANK_LOGO.png
A5: 3 | C5: 23 Wisconsin | D5: Sept 13 | F5: BLANK_LOGO | K5: =$I$2&F6&".png" -> D:\IMS Images\Network\Primary\.png
A6: 4 | C6: Idle | K6: =$I$2&F7&".png" -> D:\IMS Images\Network\Primary\.png
A7: 5 | B7: at | C7: 2 Georgia | D7: Sept 27 | K7: =$I$2&F8&".png" -> D:\IMS Images\Network\Primary\.png
A8: 6 | C8: Vanderbilt | D8: Oct 4 | K8: =$I$2&F9&".png" -> D:\IMS Images\Network\Primary\.png
A9: 7 | B9: at | C9: Missouri | D9: Oct 11 | K9: =$I$2&F10&".png" -> D:\IMS Images\Network\Primary\ABC.png
A10: 8 | C10: 17 Tennessee | D10: Oct 18 | F10: ABC | K10: =$I$2&F11&".png" -> D:\IMS Images\Network\Primary\.png
A11: 9 | B11: at | C11: 9 South Carolina | D11: Oct 25 | K11: =$I$2&F12&".png" -> D:\IMS Images\Network\Primary\.png
A12: 10 | C12: Idle | K12: =$I$2&F13&".png" -> D:\IMS Images\Network\Primary\.png
A13: 11 | C13: 14 LSU | D13: Nov 8 | K13: =$I$2&F14&".png" -> D:\IMS Images\Network\Primary\.png
A14: 12 | C14: Oklahoma | D14: Nov 15
A15: 13 | C15: Eastern Illinois | D15: Nov 23 | F15: ESPN
A16: SAVES TO 750 (AWAY) OR 850 (HOME)
A18: CURRENT WEEK | D18: 1
A20: UPCOMING GAMES - BLITZ | D20: TEMPLATE 9956
A21: WEEK | B21: at | C21: OPPONENT | D21: DATE | E21: TIME | F21: OPPONENT LOGO
A22: =D18+1 -> 2 | B22: =VLOOKUP(A22,A1:F15,2,TRUE) | C22: =VLOOKUP(A22,A1:F15,3,TRUE) -> UL Monroe | D22: =VLOOKUP(A22,A1:F15,4,TRUE) -> Sept 6 | F22: UL_MONROE
A23: =A22+1 -> 3 | B23: =VLOOKUP(A23,A1:F15,2,TRUE) | C23: =VLOOKUP(A23,A1:F15,3,TRUE) -> 23 Wisconsin | D23: =VLOOKUP(A23,A1:F15,4,TRUE) -> Sept 13 | F23: WISCONSIN
A24: =A23+1 -> 4 | B24: =VLOOKUP(A24,A1:F15,2,TRUE) | C24: =VLOOKUP(A24,A1:F15,3,TRUE) -> Idle | D24: =VLOOKUP(A24,A1:F15,4,TRUE) -> 0
A25: =A24+1 -> 5 | B25: =VLOOKUP(A25,A1:F15,2,TRUE) -> at | C25: =VLOOKUP(A25,A1:F15,3,TRUE) -> 2 Georgia | D25: =VLOOKUP(A25,A1:F15,4,TRUE) -> Sept 27 | F25: GEORGIA
A26: =A25+1 -> 6 | B26: =VLOOKUP(A26,A1:F15,2,TRUE) | C26: =VLOOKUP(A26,A1:F15,3,TRUE) -> Vanderbilt | D26: =VLOOKUP(A26,A1:F15,4,TRUE) -> Oct 4 | F26: VANDERBILT
A27: SAVES TO 751 (AWAY) OR 851 (HOME)

Sheet Bumps & Front Ends
A1: PLAYER BUMPS | E1: TEMPLATE: 9043
A2: JERSEY | B2: SAVE | C2: Player Name Here | D2: HEADER | E2: NOTE (ALL CAPS CFB // Upper-Lower SEC) | F2: HEADSHOT IMAGE | G2: LOGO
A3: 1 | B3: =IF('Team Info'!B2="Away",8701,8801) -> 8801 | C3: =VLOOKUP(A3,ROSTER,17,0) -> First Name Last Name | D3: Optional Header | E3: Note goes here | F3: =VLOOKUP(A3,ROSTER,4,0) & "_" & VLOOKUP(A3,ROSTER,3,0) -> Last Name_First Name | G3: ='Team Info'!$B$8 -> VANDERBILT | J3: 0 | K3: OFF
A4: 2 | B4: =B3+1 -> 8802 | C4: =VLOOKUP(A4,ROSTER,17,0) | F4: =VLOOKUP(A4,ROSTER,4,0) & "_" & VLOOKUP(A4,ROSTER,3,0) -> _ | G4: ='Team Info'!$B$8 -> VANDERBILT | J4: 1 | K4: ACTION SHOT
A5: 3 | B5: =B4+1 -> 8803 | C5: =VLOOKUP(A5,ROSTER,17,0) | F5: =VLOOKUP(A5,ROSTER,4,0) & "_" & VLOOKUP(A5,ROSTER,3,0) -> _ | G5: ='Team Info'!$B$8 -> VANDERBILT | J5: 2 | K5: PORTRAIT
A6: 4 | B6: =B5+1 -> 8804 | C6: =VLOOKUP(A6,ROSTER,17,0) | F6: =VLOOKUP(A6,ROSTER,4,0) & "_" & VLOOKUP(A6,ROSTER,3,0) -> _ | G6: ='Team Info'!$B$8 -> VANDERBILT
A7: 5 | B7: =B6+1 -> 8805 | C7: =VLOOKUP(A7,ROSTER,17,0) | F7: =VLOOKUP(A7,ROSTER,4,0) & "_" & VLOOKUP(A7,ROSTER,3,0) -> _ | G7: ='Team Info'!$B$8 -> VANDERBILT
A8: 6 | B8: =B7+1 -> 8806 | C8: =VLOOKUP(A8,ROSTER,17,0) | F8: =VLOOKUP(A8,ROSTER,4,0) & "_" & VLOOKUP(A8,ROSTER,3,0) -> _ | G8: ='Team Info'!$B$8 -> VANDERBILT
A9: 7 | B9: =B8+1 -> 8807 | C9: =VLOOKUP(A9,ROSTER,17,0) | F9: =VLOOKUP(A9,ROSTER,4,0) & "_" & VLOOKUP(A9,ROSTER,3,0) -> _ | G9: ='Team Info'!$B$8 -> VANDERBILT
A10: 8 | B10: =B9+1 -> 8808 | C10: =VLOOKUP(A10,ROSTER,17,0) | F10: =VLOOKUP(A10,ROSTER,4,0) & "_" & VLOOKUP(A10,ROSTER,3,0) -> _ | G10: ='Team Info'!$B$8 -> VANDERBILT
A11: 9 | B11: =B10+1 -> 8809 | C11: =VLOOKUP(A11,ROSTER,17,0) | F11: =VLOOKUP(A11,ROSTER,4,0) & "_" & VLOOKUP(A11,ROSTER,3,0) -> _ | G11: ='Team Info'!$B$8 -> VANDERBILT
A12: 10 | B12: =B11+1 -> 8810 | C12: =VLOOKUP(A12,ROSTER,17,0) | F12: =VLOOKUP(A12,ROSTER,4,0) & "_" & VLOOKUP(A12,ROSTER,3,0) -> _ | G12: ='Team Info'!$B$8 -> VANDERBILT
A13: 28 | B13: =B12+1 -> 8811 | C13: =VLOOKUP(A13,ROSTER,17,0) | F13: =VLOOKUP(A13,ROSTER,4,0) & "_" & VLOOKUP(A13,ROSTER,3,0) -> _ | G13: ='Team Info'!$B$8 -> VANDERBILT
A14: 30 | B14: =B13+1 -> 8812 | C14: =VLOOKUP(A14,ROSTER,17,0) | F14: =VLOOKUP(A14,ROSTER,4,0) & "_" & VLOOKUP(A14,ROSTER,3,0) -> _ | G14: ='Team Info'!$B$8 -> VANDERBILT
A15: 31 | B15: =B14+1 -> 8813 | C15: =VLOOKUP(A15,ROSTER,17,0) | F15: =VLOOKUP(A15,ROSTER,4,0) & "_" & VLOOKUP(A15,ROSTER,3,0) -> _ | G15: ='Team Info'!$B$8 -> VANDERBILT
A16: 32 | B16: =B15+1 -> 8814 | C16: =VLOOKUP(A16,ROSTER,17,0) | F16: =VLOOKUP(A16,ROSTER,4,0) & "_" & VLOOKUP(A16,ROSTER,3,0) -> _ | G16: ='Team Info'!$B$8 -> VANDERBILT
A17: 80 | B17: =B16+1 -> 8815 | C17: =VLOOKUP(A17,ROSTER,17,0) | F17: =VLOOKUP(A17,ROSTER,4,0) & "_" & VLOOKUP(A17,ROSTER,3,0) -> _ | G17: ='Team Info'!$B$8 -> VANDERBILT
B18: AWAY TEAM - SAVE TO 8700s | E18: HOME TEAM - SAVE TO 8800s | K18: 20 - Upper/Lower; 24=CAPS
A20: PLAYER FRONT ENDS | E20: TEMPLATE: 9351
A21: JERSEY | B21: SAVE | C21: FIRST NAME | D21: LAST NAME | E21: PORTRAIT IMAGE | F21: LOGO | G21: IMAGE
A22: 1 | B22: =IF('Team Info'!B2="Away",87001,88001) -> 88001 | C22: =VLOOKUP(A22,ROSTER,3,0) -> First Name | D22: =VLOOKUP(A22,ROSTER,4,0) -> Last Name | E22: =D22 & "_" & C22 -> Last Name_First Name | F22: ='Team Info'!$B$8 -> VANDERBILT | G22: 1 | H22: =VLOOKUP(G22,$J$22:$K$23,2,0) -> ON | J22: 0 | K22: OFF
A23: 2 | B23: =B22+1 -> 88002 | C23: =VLOOKUP(A23,ROSTER,3,0) -> 0 | D23: =VLOOKUP(A23,ROSTER,4,0) -> 0 | E23: =D23 & "_" & C23 -> 0_0 | F23: ='Team Info'!$B$8 -> VANDERBILT | G23: 1 | H23: =VLOOKUP(G23,$J$22:$K$23,2,0) -> ON | J23: 1 | K23: ON
A24: 3 | B24: =B23+1 -> 88003 | C24: =VLOOKUP(A24,ROSTER,3,0) -> 0 | D24: =VLOOKUP(A24,ROSTER,4,0) -> 0 | E24: =D24 & "_" & C24 -> 0_0 | F24: ='Team Info'!$B$8 -> VANDERBILT | G24: 1 | H24: =VLOOKUP(G24,$J$22:$K$23,2,0) -> ON
A25: 4 | B25: =B24+1 -> 88004 | C25: =VLOOKUP(A25,ROSTER,3,0) -> 0 | D25: =VLOOKUP(A25,ROSTER,4,0) -> 0 | E25: =D25 & "_" & C25 -> 0_0 | F25: ='Team Info'!$B$8 -> VANDERBILT | G25: 1 | H25: =VLOOKUP(G25,$J$22:$K$23,2,0) -> ON
A26: 5 | B26: =B25+1 -> 88005 | C26: =VLOOKUP(A26,ROSTER,3,0) -> 0 | D26: =VLOOKUP(A26,ROSTER,4,0) -> 0 | E26: =D26 & "_" & C26 -> 0_0 | F26: ='Team Info'!$B$8 -> VANDERBILT | G26: 1 | H26: =VLOOKUP(G26,$J$22:$K$23,2,0) -> ON
A27: 6 | B27: =B26+1 -> 88006 | C27: =VLOOKUP(A27,ROSTER,3,0) -> 0 | D27: =VLOOKUP(A27,ROSTER,4,0) -> 0 | E27: =D27 & "_" & C27 -> 0_0 | F27: ='Team Info'!$B$8 -> VANDERBILT | G27: 1 | H27: =VLOOKUP(G27,$J$22:$K$23,2,0) -> ON
A28: 7 | B28: =B27+1 -> 88007 | C28: =VLOOKUP(A28,ROSTER,3,0) -> 0 | D28: =VLOOKUP(A28,ROSTER,4,0) -> 0 | E28: =D28 & "_" & C28 -> 0_0 | F28: ='Team Info'!$B$8 -> VANDERBILT | G28: 1 | H28: =VLOOKUP(G28,$J$22:$K$23,2,0) -> ON
A29: 8 | B29: =B28+1 -> 88008 | C29: =VLOOKUP(A29,ROSTER,3,0) -> 0 | D29: =VLOOKUP(A29,ROSTER,4,0) -> 0 | E29: =D29 & "_" & C29 -> 0_0 | F29: ='Team Info'!$B$8 -> VANDERBILT | G29: 1 | H29: =VLOOKUP(G29,$J$22:$K$23,2,0) -> ON
A30: 9 | B30: =B29+1 -> 88009 | C30: =VLOOKUP(A30,ROSTER,3,0) -> 0 | D30: =VLOOKUP(A30,ROSTER,4,0) -> 0 | E30: =D30 & "_" & C30 -> 0_0 | F30: ='Team Info'!$B$8 -> VANDERBILT | G30: 1 | H30: =VLOOKUP(G30,$J$22:$K$23,2,0) -> ON
A31: 10 | B31: =B30+1 -> 88010 | C31: =VLOOKUP(A31,ROSTER,3,0) -> 0 | D31: =VLOOKUP(A31,ROSTER,4,0) -> 0 | E31: =D31 & "_" & C31 -> 0_0 | F31: ='Team Info'!$B$8 -> VANDERBILT | G31: 1 | H31: =VLOOKUP(G31,$J$22:$K$23,2,0) -> ON
A32: 28 | B32: =B31+1 -> 88011 | C32: =VLOOKUP(A32,ROSTER,3,0) -> 0 | D32: =VLOOKUP(A32,ROSTER,4,0) -> 0 | E32: =D32 & "_" & C32 -> 0_0 | F32: ='Team Info'!$B$8 -> VANDERBILT | G32: 1 | H32: =VLOOKUP(G32,$J$22:$K$23,2,0) -> ON
A33: 30 | B33: =B32+1 -> 88012 | C33: =VLOOKUP(A33,ROSTER,3,0) -> 0 | D33: =VLOOKUP(A33,ROSTER,4,0) -> 0 | E33: =D33 & "_" & C33 -> 0_0 | F33: ='Team Info'!$B$8 -> VANDERBILT | G33: 1 | H33: =VLOOKUP(G33,$J$22:$K$23,2,0) -> ON
A34: 35 | B34: =B33+1 -> 88013 | C34: =VLOOKUP(A34,ROSTER,3,0) -> 0 | D34: =VLOOKUP(A34,ROSTER,4,0) -> 0 | E34: =D34 & "_" & C34 -> 0_0 | F34: ='Team Info'!$B$8 -> VANDERBILT | G34: 1 | H34: =VLOOKUP(G34,$J$22:$K$23,2,0) -> ON
A35: 40 | B35: =B34+1 -> 88014 | C35: =VLOOKUP(A35,ROSTER,3,0) -> 0 | D35: =VLOOKUP(A35,ROSTER,4,0) -> 0 | E35: =D35 & "_" & C35 -> 0_0 | F35: ='Team Info'!$B$8 -> VANDERBILT | G35: 1 | H35: =VLOOKUP(G35,$J$22:$K$23,2,0) -> ON
A36: 85 | B36: =B35+1 -> 88015 | C36: =VLOOKUP(A36,ROSTER,3,0) -> 0 | D36: =VLOOKUP(A36,ROSTER,4,0) -> 0 | E36: =D36 & "_" & C36 -> 0_0 | F36: ='Team Info'!$B$8 -> VANDERBILT | G36: 1 | H36: =VLOOKUP(G36,$J$22:$K$23,2,0) -> ON
B37: AWAY TEAM - SAVE TO 86000s | E37: HOME TEAM - SAVE TO 87000s

Sheet LOGOS
A1: TEAM_LOGOS | C1: CONFERENCE_LOGOS | E1: NETWORK_LOGOS
A2: ABILENE_CHRISTIAN | C2: AMERICAN | E2: AAC_ESPN+_HORIZONTAL
A3: AIR_FORCE | C3: ATLANTIC_COAST | E3: AAC_ESPN+_HORIZONTALBLACK
A4: AKRON | C4: BIG_12 | E4: ABC
A5: ALABAMA | C5: BIG_SKY | E5: ABC_BLACK
A6: ALABAMA_AM | C6: BIG_SOUTH | E6: ACC_ESPN_NETWORK
A7: ALABAMA_ST | C7: BIG_TEN | E7: ACC_ESPN_NETWORK_BLACK
A8: ALCORN_ST | C8: CONFERENCE_USA | E8: ACC_NETWORK
A9: AMERICAN_UNIVERSITY | C9: GREAT_WEST | E9: ACC_NETWORK_BLACK
A10: APPALACHIAN_ST | C10: IVY_LEAGUE | E10: ACC_ON_ESPN
A11: ARIZONA | C11: MEAC | E11: BIG12_ESPN
A12: ARIZONA_ST | C12: MIDAMERICAN | E12: ESPN
... A22: BELMONT | C22: SWAC | E22: ESPNEWS
A23: BETHUNE_COOKMAN | E23: ESPNEWS_BLACK
A24: BOISE_ST | E24: ESPNU
A25: BOSTON_COLLEGE | E25: ESPNU_BLACK
A26: BOSTON_UNIVERSITY | E26: SEC_NETWORK.PNG
A27: BOWLING_GREEN | E27: SEC_NETWORK_BLACK.PNG
A28: BRADLEY
A29: BROWN | E29: AAC_ESPN+_HORIZONTALDARKGRAY
A30: BRYANT | E30: AAC_ESPN+_HORIZONTALLIGHTGRAY
A31: BUCKNELL | E31: AAC_ESPN+_HORIZONTALWHITE
A32: BUFFALO | E32: AAC_ESPN+_VERTICAL
A33: BYU | E33: AAC_ESPN+_VERTICALBLACK
A34: CALIFORNIA | E34: AAC_ESPN+_VERTICALDARKGRAY
A35: CALIFORNIA_BAPTIST | E35: AAC_ESPN+_VERTICALLIGHTGRAY
A36: CAL_POLY | E36: AAC_ESPN+_VERTICALWHITE
A37: CAL_ST_BAKERSFIELD | E37: ABC_ESPN_MIRROR_WHITE
A38: CAL_ST_FULLERTON | E38: AAC_ESPN+_WATERMARK
A39: CAL_ST_NORTHRIDGE | E39: AAC_ESPN_COBRAND
A40: CAMPBELL | E40: ABCAPPMIRROR
... A342: YOUNGSTOWN_ST | E342: SUNBELT_ESPN_DARKGRAY
E343: SUNBELT_ESPN_PRIMARY
E344: SUNBELT_ESPN_WHITE
E345: SUNBELT_GRAY
E346: SUNBELT_WHITE
E347: TBS
E348: TBS_BLACK
E349: TBS_BOXTRANSPARENT
E350: TBS_BOXWHITE
...
