Workbook
Name ACTIONSHOT: Roster!$S$3:$S$102
Name AGE: Roster!$O$3:$O$102
Name BIO_HEADER: Roster!$N$3:$N$4
Name CAT_1: 'Season Stats'!$D$1:$D$100
Name CAT_1_HILITE: 'Season Stats'!$E$1:$E$100
Name CAT_2: 'Season Stats'!$F$1:$F$100
Name CAT_2_HILITE: 'Season Stats'!$G$1:$G$100
Name CAT_3: 'Season Stats'!$H$1:$H$100
Name CAT_3_HILITE: 'Season Stats'!$I$1:$I$100
Name COACH_ASST_DROP: 'Team Personnel'!$G$13:$G$23
Name COACH_ASST_FIRST: 'Team Personnel'!$B$13:$B$23
Name COACH_ASST_FULL: 'Team Personnel'!$D$13:$D$23
Name COACH_ASST_HEADER: 'Team Personnel'!$E$13:$E$23
Name COACH_ASST_LAST: 'Team Personnel'!$C$13:$C$23
Name COACH_ASST_TEXT: 'Team Personnel'!$F$13:$F$23
Name COACH_DEF_FIRST: 'Team Personnel'!$B$24:$B$34
Name COACH_DEF_LAST: 'Team Personnel'!$C$24:$C$34
Name COACH_DEF_TEXT: 'Team Personnel'!$F$24:$F$34
Name COACH_HEAD_DROP: 'Team Personnel'!$G$2:$G$12
Name COACH_HEAD_FIRST: 'Team Personnel'!$B$2:$B$12
Name COACH_HEAD_FULL: 'Team Personnel'!$D$2:$D$12
Name COACH_HEAD_HEADER: 'Team Personnel'!$E$2:$E$12
Name COACH_HEAD_LAST: 'Team Personnel'!$C$2:$C$12
Name COACH_HEAD_TEXT: 'Team Personnel'!$F$2:$F$12
Name COACH_RESUME_DROP: 'Team Personnel'!$L$32:$L$33
Name COACH_RESUME_LINE1: 'Team Personnel'!$L$8:$L$9
Name COACH_RESUME_LINE2: 'Team Personnel'!$L$11:$L$12
Name COACH_RESUME_LINE3: 'Team Personnel'!$L$14:$L$15
Name COACH_RESUME_LINE4: 'Team Personnel'!$L$17:$L$18
Name COACH_RESUME_LINE5: 'Team Personnel'!$L$20:$L$21
Name COACH_RESUME_LINE6: 'Team Personnel'!$L$23:$L$24
Name COACH_RESUME_LINE7: 'Team Personnel'!$L$26:$L$27
Name COACH_RESUME_LINE8: 'Team Personnel'!$L$29:$L$30
Name COACH_RESUME_ROWS: 'Team Personnel'!$L$34:$L$35
Name COACH_RESUME_SUBTITLE: 'Team Personnel'!$L$5:$L$6
Name COACH_RESUME_TITLE: 'Team Personnel'!$L$2:$L$3
Name CONFERENCE_LOGOS: LOGOS!$C$1:$C$50
Name ESPN100: Roster!$M$3:$M$102
Name HEADER: Roster!$L$3:$L$102
Name HEADSHOT: Roster!$R$3:$R$102
Name HEIGHT: Roster!$F$3:$F$102
Name HERO_1_DROP: 'Player Heroes'!$J$2:$J$101
Name HERO_1_HEADER: 'Player Heroes'!$G$2:$G$101
Name HERO_1_INFO: 'Player Heroes'!$I$2:$I$101
Name HERO_2_DROP: 'Player Heroes'!$O$2:$O$101
Name HERO_2_HEADER: 'Player Heroes'!$L$2:$L$101
Name HERO_2_INFO: 'Player Heroes'!$N$2:$N$101
Name HERO_USER: 'Player Users'!$G$2:$G$101
Name HERO_USER2: 'Player Users'!$I$2:$I$101
Name HERO_USER3: 'Player Users'!$K$2:$K$101
Name HERO_USER4: 'Player Users'!$M$2:$M$101
Name HOMETOWN: Roster!$I$3:$I$102
Name JERSEY: Roster!$B$3:$B$102
Name MAJOR: Roster!$K$3:$K$102
Name NAME_FINIT: Roster!$U$3:$U$102
Name NAME_FIRST: Roster!$C$3:$C$102
Name NAME_FIRST_CAPS: Roster!$X$3:$X$102
Name NAME_FULL: Roster!$T$3:$T$102
Name NAME_FULL_CAPS: Roster!$W$3:$W$102
Name NAME_LAST: Roster!$D$3:$D$102

Sheet Team Info
A1: ESPN Team Sheet | B1: Updated 8/13/2024 | D1: TEAM INFO | F1: TODAY_TONIGHT_SEL | H1: SWATCH SEL
A2: TEAM INFO | B2: Home | D2: TEAM_RANK | F2: =$B$18 -> Tonight | H2: 0
A3: Team Rank | B3: 0 | D3: =$B$3 -> 0 | F3: =UPPER(F2) -> TONIGHT | H3: 1
A4: Team College | B4: College | H4: 2
A5: Team Nickname | B5: Nickname | D5: TEAM_CITY_COLLEGE | F5: SEASON_SEL | H5: 3
A6: Team Tricode | B6: TRI | D6: =$B$4 -> College | F6: =$B$19 -> Last Season
A7: Team Dashboard Name | B7: Dashname | D7: =UPPER(D6) -> COLLEGE | F7: =UPPER(F6) -> LAST SEASON | H7: TODAY/SEASON SEL
A8: Split Locator Name CAPS (LINE1|LINE2) | B8: TEAM|NAME | H8: Season
A9: Team Record (CAPS) | B9: X-X | D9: TEAM_NICKNAME | F9: TODAY_TONIGHT_SEL_COLON | H9: Last Season
D10: =$B$5 -> Nickname | F10: =$F$2&":" -> Tonight:
A11: TEAM LOGOS / SWATCH / HEADSHOTS | D11: =UPPER(D10) -> NICKNAME | H11: Today
A12: LOGO / SWATCH / HEADSHOT / ACTION | B12: AKRON | F12: SEASON_SEL_COLON | H12: Tonight
A13: Swatch Selector | B13: 0 | C13: =H16 -> LOGO | D13: TEAM_TRICODE | F13: =$F$6&":" -> Last Season:
A14: Dashboard Swatch Selector | B14: 0 | C14: =H21 -> LOGO | D14: =$B$6 -> TRI | H14: SWATCH_SELECT
A15: Headshots On/Off (0=Off, 1=On) | B15: 0 | C15: =F22 -> Off | H15: =B$13 -> 0
D16: TEAM_FULL_NAME | F16: AWAY/HOME SEL | H16: =IF(H15=1,"PRIMARY",IF(H15=2,"SECONDARY",IF(H15=3,"BOTTOMLINE",IF(H15=0,"LOGO")))) -> LOGO
A17: TODAY / SEASON SELECTION | D17: =B4&" "&B5 -> College Nickname | F17: Away
A18: Today / Tonight Selection | B18: Tonight | D18: =UPPER(D17) -> COLLEGE NICKNAME | F18: Home
A19: Season / Last Season | B19: Last Season | H19: DASH_SWATCH_SELECT
D20: TEAM_DASH_NAME | F20: HEADSHOT_ONOFF | H20: =$B$14 -> 0
A21: Note: Fill out information in BLUE cells only and select Away/Home in cell B2 | D21: =$B$7 -> Dashname | F21: =$B$15 -> 0 | H21: =IF(H20=1,"PRIMARY",IF(H20=2,"SECONDARY",IF(H20=3,"BOTTOMLINE",IF(H20=0,"LOGO")))) -> LOGO
F22: =IF(F21=1,"On","Off") -> Off
D23: TEAM_RANK_NAME
D24: =D3&" "&D6 -> 0 College | F24: On/Off
D25: =UPPER(D24) -> 0 COLLEGE | F25: 0
F26: 1
D27: TEAM_RANK_NAME_NICKNAME
D28: =D3&" "&D6&" "&D10 -> 0 College Nickname
D29: =UPPER(D28) -> 0 COLLEGE NICKNAME
D31: TEAM_RANK_NAME_RECORD
D32: =D3&" "&D6&" "& "(" & D39 &")" -> 0 College (X-X)
D33: =UPPER(D32) -> 0 COLLEGE (X-X)
D35: TEAM_LOGOTEXT
D36: =$B$12 -> AKRON
D38: TEAM_RECORD_OVERALL
D39: =B9 -> X-X
D41: TEAM_SPLIT
D42: =B8 -> TEAM|NAME

Sheet Team Personnel
A1: Away: 179-199; Home 279-299 | B1: Upper / Lower | C1: Upper / Lower | E1: CAPS | F1: Upper / Lower | G1: Upper/Lower (if needed) | J1: ROWS
A2: Save # | B2: First Name | C2: Last Name | D2: Full Name | E2: Header | F2: Line 1 Text | G2: Dropline Text | J2: 2 | L2: COACH_RESUME_TITLE
A3: =IF('Team Info'!$B$2 = "Away",180,280) -> 280 | B3: Jason | C3: Kennedy | D3: =$B3 & " " & $C3 -> Jason Kennedy | F3: Boston College Head Coach | G3: Sticker only - no dropline | J3: 3 | L3: =B38 -> Jason Kennedy
A4: =A3+1 -> 281 | B4: =$B$3 -> Jason | C4: =$C$3 -> Kennedy | D4: =$B4 & " " & $C4 -> Jason Kennedy | J4: 4
A5: =A3+2 -> 282 | B5: =$B$3 -> Jason | C5: =$C$3 -> Kennedy | D5: =$B5 & " " & $C5 -> Jason Kennedy | J5: 5 | L5: COACH_RESUME_SUBTITLE
A6: =A3+3 -> 283 | B6: =$B$3 -> Jason | C6: =$C$3 -> Kennedy | D6: =$B6 & " " & $C6 -> Jason Kennedy | J6: 6 | L6: =B39 -> Head Coaching Résumé
A7: =A3+4 -> 284 | B7: =$B$3 -> Jason | C7: =$C$3 -> Kennedy | D7: =$B7 & " " & $C7 -> Jason Kennedy | J7: 7
A8: =A3+5 -> 285 | B8: =$B$3 -> Jason | C8: =$C$3 -> Kennedy | D8: =$B8 & " " & $C8 -> Jason Kennedy | J8: 8 | L8: COACH_RESUME_LINE1
A9: =A3+6 -> 286 | B9: =$B$3 -> Jason | C9: =$C$3 -> Kennedy | D9: =$B9 & " " & $C9 -> Jason Kennedy | L9: =B43 -> Line1 text
A10: =A3+7 -> 287 | B10: =$B$3 -> Jason | C10: =$C$3 -> Kennedy | D10: =$B10 & " " & $C10 -> Jason Kennedy
A11: =A3+8 -> 288 | B11: =$B$3 -> Jason | C11: =$C$3 -> Kennedy | D11: =$B11 & " " & $C11 -> Jason Kennedy | L11: COACH_RESUME_LINE2
A12: =A3+9 -> 289 | B12: =$B$3 -> Jason | C12: =$C$3 -> Kennedy | D12: =$B12 & " " & $C12 -> Jason Kennedy | L12: =B44 -> Line2 text
A13: Save # | B13: First Name | C13: Last Name | D13: Full Name | E13: Header | F13: Line 1 Text | G13: Dropline Text | H13: Do not delete COLUMNS. Do not Delete rows above here.
A14: =IF('Team Info'!$B$2 = "Away",190,290) -> 290 | B14: Marissa | C14: Prinzbach | D14: =$B14 & " " & $C14 -> Marissa Prinzbach | F14: Associate Head Coach | L14: COACH_RESUME_LINE3
A15: =A14+1 -> 291 | B15: Kin | C15: Yun | D15: =$B15 & " " & $C15 -> Kin Yun | F15: Assistant Coach | L15: =B45 -> Line3 text
A16: =A14+2 -> 292 | B16: Ted | C16: Hurley | D16: =$B16 & " " & $C16 -> Ted Hurley | F16: Volunteer Assistant Coach
A17: =A14+3 -> 293 | B17: First | C17: Last | D17: =$B17 & " " & $C17 -> First Last | L17: COACH_RESUME_LINE4
A18: =A14+4 -> 294 | B18: First | C18: Last | D18: =$B18 & " " & $C18 -> First Last | L18: =B46 -> Line4 text
A19: =A14+5 -> 295 | B19: First | C19: Last | D19: =$B19 & " " & $C19 -> First Last
A20: =A14+6 -> 296 | B20: First | C20: Last | D20: =$B20 & " " & $C20 -> First Last | L20: COACH_RESUME_LINE5
A21: =A14+7 -> 297 | B21: First | C21: Last | D21: =$B21 & " " & $C21 -> First Last | L21: =B47 -> Line5 text
A22: =A14+8 -> 298 | B22: First | C22: Last | D22: =$B22 & " " & $C22 -> First Last
A23: =A14+9 -> 299 | B23: First | C23: Last | D23: =$B23 & " " & $C23 -> First Last | L23: COACH_RESUME_LINE6
A24: Save # | B24: First Name CAPS | C24: Last Name CAPS | F24: Line 1 Text (Upper/Lower) | G24: Stickers only | L24: =B48 -> Line6 text
A25: =IF('Team Info'!$B$2 = "Away",190,290) -> 290 | B25: MIKE | C25: STOOPS | F25: Defensive Coordinator
A26: =A25+1 -> 291 | B26: RUFFIN | C26: McNEIL | F26: Assistant Head Coach/Defensive Tackles Coach | L26: COACH_RESUME_LINE7
A27: =A25+2 -> 292 | B27: DEF. COACH | C27: DEF. COACH | L27: =B49 -> Line7 text
A28: =A25+3 -> 293 | B28: DEF. COACH | C28: DEF. COACH
A29: =A25+4 -> 294 | B29: DEF. COACH | C29: DEF. COACH | L29: COACH_RESUME_LINE8
A30: =A25+5 -> 295 | B30: DEF. COACH | C30: DEF. COACH | L30: =B50 -> Line8 text
A31: =A25+6 -> 296 | B31: DEF. COACH | C31: DEF. COACH
A32: =A25+7 -> 297 | B32: DEF. COACH | C32: DEF. COACH | L32: COACH_RESUME_DROP
A33: =A25+8 -> 298 | B33: DEF. COACH | C33: DEF. COACH | L33: =B51
A34: =A25+9 -> 299 | B34: DEF. COACH | C34: DEF. COACH | L34: COACH_RESUME_ROWS
A35: ** MAKE SURE YOU SELECT AWAY OR HOME ON THE TEAM INFO TAB (CELL B2) ** | L35: =B37 -> 4
A36: Coach Resume: | B36: =IF('Team Info'!$B$2 = "Away",179,279) -> 279
A37: Number of Lines (2-8): | B37: 4 | E37: Head Coach: Fill in first/last name in cells B3/C3. This will copy to the remaining head coach shells.
A38: Title | B38: =D3 -> Jason Kennedy
A39: Subtitle | B39: Head Coaching Résumé
A40: Column Header (0=Off, 1=On) | B40: 0
...

Sheet Roster
A1: Roster | B1: BIOS: 11xx Away, 21xx Home | I1: Choose Header or Major in Cell K3 | K1: ACCN & SECN Teams = Major
E2: OPP/OH/MB/S/L | H2: Date calc - enter as xx/xx/xx | J2: 1=FR, 2=SO, 3=JR, 4=SR | K2: ALL CAPS | M2: Optional
A3: Jersey | B3: Display | C3: First Name | D3: Last Name | E3: POS | F3: Height | G3: Weight | H3: Birthday | I3: Hometown | J3: Year | K3: Major | L3: Bio Dropline | M3: ESPN 100 Rank | N3: HEADER | O3: Age | P3: Position | Q3: Year | R3: Headshot | S3: Actionshot | T3: Full Name | U3: Initial Name | V3: Year | W3: Full Name CAPS | X3: First Name CAPS | Y3: Last Name CAPS | Z3: Year CAPS | AA3: Last Jersey | AB3: Last Jersey CAPS
A4: 1 | B4: 1 | C4: Grace | D4: Penn | E4: S | F4: 5'10" | I4: Manhattan Beach, CA | J4: 3 | N4: =IF(K3="Header", 0, 1) -> 1 | O4: =INT(YEARFRAC($H4, TODAY())) -> 124 | P4: =IF($E4="OPP","Opposite",IF($E4="OH","Outside Hitter",IF($E4="MB","Middle Blocker",IF($E4="S","Setter",IF($E4="L","Libero",""))))) -> Setter | Q4: =IF($J4=4,"Senior",IF($J4=3,"Junior",IF($J4=2,"Sophomore",IF($J4=1,"Freshman","")))) -> Junior | R4: ="D:\IMS Images\Headshots\VB\"&'Team Info'!$B$12&"\"&D4&"_"&C4&".png" -> D:\IMS Images\Headshots\VB\AKRON\Penn_Grace.png | S4: ="D:\IMS Images\ActionShots\VB\"&'Team Info'!$B$12&"\"&D4&"_"&C4&".png" -> D:\IMS Images\ActionShots\VB\AKRON\Penn_Grace.png | T4: =C4&" "&D4 -> Grace Penn | U4: =LEFT(C4,1)&". "&D4 -> G. Penn | V4: =IF($J4=4,"SR",IF($J4=3,"JR",IF($J4=2,"SO",IF($J4=1,"FR","")))) -> JR | W4: =UPPER(T4) -> GRACE PENN | X4: =UPPER(C4) -> GRACE | Y4: =UPPER(D4) -> PENN | Z4: =UPPER(Q4) -> JUNIOR | AA4: =B4 & " " &D4 -> 1 Penn | AB4: =UPPER(AA4) -> 1 PENN
A5: 2 | B5: 2 | C5: Silvia | D5: Ianeselli | E5: OH | F5: 6'1" | I5: Trento, Italy | J5: 4 | O5: =INT(YEARFRAC($H5, TODAY())) -> 124 | P5: =IF($E5="OPP","Opposite",IF($E5="OH","Outside Hitter",IF($E5="MB","Middle Blocker",IF($E5="S","Setter",IF($E5="L","Libero",""))))) -> Outside Hitter | Q5: =IF($J5=4,"Senior",IF($J5=3,"Junior",IF($J5=2,"Sophomore",IF($J5=1,"Freshman","")))) -> Senior | R5: ="D:\IMS Images\Headshots\VB\"&'Team Info'!$B$12&"\"&D5&"_"&C5&".png" -> D:\IMS Images\Headshots\VB\AKRON\Ianeselli_Silvia.png | S5: ="D:\IMS Images\ActionShots\VB\"&'Team Info'!$B$12&"\"&D5&"_"&C5&".png" -> D:\IMS Images\ActionShots\VB\AKRON\Ianeselli_Silvia.png | T5: =C5&" "&D5 -> Silvia Ianeselli | U5: =LEFT(C5,1)&". "&D5 -> S. Ianeselli | V5: =IF($J5=4,"SR",IF($J5=3,"JR",IF($J5=2,"SO",IF($J5=1,"FR","")))) -> SR | W5: =UPPER(T5) -> SILVIA IANESELLI | X5: =UPPER(C5) -> SILVIA | Y5: =UPPER(D5) -> IANESELLI | Z5: =UPPER(Q5) -> SENIOR | AA5: =B5 & " " &D5 -> 2 Ianeselli | AB5: =UPPER(AA5) -> 2 IANESELLI
A6: 3 | B6: 3 | O6: =INT(YEARFRAC($H6, TODAY())) -> 124 | P6: =IF($E6="OPP","Opposite",IF($E6="OH","Outside Hitter",IF($E6="MB","Middle Blocker",IF($E6="S","Setter",IF($E6="L","Libero",""))))) | Q6: =IF($J6=4,"Senior",IF($J6=3,"Junior",IF($J6=2,"Sophomore",IF($J6=1,"Freshman","")))) | R6: ="D:\IMS Images\Headshots\VB\"&'Team Info'!$B$12&"\"&D6&"_"&C6&".png" -> D:\IMS Images\Headshots\VB\AKRON\_.png | S6: ="D:\IMS Images\ActionShots\VB\"&'Team Info'!$B$12&"\"&D6&"_"&C6&".png" -> D:\IMS Images\ActionShots\VB\AKRON\_.png | T6: =C6&" "&D6 | U6: =LEFT(C6,1)&". "&D6 -> . | V6: =IF($J6=4,"SR",IF($J6=3,"JR",IF($J6=2,"SO",IF($J6=1,"FR","")))) | W6: =UPPER(T6) | X6: =UPPER(C6) | Y6: =UPPER(D6) | Z6: =UPPER(Q6) | AA6: =B6 & " " &D6 -> 3 | AB6: =UPPER(AA6) -> 3
A7: 4 | B7: 4 | C7: Anna | D7: Murphy | E7: L | F7: 5'6" | I7: Zionsville, CA | J7: 3 | N7: HDR_SEL | O7: =INT(YEARFRAC($H7, TODAY())) -> 124 | P7: =IF($E7="OPP","Opposite",IF($E7="OH","Outside Hitter",IF($E7="MB","Middle Blocker",IF($E7="S","Setter",IF($E7="L","Libero",""))))) -> Libero | Q7: =IF($J7=4,"Senior",IF($J7=3,"Junior",IF($J7=2,"Sophomore",IF($J7=1,"Freshman","")))) -> Junior | R7: ="D:\IMS Images\Headshots\VB\"&'Team Info'!$B$12&"\"&D7&"_"&C7&".png" -> D:\IMS Images\Headshots\VB\AKRON\Murphy_Anna.png | S7: ="D:\IMS Images\ActionShots\VB\"&'Team Info'!$B$12&"\"&D7&"_"&C7&".png" -> D:\IMS Images\ActionShots\VB\AKRON\Murphy_Anna.png | T7: =C7&" "&D7 -> Anna Murphy | U7: =LEFT(C7,1)&". "&D7 -> A. Murphy | V7: =IF($J7=4,"SR",IF($J7=3,"JR",IF($J7=2,"SO",IF($J7=1,"FR","")))) -> JR | W7: =UPPER(T7) -> ANNA MURPHY | X7: =UPPER(C7) -> ANNA | Y7: =UPPER(D7) -> MURPHY | Z7: =UPPER(Q7) -> JUNIOR | AA7: =B7 & " " &D7 -> 4 Murphy | AB7: =UPPER(AA7) -> 4 MURPHY
A8: 5 | B8: 5 | C8: Sophia | D8: Lambros | E8: S | F8: 6'0" | I8: Fullerton, CA | J8: 3 | N8: Header | O8: =INT(YEARFRAC($H8, TODAY())) -> 124 | P8: =IF($E8="OPP","Opposite",IF($E8="OH","Outside Hitter",IF($E8="MB","Middle Blocker",IF($E8="S","Setter",IF($E8="L","Libero",""))))) -> Setter | Q8: =IF($J8=4,"Senior",IF($J8=3,"Junior",IF($J8=2,"Sophomore",IF($J8=1,"Freshman","")))) -> Junior | R8: ="D:\IMS Images\Headshots\VB\"&'Team Info'!$B$12&"\"&D8&"_"&C8&".png" -> D:\IMS Images\Headshots\VB\AKRON\Lambros_Sophia.png | S8: ="D:\IMS Images\ActionShots\VB\"&'Team Info'!$B$12&"\"&D8&"_"&C8&".png" -> D:\IMS Images\ActionShots\VB\AKRON\Lambros_Sophia.png | T8: =C8&" "&D8 -> Sophia Lambros | U8: =LEFT(C8,1)&". "&D8 -> S. Lambros | V8: =IF($J8=4,"SR",IF($J8=3,"JR",IF($J8=2,"SO",IF($J8=1,"FR","")))) -> JR | W8: =UPPER(T8) -> SOPHIA LAMBROS | X8: =UPPER(C8) -> SOPHIA | Y8: =UPPER(D8) -> LAMBROS | Z8: =UPPER(Q8) -> JUNIOR | AA8: =B8 & " " &D8 -> 5 Lambros | AB8: =UPPER(AA8) -> 5 LAMBROS
A9: 6 | B9: 6 | C9: Jenna | D9: Pollock | E9: MB/OPP | F9: 5'2" | I9: St. Catherines, Ontario | J9: 2 | N9: Major | O9: =INT(YEARFRAC($H9, TODAY())) -> 124 | P9: =IF($E9="OPP","Opposite",IF($E9="OH","Outside Hitter",IF($E9="MB","Middle Blocker",IF($E9="S","Setter",IF($E9="L","Libero",""))))) | Q9: =IF($J9=4,"Senior",IF($J9=3,"Junior",IF($J9=2,"Sophomore",IF($J9=1,"Freshman","")))) -> Sophomore | R9: ="D:\IMS Images\Headshots\VB\"&'Team Info'!$B$12&"\"&D9&"_"&C9&".png" -> D:\IMS Images\Headshots\VB\AKRON\Pollock_Jenna.png | S9: ="D:\IMS Images\ActionShots\VB\"&'Team Info'!$B$12&"\"&D9&"_"&C9&".png" -> D:\IMS Images\ActionShots\VB\AKRON\Pollock_Jenna.png | T9: =C9&" "&D9 -> Jenna Pollock | U9: =LEFT(C9,1)&". "&D9 -> J. Pollock | V9: =IF($J9=4,"SR",IF($J9=3,"JR",IF($J9=2,"SO",IF($J9=1,"FR","")))) -> SO | W9: =UPPER(T9) -> JENNA POLLOCK | X9: =UPPER(C9) -> JENNA | Y9: =UPPER(D9) -> POLLOCK | Z9: =UPPER(Q9) -> SOPHOMORE | AA9: =B9 & " " &D9 -> 6 Pollock | AB9: =UPPER(AA9) -> 6 POLLOCK
A10: 7 | B10: 7 | O10: =INT(YEARFRAC($H10, TODAY())) -> 124 | P10: =IF($E10="OPP","Opposite",IF($E10="OH","Outside Hitter",IF($E10="MB","Middle Blocker",IF($E10="S","Setter",IF($E10="L","Libero",""))))) | Q10: =IF($J10=4,"Senior",IF($J10=3,"Junior",IF($J10=2,"Sophomore",IF($J10=1,"Freshman","")))) | R10: ="D:\IMS Images\Headshots\VB\"&'Team Info'!$B$12&"\"&D10&"_"&C10&".png" -> D:\IMS Images\Headshots\VB\AKRON\_.png | S10: ="D:\IMS Images\ActionShots\VB\"&'Team Info'!$B$12&"\"&D10&"_"&C10&".png" -> D:\IMS Images\ActionShots\VB\AKRON\_.png | T10: =C10&" "&D10 | U10: =LEFT(C10,1)&". "&D10 -> . | V10: =IF($J10=4,"SR",IF($J10=3,"JR",IF($J10=2,"SO",IF($J10=1,"FR","")))) | W10: =UPPER(T10) | X10: =UPPER(C10) | Y10: =UPPER(D10) | Z10: =UPPER(Q10) | AA10: =B10 & " " &D10 -> 7 | AB10: =UPPER(AA10) -> 7
A11: 8 | B11: 8 | O11: =INT(YEARFRAC($H11, TODAY())) -> 124 | P11: =IF($E11="OPP","Opposite",IF($E11="OH","Outside Hitter",IF($E11="MB","Middle Blocker",IF($E11="S","Setter",IF($E11="L","Libero",""))))) | Q11: =IF($J11=4,"Senior",IF($J11=3,"Junior",IF($J11=2,"Sophomore",IF($J11=1,"Freshman","")))) | R11: ="D:\IMS Images\Headshots\VB\"&'Team Info'!$B$12&"\"&D11&"_"&C11&".png" -> D:\IMS Images\Headshots\VB\AKRON\_.png | S11: ="D:\IMS Images\ActionShots\VB\"&'Team Info'!$B$12&"\"&D11&"_"&C11&".png" -> D:\IMS Images\ActionShots\VB\AKRON\_.png | T11: =C11&" "&D11 | U11: =LEFT(C11,1)&". "&D11 -> . | V11: =IF($J11=4,"SR",IF($J11=3,"JR",IF($J11=2,"SO",IF($J11=1,"FR","")))) | W11: =UPPER(T11) | X11: =UPPER(C11) | Y11: =UPPER(D11) | Z11: =UPPER(Q11) | AA11: =B11 & " " &D11 -> 8 | AB11: =UPPER(AA11) -> 8
A12: 9 | B12: 9 | C12: Katrina | D12: Jensen | E12: OH | F12: 6'1" | I12: Temecula, CA | J12: 3 | O12: =INT(YEARFRAC($H12, TODAY())) -> 124 | P12: =IF($E12="OPP","Opposite",IF($E12="OH","Outside Hitter",IF($E12="MB","Middle Blocker",IF($E12="S","Setter",IF($E12="L","Libero",""))))) -> Outside Hitter | Q12: =IF($J12=4,"Senior",IF($J12=3,"Junior",IF($J12=2,"Sophomore",IF($J12=1,"Freshman","")))) -> Junior | R12: ="D:\IMS Images\Headshots\VB\"&'Team Info'!$B$12&"\"&D12&"_"&C12&".png" -> D:\IMS Images\Headshots\VB\AKRON\Jensen_Katrina.png | S12: ="D:\IMS Images\ActionShots\VB\"&'Team Info'!$B$12&"\"&D12&"_"&C12&".png" -> D:\IMS Images\ActionShots\VB\AKRON\Jensen_Katrina.png | T12: =C12&" "&D12 -> Katrina Jensen | U12: =LEFT(C12,1)&". "&D12 -> K. Jensen | V12: =IF($J12=4,"SR",IF($J12=3,"JR",IF($J12=2,"SO",IF($J12=1,"FR","")))) -> JR | W12: =UPPER(T12) -> KATRINA JENSEN | X12: =UPPER(C12) -> KATRINA | Y12: =UPPER(D12) -> JENSEN | Z12: =UPPER(Q12) -> JUNIOR | AA12: =B12 & " " &D12 -> 9 Jensen | AB12: =UPPER(AA12) -> 9 JENSEN
A13: 10 | B13: 10 | C13: Peyton | D13: Minyard | E13: MB | F13: 6'2" | I13: Coppell, TX | J13: 3 | O13: =INT(YEARFRAC($H13, TODAY())) -> 124 | P13: =IF($E13="OPP","Opposite",IF($E13="OH","Outside Hitter",IF($E13="MB","Middle Blocker",IF($E13="S","Setter",IF($E13="L","Libero",""))))) -> Middle Blocker | Q13: =IF($J13=4,"Senior",IF($J13=3,"Junior",IF($J13=2,"Sophomore",IF($J13=1,"Freshman","")))) -> Junior | R13: ="D:\IMS Images\Headshots\VB\"&'Team Info'!$B$12&"\"&D13&"_"&C13&".png" -> D:\IMS Images\Headshots\VB\AKRON\Minyard_Peyton.png | S13: ="D:\IMS Images\ActionShots\VB\"&'Team Info'!$B$12&"\"&D13&"_"&C13&".png" -> D:\IMS Images\ActionShots\VB\AKRON\Minyard_Peyton.png | T13: =C13&" "&D13 -> Peyton Minyard | U13: =LEFT(C13,1)&". "&D13 -> P. Minyard | V13: =IF($J13=4,"SR",IF($J13=3,"JR",IF($J13=2,"SO",IF($J13=1,"FR","")))) -> JR | W13: =UPPER(T13) -> PEYTON MINYARD | X13: =UPPER(C13) -> PEYTON | Y13: =UPPER(D13) -> MINYARD | Z13: =UPPER(Q13) -> JUNIOR | AA13: =B13 & " " &D13 -> 10 Minyard | AB13: =UPPER(AA13) -> 10 MINYARD
A14: 11 | B14: 11 | C14: Alayna | D14: Crabtree | E14: OH | F14: 6'2" | I14: Normal, IL | J14: 3 | O14: =INT(YEARFRAC($H14, TODAY())) -> 124 | P14: =IF($E14="OPP","Opposite",IF($E14="OH","Outside Hitter",IF($E14="MB","Middle Blocker",IF($E14="S","Setter",IF($E14="L","Libero",""))))) -> Outside Hitter | Q14: =IF($J14=4,"Senior",IF($J14=3,"Junior",IF($J14=2,"Sophomore",IF($J14=1,"Freshman","")))) -> Junior | R14: ="D:\IMS Images\Headshots\VB\"&'Team Info'!$B$12&"\"&D14&"_"&C14&".png" -> D:\IMS Images\Headshots\VB\AKRON\Crabtree_Alayna.png | S14: ="D:\IMS Images\ActionShots\VB\"&'Team Info'!$B$12&"\"&D14&"_"&C14&".png" -> D:\IMS Images\ActionShots\VB\AKRON\Crabtree_Alayna.png | T14: =C14&" "&D14 -> Alayna Crabtree | U14: =LEFT(C14,1)&". "&D14 -> A. Crabtree | V14: =IF($J14=4,"SR",IF($J14=3,"JR",IF($J14=2,"SO",IF($J14=1,"FR","")))) -> JR | W14: =UPPER(T14) -> ALAYNA CRABTREE | X14: =UPPER(C14) -> ALAYNA | Y14: =UPPER(D14) -> CRABTREE | Z14: =UPPER(Q14) -> JUNIOR | AA14: =B14 & " " &D14 -> 11 Crabtree | AB14: =UPPER(AA14) -> 11 CRABTREE
A15: 12 | B15: 12 | C15: Izzy | D15: Clavenna | E15: S | F15: 6'2" | I15: Dallas, TX | J15: 4 | O15: =INT(YEARFRAC($H15, TODAY())) -> 124 | P15: =IF($E15="OPP","Opposite",IF($E15="OH","Outside Hitter",IF($E15="MB","Middle Blocker",IF($E15="S","Setter",IF($E15="L","Libero",""))))) -> Setter | Q15: =IF($J15=4,"Senior",IF($J15=3,"Junior",IF($J15=2,"Sophomore",IF($J15=1,"Freshman","")))) -> Senior | R15: ="D:\IMS Images\Headshots\VB\"&'Team Info'!$B$12&"\"&D15&"_"&C15&".png" -> D:\IMS Images\Headshots\VB\AKRON\Clavenna_Izzy.png | S15: ="D:\IMS Images\ActionShots\VB\"&'Team Info'!$B$12&"\"&D15&"_"&C15&".png" -> D:\IMS Images\ActionShots\VB\AKRON\Clavenna_Izzy.png | T15: =C15&" "&D15 -> Izzy Clavenna | U15: =LEFT(C15,1)&". "&D15 -> I. Clavenna | V15: =IF($J15=4,"SR",IF($J15=3,"JR",IF($J15=2,"SO",IF($J15=1,"FR","")))) -> SR | W15: =UPPER(T15) -> IZZY CLAVENNA | X15: =UPPER(C15) -> IZZY | Y15: =UPPER(D15) -> CLAVENNA | Z15: =UPPER(Q15) -> SENIOR | AA15: =B15 & " " &D15 -> 12 Clavenna | AB15: =UPPER(AA15) -> 12 CLAVENNA
A16: 13 | B16: 13 | O16: =INT(YEARFRAC($H16, TODAY())) -> 124 | P16: =IF($E16="OPP","Opposite",IF($E16="OH","Outside Hitter",IF($E16="MB","Middle Blocker",IF($E16="S","Setter",IF($E16="L","Libero",""))))) | Q16: =IF($J16=4,"Senior",IF($J16=3,"Junior",IF($J16=2,"Sophomore",IF($J16=1,"Freshman","")))) | R16: ="D:\IMS Images\Headshots\VB\"&'Team Info'!$B$12&"\"&D16&"_"&C16&".png" -> D:\IMS Images\Headshots\VB\AKRON\_.png | S16: ="D:\IMS Images\ActionShots\VB\"&'Team Info'!$B$12&"\"&D16&"_"&C16&".png" -> D:\IMS Images\ActionShots\VB\AKRON\_.png | T16: =C16&" "&D16 | U16: =LEFT(C16,1)&". "&D16 -> . | V16: =IF($J16=4,"SR",IF($J16=3,"JR",IF($J16=2,"SO",IF($J16=1,"FR","")))) | W16: =UPPER(T16) | X16: =UPPER(C16) | Y16: =UPPER(D16) | Z16: =UPPER(Q16) | AA16: =B16 & " " &D16 -> 13 | AB16: =UPPER(AA16) -> 13
A17: 14 | B17: 14 | O17: =INT(YEARFRAC($H17, TODAY())) -> 124 | P17: =IF($E17="OPP","Opposite",IF($E17="OH","Outside Hitter",IF($E17="MB","Middle Blocker",IF($E17="S","Setter",IF($E17="L","Libero",""))))) | Q17: =IF($J17=4,"Senior",IF($J17=3,"Junior",IF($J17=2,"Sophomore",IF($J17=1,"Freshman","")))) | R17: ="D:\IMS Images\Headshots\VB\"&'Team Info'!$B$12&"\"&D17&"_"&C17&".png" -> D:\IMS Images\Headshots\VB\AKRON\_.png | S17: ="D:\IMS Images\ActionShots\VB\"&'Team Info'!$B$12&"\"&D17&"_"&C17&".png" -> D:\IMS Images\ActionShots\VB\AKRON\_.png | T17: =C17&" "&D17 | U17: =LEFT(C17,1)&". "&D17 -> . | V17: =IF($J17=4,"SR",IF($J17=3,"JR",IF($J17=2,"SO",IF($J17=1,"FR","")))) | W17: =UPPER(T17) | X17: =UPPER(C17) | Y17: =UPPER(D17) | Z17: =UPPER(Q17) | AA17: =B17 & " " &D17 -> 14 | AB17: =UPPER(AA17) -> 14
A18: 15 | B18: 15 | O18: =INT(YEARFRAC($H18, TODAY())) -> 124 | P18: =IF($E18="OPP","Opposite",IF($E18="OH","Outside Hitter",IF($E18="MB","Middle Blocker",IF($E18="S","Setter",IF($E18="L","Libero",""))))) | Q18: =IF($J18=4,"Senior",IF($J18=3,"Junior",IF($J18=2,"Sophomore",IF($J18=1,"Freshman","")))) | R18: ="D:\IMS Images\Headshots\VB\"&'Team Info'!$B$12&"\"&D18&"_"&C18&".png" -> D:\IMS Images\Headshots\VB\AKRON\_.png | S18: ="D:\IMS Images\ActionShots\VB\"&'Team Info'!$B$12&"\"&D18&"_"&C18&".png" -> D:\IMS Images\ActionShots\VB\AKRON\_.png | T18: =C18&" "&D18 | U18: =LEFT(C18,1)&". "&D18 -> . | V18: =IF($J18=4,"SR",IF($J18=3,"JR",IF($J18=2,"SO",IF($J18=1,"FR","")))) | W18: =UPPER(T18) | X18: =UPPER(C18) | Y18: =UPPER(D18) | Z18: =UPPER(Q18) | AA18: =B18 & " " &D18 -> 15 | AB18: =UPPER(AA18) -> 15
A19: 16 | B19: 16 | O19: =INT(YEARFRAC($H19, TODAY())) -> 124 | P19: =IF($E19="OPP","Opposite",IF($E19="OH","Outside Hitter",IF($E19="MB","Middle Blocker",IF($E19="S","Setter",IF($E19="L","Libero",""))))) | Q19: =IF($J19=4,"Senior",IF($J19=3,"Junior",IF($J19=2,"Sophomore",IF($J19=1,"Freshman","")))) | R19: ="D:\IMS Images\Headshots\VB\"&'Team Info'!$B$12&"\"&D19&"_"&C19&".png" -> D:\IMS Images\Headshots\VB\AKRON\_.png | S19: ="D:\IMS Images\ActionShots\VB\"&'Team Info'!$B$12&"\"&D19&"_"&C19&".png" -> D:\IMS Images\ActionShots\VB\AKRON\_.png | T19: =C19&" "&D19 | U19: =LEFT(C19,1)&". "&D19 -> . | V19: =IF($J19=4,"SR",IF($J19=3,"JR",IF($J19=2,"SO",IF($J19=1,"FR","")))) | W19: =UPPER(T19) | X19: =UPPER(C19) | Y19: =UPPER(D19) | Z19: =UPPER(Q19) | AA19: =B19 & " " &D19 -> 16 | AB19: =UPPER(AA19) -> 16
A20: 17 | B20: 17 | C20: Cornelia | D20: Roach | E20: MB | F20: 6'2" | I20: Greenwich, CT | J20: 2 | O20: =INT(YEARFRAC($H20, TODAY())) -> 124 | P20: =IF($E20="OPP","Opposite",IF($E20="OH","Outside Hitter",IF($E20="MB","Middle Blocker",IF($E20="S","Setter",IF($E20="L","Libero",""))))) -> Middle Blocker | Q20: =IF($J20=4,"Senior",IF($J20=3,"Junior",IF($J20=2,"Sophomore",IF($J20=1,"Freshman","")))) -> Sophomore | R20: ="D:\IMS Images\Headshots\VB\"&'Team Info'!$B$12&"\"&D20&"_"&C20&".png" -> D:\IMS Images\Headshots\VB\AKRON\Roach_Cornelia.png | S20: ="D:\IMS Images\ActionShots\VB\"&'Team Info'!$B$12&"\"&D20&"_"&C20&".png" -> D:\IMS Images\ActionShots\VB\AKRON\Roach_Cornelia.png | T20: =C20&" "&D20 -> Cornelia Roach | U20: =LEFT(C20,1)&". "&D20 -> C. Roach | V20: =IF($J20=4,"SR",IF($J20=3,"JR",IF($J20=2,"SO",IF($J20=1,"FR","")))) -> SO | W20: =UPPER(T20) -> CORNELIA ROACH | X20: =UPPER(C20) -> CORNELIA | Y20: =UPPER(D20) -> ROACH | Z20: =UPPER(Q20) -> SOPHOMORE | AA20: =B20 & " " &D20 -> 17 Roach | AB20: =UPPER(AA20) -> 17 ROACH
A21: 18 | B21: 18 | C21: Bridget | D21: Green | E21: L | F21: 5'8" | I21: New York, NY | J21: 3 | O21: =INT(YEARFRAC($H21, TODAY())) -> 124 | P21: =IF($E21="OPP","Opposite",IF($E21="OH","Outside Hitter",IF($E21="MB","Middle Blocker",IF($E21="S","Setter",IF($E21="L","Libero",""))))) -> Libero | Q21: =IF($J21=4,"Senior",IF($J21=3,"Junior",IF($J21=2,"Sophomore",IF($J21=1,"Freshman","")))) -> Junior | R21: ="D:\IMS Images\Headshots\VB\"&'Team Info'!$B$12&"\"&D21&"_"&C21&".png" -> D:\IMS Images\Headshots\VB\AKRON\Green_Bridget.png | S21: ="D:\IMS Images\ActionShots\VB\"&'Team Info'!$B$12&"\"&D21&"_"&C21&".png" -> D:\IMS Images\ActionShots\VB\AKRON\Green_Bridget.png | T21: =C21&" "&D21 -> Bridget Green | U21: =LEFT(C21,1)&". "&D21 -> B. Green | V21: =IF($J21=4,"SR",IF($J21=3,"JR",IF($J21=2,"SO",IF($J21=1,"FR","")))) -> JR | W21: =UPPER(T21) -> BRIDGET GREEN | X21: =UPPER(C21) -> BRIDGET | Y21: =UPPER(D21) -> GREEN | Z21: =UPPER(Q21) -> JUNIOR | AA21: =B21 & " " &D21 -> 18 Green | AB21: =UPPER(AA21) -> 18 GREEN
A22: 19 | B22: 19 | C22: Jane | D22: Petrie | E22: S | F22: 5'8" | I22: San Diego, CA | J22: 2 | O22: =INT(YEARFRAC($H22, TODAY())) -> 124 | P22: =IF($E22="OPP","Opposite",IF($E22="OH","Outside Hitter",IF($E22="MB","Middle Blocker",IF($E22="S","Setter",IF($E22="L","Libero",""))))) -> Setter | Q22: =IF($J22=4,"Senior",IF($J22=3,"Junior",IF($J22=2,"Sophomore",IF($J22=1,"Freshman","")))) -> Sophomore | R22: ="D:\IMS Images\Headshots\VB\"&'Team Info'!$B$12&"\"&D22&"_"&C22&".png" -> D:\IMS Images\Headshots\VB\AKRON\Petrie_Jane.png | S22: ="D:\IMS Images\ActionShots\VB\"&'Team Info'!$B$12&"\"&D22&"_"&C22&".png" -> D:\IMS Images\ActionShots\VB\AKRON\Petrie_Jane.png | T22: =C22&" "&D22 -> Jane Petrie | U22: =LEFT(C22,1)&". "&D22 -> J. Petrie | V22: =IF($J22=4,"SR",IF($J22=3,"JR",IF($J22=2,"SO",IF($J22=1,"FR","")))) -> SO | W22: =UPPER(T22) -> JANE PETRIE | X22: =UPPER(C22) -> JANE | Y22: =UPPER(D22) -> PETRIE | Z22: =UPPER(Q22) -> SOPHOMORE | AA22: =B22 & " " &D22 -> 19 Petrie | AB22: =UPPER(AA22) -> 19 PETRIE
A23: 20 | B23: 20 | O23: =INT(YEARFRAC($H23, TODAY())) -> 124 | P23: =IF($E23="OPP","Opposite",IF($E23="OH","Outside Hitter",IF($E23="MB","Middle Blocker",IF($E23="S","Setter",IF($E23="L","Libero",""))))) | Q23: =IF($J23=4,"Senior",IF($J23=3,"Junior",IF($J23=2,"Sophomore",IF($J23=1,"Freshman","")))) | R23: ="D:\IMS Images\Headshots\VB\"&'Team Info'!$B$12&"\"&D23&"_"&C23&".png" -> D:\IMS Images\Headshots\VB\AKRON\_.png | S23: ="D:\IMS Images\ActionShots\VB\"&'Team Info'!$B$12&"\"&D23&"_"&C23&".png" -> D:\IMS Images\ActionShots\VB\AKRON\_.png | T23: =C23&" "&D23 | U23: =LEFT(C23,1)&". "&D23 -> . | V23: =IF($J23=4,"SR",IF($J23=3,"JR",IF($J23=2,"SO",IF($J23=1,"FR","")))) | W23: =UPPER(T23) | X23: =UPPER(C23) | Y23: =UPPER(D23) | Z23: =UPPER(Q23) | AA23: =B23 & " " &D23 -> 20 | AB23: =UPPER(AA23) -> 20
A24: 21 | B24: 21 | C24: Nikki | D24: Steinheiser | E24: OH | F24: 6'0" | I24: Celina, TX | J24: 2 | O24: =INT(YEARFRAC($H24, TODAY())) -> 124 | P24: =IF($E24="OPP","Opposite",IF($E24="OH","Outside Hitter",IF($E24="MB","Middle Blocker",IF($E24="S","Setter",IF($E24="L","Libero",""))))) -> Outside Hitter | Q24: =IF($J24=4,"Senior",IF($J24=3,"Junior",IF($J24=2,"Sophomore",IF($J24=1,"Freshman","")))) -> Sophomore | R24: ="D:\IMS Images\Headshots\VB\"&'Team Info'!$B$12&"\"&D24&"_"&C24&".png" -> D:\IMS Images\Headshots\VB\AKRON\Steinheiser_Nikki.png | S24: ="D:\IMS Images\ActionShots\VB\"&'Team Info'!$B$12&"\"&D24&"_"&C24&".png" -> D:\IMS Images\ActionShots\VB\AKRON\Steinheiser_Nikki.png | T24: =C24&" "&D24 -> Nikki Steinheiser | U24: =LEFT(C24,1)&". "&D24 -> N. Steinheiser | V24: =IF($J24=4,"SR",IF($J24=3,"JR",IF($J24=2,"SO",IF($J24=1,"FR","")))) -> SO | W24: =UPPER(T24) -> NIKKI STEINHEISER | X24: =UPPER(C24) -> NIKKI | Y24: =UPPER(D24) -> STEINHEISER | Z24: =UPPER(Q24) -> SOPHOMORE | AA24: =B24 & " " &D24 -> 21 Steinheiser | AB24: =UPPER(AA24) -> 21 STEINHEISER
A25: 22 | B25: 22 | O25: =INT(YEARFRAC($H25, TODAY())) -> 124 | P25: =IF($E25="OPP","Opposite",IF($E25="OH","Outside Hitter",IF($E25="MB","Middle Blocker",IF($E25="S","Setter",IF($E25="L","Libero",""))))) | Q25: =IF($J25=4,"Senior",IF($J25=3,"Junior",IF($J25=2,"Sophomore",IF($J25=1,"Freshman","")))) | R25: ="D:\IMS Images\Headshots\VB\"&'Team Info'!$B$12&"\"&D25&"_"&C25&".png" -> D:\IMS Images\Headshots\VB\AKRON\_.png | S25: ="D:\IMS Images\ActionShots\VB\"&'Team Info'!$B$12&"\"&D25&"_"&C25&".png" -> D:\IMS Images\ActionShots\VB\AKRON\_.png | T25: =C25&" "&D25 | U25: =LEFT(C25,1)&". "&D25 -> . | V25: =IF($J25=4,"SR",IF($J25=3,"JR",IF($J25=2,"SO",IF($J25=1,"FR","")))) | W25: =UPPER(T25) | X25: =UPPER(C25) | Y25: =UPPER(D25) | Z25: =UPPER(Q25) | AA25: =B25 & " " &D25 -> 22 | AB25: =UPPER(AA25) -> 22
A26: 23 | B26: 23 | C26: Julia | D26: Haggerty | E26: MB/OPP | F26: 6'2" | I26: Lafayette, CA | J26: 2 | O26: =INT(YEARFRAC($H26, TODAY())) -> 124 | P26: =IF($E26="OPP","Opposite",IF($E26="OH","Outside Hitter",IF($E26="MB","Middle Blocker",IF($E26="S","Setter",IF($E26="L","Libero",""))))) | Q26: =IF($J26=4,"Senior",IF($J26=3,"Junior",IF($J26=2,"Sophomore",IF($J26=1,"Freshman","")))) -> Sophomore | R26: ="D:\IMS Images\Headshots\VB\"&'Team Info'!$B$12&"\"&D26&"_"&C26&".png" -> D:\IMS Images\Headshots\VB\AKRON\Haggerty_Julia.png | S26: ="D:\IMS Images\ActionShots\VB\"&'Team Info'!$B$12&"\"&D26&"_"&C26&".png" -> D:\IMS Images\ActionShots\VB\AKRON\Haggerty_Julia.png | T26: =C26&" "&D26 -> Julia Haggerty | U26: =LEFT(C26,1)&". "&D26 -> J. Haggerty | V26: =IF($J26=4,"SR",IF($J26=3,"JR",IF($J26=2,"SO",IF($J26=1,"FR","")))) -> SO | W26: =UPPER(T26) -> JULIA HAGGERTY | X26: =UPPER(C26) -> JULIA | Y26: =UPPER(D26) -> HAGGERTY | Z26: =UPPER(Q26) -> SOPHOMORE | AA26: =B26 & " " &D26 -> 23 Haggerty | AB26: =UPPER(AA26) -> 23 HAGGERTY
A27: 24 | B27: 24 | O27: =INT(YEARFRAC($H27, TODAY())) -> 124 | P27: =IF($E27="OPP","Opposite",IF($E27="OH","Outside Hitter",IF($E27="MB","Middle Blocker",IF($E27="S","Setter",IF($E27="L","Libero",""))))) | Q27: =IF($J27=4,"Senior",IF($J27=3,"Junior",IF($J27=2,"Sophomore",IF($J27=1,"Freshman","")))) | R27: ="D:\IMS Images\Headshots\VB\"&'Team Info'!$B$12&"\"&D27&"_"&C27&".png" -> D:\IMS Images\Headshots\VB\AKRON\_.png | S27: ="D:\IMS Images\ActionShots\VB\"&'Team Info'!$B$12&"\"&D27&"_"&C27&".png" -> D:\IMS Images\ActionShots\VB\AKRON\_.png | T27: =C27&" "&D27 | U27: =LEFT(C27,1)&". "&D27 -> . | V27: =IF($J27=4,"SR",IF($J27=3,"JR",IF($J27=2,"SO",IF($J27=1,"FR","")))) | W27: =UPPER(T27) | X27: =UPPER(C27) | Y27: =UPPER(D27) | Z27: =UPPER(Q27) | AA27: =B27 & " " &D27 -> 24 | AB27: =UPPER(AA27) -> 24
A28: 25 | B28: 25 | O28: =INT(YEARFRAC($H28, TODAY())) -> 124 | P28: =IF($E28="OPP","Opposite",IF($E28="OH","Outside Hitter",IF($E28="MB","Middle Blocker",IF($E28="S","Setter",IF($E28="L","Libero",""))))) | Q28: =IF($J28=4,"Senior",IF($J28=3,"Junior",IF($J28=2,"Sophomore",IF($J28=1,"Freshman","")))) | R28: ="D:\IMS Images\Headshots\VB\"&'Team Info'!$B$12&"\"&D28&"_"&C28&".png" -> D:\IMS Images\Headshots\VB\AKRON\_.png | S28: ="D:\IMS Images\ActionShots\VB\"&'Team Info'!$B$12&"\"&D28&"_"&C28&".png" -> D:\IMS Images\ActionShots\VB\AKRON\_.png | T28: =C28&" "&D28 | U28: =LEFT(C28,1)&". "&D28 -> . | V28: =IF($J28=4,"SR",IF($J28=3,"JR",IF($J28=2,"SO",IF($J28=1,"FR","")))) | W28: =UPPER(T28) | X28: =UPPER(C28) | Y28: =UPPER(D28) | Z28: =UPPER(Q28) | AA28: =B28 & " " &D28 -> 25 | AB28: =UPPER(AA28) -> 25
A29: 26 | B29: 26 | O29: =INT(YEARFRAC($H29, TODAY())) -> 124 | P29: =IF($E29="OPP","Opposite",IF($E29="OH","Outside Hitter",IF($E29="MB","Middle Blocker",IF($E29="S","Setter",IF($E29="L","Libero",""))))) | Q29: =IF($J29=4,"Senior",IF($J29=3,"Junior",IF($J29=2,"Sophomore",IF($J29=1,"Freshman","")))) | R29: ="D:\IMS Images\Headshots\VB\"&'Team Info'!$B$12&"\"&D29&"_"&C29&".png" -> D:\IMS Images\Headshots\VB\AKRON\_.png | S29: ="D:\IMS Images\ActionShots\VB\"&'Team Info'!$B$12&"\"&D29&"_"&C29&".png" -> D:\IMS Images\ActionShots\VB\AKRON\_.png | T29: =C29&" "&D29 | U29: =LEFT(C29,1)&". "&D29 -> . | V29: =IF($J29=4,"SR",IF($J29=3,"JR",IF($J29=2,"SO",IF($J29=1,"FR","")))) | W29: =UPPER(T29) | X29: =UPPER(C29) | Y29: =UPPER(D29) | Z29: =UPPER(Q29) | AA29: =B29 & " " &D29 -> 26 | AB29: =UPPER(AA29) -> 26
A30: 27 | B30: 27 | O30: =INT(YEARFRAC($H30, TODAY())) -> 124 | P30: =IF($E30="OPP","Opposite",IF($E30="OH","Outside Hitter",IF($E30="MB","Middle Blocker",IF($E30="S","Setter",IF($E30="L","Libero",""))))) | Q30: =IF($J30=4,"Senior",IF($J30=3,"Junior",IF($J30=2,"Sophomore",IF($J30=1,"Freshman","")))) | R30: ="D:\IMS Images\Headshots\VB\"&'Team Info'!$B$12&"\"&D30&"_"&C30&".png" -> D:\IMS Images\Headshots\VB\AKRON\_.png | S30: ="D:\IMS Images\ActionShots\VB\"&'Team Info'!$B$12&"\"&D30&"_"&C30&".png" -> D:\IMS Images\ActionShots\VB\AKRON\_.png | T30: =C30&" "&D30 | U30: =LEFT(C30,1)&". "&D30 -> . | V30: =IF($J30=4,"SR",IF($J30=3,"JR",IF($J30=2,"SO",IF($J30=1,"FR","")))) | W30: =UPPER(T30) | X30: =UPPER(C30) | Y30: =UPPER(D30) | Z30: =UPPER(Q30) | AA30: =B30 & " " &D30 -> 27 | AB30: =UPPER(AA30) -> 27
A31: 28 | B31: 28 | O31: =INT(YEARFRAC($H31, TODAY())) -> 124 | P31: =IF($E31="OPP","Opposite",IF($E31="OH","Outside Hitter",IF($E31="MB","Middle Blocker",IF($E31="S","Setter",IF($E31="L","Libero",""))))) | Q31: =IF($J31=4,"Senior",IF($J31=3,"Junior",IF($J31=2,"Sophomore",IF($J31=1,"Freshman","")))) | R31: ="D:\IMS Images\Headshots\VB\"&'Team Info'!$B$12&"\"&D31&"_"&C31&".png" -> D:\IMS Images\Headshots\VB\AKRON\_.png | S31: ="D:\IMS Images\ActionShots\VB\"&'Team Info'!$B$12&"\"&D31&"_"&C31&".png" -> D:\IMS Images\ActionShots\VB\AKRON\_.png | T31: =C31&" "&D31 | U31: =LEFT(C31,1)&". "&D31 -> . | V31: =IF($J31=4,"SR",IF($J31=3,"JR",IF($J31=2,"SO",IF($J31=1,"FR","")))) | W31: =UPPER(T31) | X31: =UPPER(C31) | Y31: =UPPER(D31) | Z31: =UPPER(Q31) | AA31: =B31 & " " &D31 -> 28 | AB31: =UPPER(AA31) -> 28
A32: 29 | B32: 29 | O32: =INT(YEARFRAC($H32, TODAY())) -> 124 | P32: =IF($E32="OPP","Opposite",IF($E32="OH","Outside Hitter",IF($E32="MB","Middle Blocker",IF($E32="S","Setter",IF($E32="L","Libero",""))))) | Q32: =IF($J32=4,"Senior",IF($J32=3,"Junior",IF($J32=2,"Sophomore",IF($J32=1,"Freshman","")))) | R32: ="D:\IMS Images\Headshots\VB\"&'Team Info'!$B$12&"\"&D32&"_"&C32&".png" -> D:\IMS Images\Headshots\VB\AKRON\_.png | S32: ="D:\IMS Images\ActionShots\VB\"&'Team Info'!$B$12&"\"&D32&"_"&C32&".png" -> D:\IMS Images\ActionShots\VB\AKRON\_.png | T32: =C32&" "&D32 | U32: =LEFT(C32,1)&". "&D32 -> . | V32: =IF($J32=4,"SR",IF($J32=3,"JR",IF($J32=2,"SO",IF($J32=1,"FR","")))) | W32: =UPPER(T32) | X32: =UPPER(C32) | Y32: =UPPER(D32) | Z32: =UPPER(Q32) | AA32: =B32 & " " &D32 -> 29 | AB32: =UPPER(AA32) -> 29
A33: 30 | B33: 30 | O33: =INT(YEARFRAC($H33, TODAY())) -> 124 | P33: =IF($E33="OPP","Opposite",IF($E33="OH","Outside Hitter",IF($E33="MB","Middle Blocker",IF($E33="S","Setter",IF($E33="L","Libero",""))))) | Q33: =IF($J33=4,"Senior",IF($J33=3,"Junior",IF($J33=2,"Sophomore",IF($J33=1,"Freshman","")))) | R33: ="D:\IMS Images\Headshots\VB\"&'Team Info'!$B$12&"\"&D33&"_"&C33&".png" -> D:\IMS Images\Headshots\VB\AKRON\_.png | S33: ="D:\IMS Images\ActionShots\VB\"&'Team Info'!$B$12&"\"&D33&"_"&C33&".png" -> D:\IMS Images\ActionShots\VB\AKRON\_.png | T33: =C33&" "&D33 | U33: =LEFT(C33,1)&". "&D33 -> . | V33: =IF($J33=4,"SR",IF($J33=3,"JR",IF($J33=2,"SO",IF($J33=1,"FR","")))) | W33: =UPPER(T33) | X33: =UPPER(C33) | Y33: =UPPER(D33) | Z33: =UPPER(Q33) | AA33: =B33 & " " &D33 -> 30 | AB33: =UPPER(AA33) -> 30
A34: 31 | B34: 31 | O34: =INT(YEARFRAC($H34, TODAY())) -> 124 | P34: =IF($E34="OPP","Opposite",IF($E34="OH","Outside Hitter",IF($E34="MB","Middle Blocker",IF($E34="S","Setter",IF($E34="L","Libero",""))))) | Q34: =IF($J34=4,"Senior",IF($J34=3,"Junior",IF($J34=2,"Sophomore",IF($J34=1,"Freshman","")))) | R34: ="D:\IMS Images\Headshots\VB\"&'Team Info'!$B$12&"\"&D34&"_"&C34&".png" -> D:\IMS Images\Headshots\VB\AKRON\_.png | S34: ="D:\IMS Images\ActionShots\VB\"&'Team Info'!$B$12&"\"&D34&"_"&C34&".png" -> D:\IMS Images\ActionShots\VB\AKRON\_.png | T34: =C34&" "&D34 | U34: =LEFT(C34,1)&". "&D34 -> . | V34: =IF($J34=4,"SR",IF($J34=3,"JR",IF($J34=2,"SO",IF($J34=1,"FR","")))) | W34: =UPPER(T34) | X34: =UPPER(C34) | Y34: =UPPER(D34) | Z34: =UPPER(Q34) | AA34: =B34 & " " &D34 -> 31 | AB34: =UPPER(AA34) -> 31
A35: 32 | B35: 32 | O35: =INT(YEARFRAC($H35, TODAY())) -> 124 | P35: =IF($E35="OPP","Opposite",IF($E35="OH","Outside Hitter",IF($E35="MB","Middle Blocker",IF($E35="S","Setter",IF($E35="L","Libero",""))))) | Q35: =IF($J35=4,"Senior",IF($J35=3,"Junior",IF($J35=2,"Sophomore",IF($J35=1,"Freshman","")))) | R35: ="D:\IMS Images\Headshots\VB\"&'Team Info'!$B$12&"\"&D35&"_"&C35&".png" -> D:\IMS Images\Headshots\VB\AKRON\_.png | S35: ="D:\IMS Images\ActionShots\VB\"&'Team Info'!$B$12&"\"&D35&"_"&C35&".png" -> D:\IMS Images\ActionShots\VB\AKRON\_.png | T35: =C35&" "&D35 | U35: =LEFT(C35,1)&". "&D35 -> . | V35: =IF($J35=4,"SR",IF($J35=3,"JR",IF($J35=2,"SO",IF($J35=1,"FR","")))) | W35: =UPPER(T35) | X35: =UPPER(C35) | Y35: =UPPER(D35) | Z35: =UPPER(Q35) | AA35: =B35 & " " &D35 -> 32 | AB35: =UPPER(AA35) -> 32
A36: 33 | B36: 33 | O36: =INT(YEARFRAC($H36, TODAY())) -> 124 | P36: =IF($E36="OPP","Opposite",IF($E36="OH","Outside Hitter",IF($E36="MB","Middle Blocker",IF($E36="S","Setter",IF($E36="L","Libero",""))))) | Q36: =IF($J36=4,"Senior",IF($J36=3,"Junior",IF($J36=2,"Sophomore",IF($J36=1,"Freshman","")))) | R36: ="D:\IMS Images\Headshots\VB\"&'Team Info'!$B$12&"\"&D36&"_"&C36&".png" -> D:\IMS Images\Headshots\VB\AKRON\_.png | S36: ="D:\IMS Images\ActionShots\VB\"&'Team Info'!$B$12&"\"&D36&"_"&C36&".png" -> D:\IMS Images\ActionShots\VB\AKRON\_.png | T36: =C36&" "&D36 | U36: =LEFT(C36,1)&". "&D36 -> . | V36: =IF($J36=4,"SR",IF($J36=3,"JR",IF($J36=2,"SO",IF($J36=1,"FR","")))) | W36: =UPPER(T36) | X36: =UPPER(C36) | Y36: =UPPER(D36) | Z36: =UPPER(Q36) | AA36: =B36 & " " &D36 -> 33 | AB36: =UPPER(AA36) -> 33
A37: 34 | B37: 34 | O37: =INT(YEARFRAC($H37, TODAY())) -> 124 | P37: =IF($E37="OPP","Opposite",IF($E37="OH","Outside Hitter",IF($E37="MB","Middle Blocker",IF($E37="S","Setter",IF($E37="L","Libero",""))))) | Q37: =IF($J37=4,"Senior",IF($J37=3,"Junior",IF($J37=2,"Sophomore",IF($J37=1,"Freshman","")))) | R37: ="D:\IMS Images\Headshots\VB\"&'Team Info'!$B$12&"\"&D37&"_"&C37&".png" -> D:\IMS Images\Headshots\VB\AKRON\_.png | S37: ="D:\IMS Images\ActionShots\VB\"&'Team Info'!$B$12&"\"&D37&"_"&C37&".png" -> D:\IMS Images\ActionShots\VB\AKRON\_.png | T37: =C37&" "&D37 | U37: =LEFT(C37,1)&". "&D37 -> . | V37: =IF($J37=4,"SR",IF($J37=3,"JR",IF($J37=2,"SO",IF($J37=1,"FR","")))) | W37: =UPPER(T37) | X37: =UPPER(C37) | Y37: =UPPER(D37) | Z37: =UPPER(Q37) | AA37: =B37 & " " &D37 -> 34 | AB37: =UPPER(AA37) -> 34
A38: 35 | B38: 35 | O38: =INT(YEARFRAC($H38, TODAY())) -> 124 | P38: =IF($E38="OPP","Opposite",IF($E38="OH","Outside Hitter",IF($E38="MB","Middle Blocker",IF($E38="S","Setter",IF($E38="L","Libero",""))))) | Q38: =IF($J38=4,"Senior",IF($J38=3,"Junior",IF($J38=2,"Sophomore",IF($J38=1,"Freshman","")))) | R38: ="D:\IMS Images\Headshots\VB\"&'Team Info'!$B$12&"\"&D38&"_"&C38&".png" -> D:\IMS Images\Headshots\VB\AKRON\_.png | S38: ="D:\IMS Images\ActionShots\VB\"&'Team Info'!$B$12&"\"&D38&"_"&C38&".png" -> D:\IMS Images\ActionShots\VB\AKRON\_.png | T38: =C38&" "&D38 | U38: =LEFT(C38,1)&". "&D38 -> . | V38: =IF($J38=4,"SR",IF($J38=3,"JR",IF($J38=2,"SO",IF($J38=1,"FR","")))) | W38: =UPPER(T38) | X38: =UPPER(C38) | Y38: =UPPER(D38) | Z38: =UPPER(Q38) | AA38: =B38 & " " &D38 -> 35 | AB38: =UPPER(AA38) -> 35
... A92: 89 | B92: 89 | O92: =INT(YEARFRAC($H92, TODAY())) -> 124 | P92: =IF($E92="OPP","Opposite",IF($E92="OH","Outside Hitter",IF($E92="MB","Middle Blocker",IF($E92="S","Setter",IF($E92="L","Libero",""))))) | Q92: =IF($J92=4,"Senior",IF($J92=3,"Junior",IF($J92=2,"Sophomore",IF($J92=1,"Freshman","")))) | R92: ="D:\IMS Images\Headshots\VB\"&'Team Info'!$B$12&"\"&D92&"_"&C92&".png" -> D:\IMS Images\Headshots\VB\AKRON\_.png | S92: ="D:\IMS Images\ActionShots\VB\"&'Team Info'!$B$12&"\"&D92&"_"&C92&".png" -> D:\IMS Images\ActionShots\VB\AKRON\_.png | T92: =C92&" "&D92 | U92: =LEFT(C92,1)&". "&D92 -> . | V92: =IF($J92=4,"SR",IF($J92=3,"JR",IF($J92=2,"SO",IF($J92=1,"FR","")))) | W92: =UPPER(T92) | X92: =UPPER(C92) | Y92: =UPPER(D92) | Z92: =UPPER(Q92) | AA92: =B92 & " " &D92 -> 89 | AB92: =UPPER(AA92) -> 89
A93: 90 | B93: 0 | C93: =IF(C$104=0,"",C$104) | D93: =IF(D$104=0,"",D$104) | E93: =IF(E$104=0,"",E$104) | F93: =IF(F$104=0,"",F$104) | G93: =IF(G$104=0,"",G$104) | H93: =IF(H$104=0,"",H$104) | I93: =IF(I$104=0,"",I$104) | J93: =IF(J$104=0,"",J$104) | ... M93: =IF(M$104=0,"",M$104) | O93: =INT(YEARFRAC($H93, TODAY())) -> #VALUE! | P93: =IF($E93="OPP","Opposite",IF($E93="OH","Outside Hitter",IF($E93="MB","Middle Blocker",IF($E93="S","Setter",IF($E93="L","Libero",""))))) | Q93: =IF($J93=4,"Senior",IF($J93=3,"Junior",IF($J93=2,"Sophomore",IF($J93=1,"Freshman","")))) | R93: ="D:\IMS Images\Headshots\VB\"&'Team Info'!$B$12&"\"&D93&"_"&C93&".png" -> D:\IMS Images\Headshots\VB\AKRON\_.png | S93: ="D:\IMS Images\ActionShots\VB\"&'Team Info'!$B$12&"\"&D93&"_"&C93&".png" -> D:\IMS Images\ActionShots\VB\AKRON\_.png | T93: =C93&" "&D93 | U93: =LEFT(C93,1)&". "&D93 -> . | V93: =IF($J93=4,"SR",IF($J93=3,"JR",IF($J93=2,"SO",IF($J93=1,"FR","")))) | W93: =UPPER(T93) | X93: =UPPER(C93) | Y93: =UPPER(D93) | Z93: =UPPER(Q93) | AA93: =B93 & " " &D93 -> 0 | AB93: =UPPER(AA93) -> 0
...

Sheet Season Stats
A1: Jersey | B1: Display Jersey | C1: Player Name | D1: CAT1 | E1: CAT1 HILITE | F1: CAT2 | G1: CAT2 HILITE | H1: CAT3 | I1: CAT3 HILITE | J1: STAT HILITE NOTE | L1: PTS STAT | M1: FG STAT | N1: 3PT% STAT | O1: FT% STAT | P1: REBS STAT | Q1: ASSTS STAT | R1: BLOCKS STAT | S1: STEALS STAT | T1: MINUTES STAT | U1: AVERAGE STAT | W1: USER CAT1 | X1: USER CAT2 | Y1: SEASON + FT STAT | Z1: SEASON + 3PT% | AB1: POINTS | AC1: FG | AD1: 3PT% | AE1: FT% | AF1: REBOUNDS | AG1: ASSISTS | AH1: BLOCKS | AI1: STEALS | AJ1: MINUTES
A2: =Roster!$A4 -> 1 | B2: =Roster!B4 -> 1 | C2: =Roster!$T4 -> Grace Penn | D2: xx | E2: X | F2: x | G2: X | H2: x | I2: X | J2: Stat Note Here zz | L2: =#REF! -> #REF! | M2: =#REF! -> #REF! | N2: =#REF! -> #REF! | O2: =#REF! -> #REF! | P2: =#REF! -> #REF! | Q2: =#REF! -> #REF! | R2: =#REF! -> #REF! | S2: =#REF! -> #REF! | T2: =#REF! -> #REF! | U2: 0 | W2: XX stat | xx Stat | X2: 45% FG | Y2: ='Team Info'!$B$19&": "&O2&"" -> #REF! | Z2: ='Team Info'!$B$19&": "&N2&"" -> #REF! | AB2: =L2&" PPG" -> #REF! | AC2: =M2&" FG" -> #REF! | AD2: =N2&" 3-PT" -> #REF! | AE2: =O2&" FT" -> #REF! | AF2: =P2&" RPG" -> #REF! | AG2: =Q2&" APG" -> #REF! | AH2: =R2&" BPG" -> #REF! | AI2: =S2&" SPG" -> #REF! | AJ2: =T2&" MPG" -> #REF!
A3: 2 | B3: 2 | C3: =Roster!$T5 -> Silvia Ianeselli | D3: xx | F3: x | H3: x | J3: Stat Note Here | L3: =#REF! -> #REF! | M3: =#REF! -> #REF! | N3: =#REF! -> #REF! | O3: =#REF! -> #REF! | P3: =#REF! -> #REF! | Q3: =#REF! -> #REF! | R3: =#REF! -> #REF! | S3: =#REF! -> #REF! | ... U3: =#REF! -> #REF! | W3: XX stat | xx Stat | X3: 43% FG | Y3: ='Team Info'!$B$19&": "&O3&"" -> #REF! | Z3: ='Team Info'!$B$19&": "&N3&"" -> #REF! | AB3: =L3&" PPG" -> #REF! | AC3: =M3&" FG" -> #REF! | AD3: =N3&" 3-PT" -> #REF! | AE3: =O3&" FT" -> #REF! | AF3: =P3&" RPG" -> #REF! | AG3: =Q3&" APG" -> #REF! | AH3: =R3&" BPG" -> #REF! | AI3: =S3&" SPG" -> #REF! | AJ3: =T3&" MPG" -> #REF!
A4: 3 | B4: 3 | C4: =Roster!$T6 | L4: =#REF! -> #REF! | M4: =#REF! -> #REF! | N4: =#REF! -> #REF! | O4: =#REF! -> #REF! | P4: =#REF! -> #REF! | Q4: =#REF! -> #REF! | R4: =#REF! -> #REF! | S4: =#REF! -> #REF! | ... U4: =#REF! -> #REF! | Y4: ='Team Info'!$B$19&": "&O4&"" -> #REF! | Z4: ='Team Info'!$B$19&": "&N4&"" -> #REF! | AB4: =L4&" PPG" -> #REF! | AC4: =M4&" FG" -> #REF! | AD4: =N4&" 3-PT" -> #REF! | AE4: =O4&" FT" -> #REF! | AF4: =P4&" RPG" -> #REF! | AG4: =Q4&" APG" -> #REF! | AH4: =R4&" BPG" -> #REF! | AI4: =S4&" SPG" -> #REF! | AJ4: =T4&" MPG" -> #REF!
A5: 4 | B5: 4 | C5: =Roster!$T7 -> Anna Murphy | L5: =#REF! -> #REF! | M5: =#REF! -> #REF! | N5: =#REF! -> #REF! | O5: =#REF! -> #REF! | P5: =#REF! -> #REF! | Q5: =#REF! -> #REF! | R5: =#REF! -> #REF! | S5: =#REF! -> #REF! | ... U5: =#REF! -> #REF! | Y5: ='Team Info'!$B$19&": "&O5&"" -> #REF! | Z5: ='Team Info'!$B$19&": "&N5&"" -> #REF! | AB5: =L5&" PPG" -> #REF! | AC5: =M5&" FG" -> #REF! | AD5: =N5&" 3-PT" -> #REF! | AE5: =O5&" FT" -> #REF! | AF5: =P5&" RPG" -> #REF! | AG5: =Q5&" APG" -> #REF! | AH5: =R5&" BPG" -> #REF! | AI5: =S5&" SPG" -> #REF! | AJ5: =T5&" MPG" -> #REF!
A6: 5 | B6: 5 | C6: =Roster!$T8 -> Sophia Lambros | L6: =#REF! -> #REF! | M6: =#REF! -> #REF! | N6: =#REF! -> #REF! | O6: =#REF! -> #REF! | P6: =#REF! -> #REF! | Q6: =#REF! -> #REF! | R6: =#REF! -> #REF! | S6: =#REF! -> #REF! | ... U6: =#REF! -> #REF! | Y6: ='Team Info'!$B$19&": "&O6&"" -> #REF! | Z6: ='Team Info'!$B$19&": "&N6&"" -> #REF! | AB6: =L6&" PPG" -> #REF! | AC6: =M6&" FG" -> #REF! | AD6: =N6&" 3-PT" -> #REF! | AE6: =O6&" FT" -> #REF! | AF6: =P6&" RPG" -> #REF! | AG6: =Q6&" APG" -> #REF! | AH6: =R6&" BPG" -> #REF! | AI6: =S6&" SPG" -> #REF! | AJ6: =T6&" MPG" -> #REF!
A7: 6 | B7: 6 | C7: =Roster!$T9 -> Jenna Pollock | L7: =#REF! -> #REF! | M7: =#REF! -> #REF! | N7: =#REF! -> #REF! | O7: =#REF! -> #REF! | P7: =#REF! -> #REF! | Q7: =#REF! -> #REF! | R7: =#REF! -> #REF! | S7: =#REF! -> #REF! | ... U7: =#REF! -> #REF! | Y7: ='Team Info'!$B$19&": "&O7&"" -> #REF! | Z7: ='Team Info'!$B$19&": "&N7&"" -> #REF! | AB7: =L7&" PPG" -> #REF! | AC7: =M7&" FG" -> #REF! | AD7: =N7&" 3-PT" -> #REF! | AE7: =O7&" FT" -> #REF! | AF7: =P7&" RPG" -> #REF! | AG7: =Q7&" APG" -> #REF! | AH7: =R7&" BPG" -> #REF! | AI7: =S7&" SPG" -> #REF! | AJ7: =T7&" MPG" -> #REF!
A8: 7 | B8: 7 | C8: =Roster!$T10 | L8: =#REF! -> #REF! | M8: =#REF! -> #REF! | N8: =#REF! -> #REF! | O8: =#REF! -> #REF! | P8: =#REF! -> #REF! | Q8: =#REF! -> #REF! | R8: =#REF! -> #REF! | S8: =#REF! -> #REF! | ... U8: =#REF! -> #REF! | Y8: ='Team Info'!$B$19&": "&O8&"" -> #REF! | Z8: ='Team Info'!$B$19&": "&N8&"" -> #REF! | AB8: =L8&" PPG" -> #REF! | AC8: =M8&" FG" -> #REF! | AD8: =N8&" 3-PT" -> #REF! | AE8: =O8&" FT" -> #REF! | AF8: =P8&" RPG" -> #REF! | AG8: =Q8&" APG" -> #REF! | AH8: =R8&" BPG" -> #REF! | AI8: =S8&" SPG" -> #REF! | AJ8: =T8&" MPG" -> #REF!
A9: 8 | B9: 8 | C9: =Roster!$T11 | L9: =#REF! -> #REF! | M9: =#REF! -> #REF! | N9: =#REF! -> #REF! | O9: =#REF! -> #REF! | P9: =#REF! -> #REF! | Q9: =#REF! -> #REF! | R9: =#REF! -> #REF! | S9: =#REF! -> #REF! | ... U9: =#REF! -> #REF! | Y9: ='Team Info'!$B$19&": "&O9&"" -> #REF! | Z9: ='Team Info'!$B$19&": "&N9&"" -> #REF! | AB9: =L9&" PPG" -> #REF! | AC9: =M9&" FG" -> #REF! | AD9: =N9&" 3-PT" -> #REF! | AE9: =O9&" FT" -> #REF! | AF9: =P9&" RPG" -> #REF! | AG9: =Q9&" APG" -> #REF! | AH9: =R9&" BPG" -> #REF! | AI9: =S9&" SPG" -> #REF! | AJ9: =T9&" MPG" -> #REF!
A10: 9 | B10: 9 | C10: =Roster!$T12 -> Katrina Jensen | L10: =#REF! -> #REF! | M10: =#REF! -> #REF! | N10: =#REF! -> #REF! | O10: =#REF! -> #REF! | P10: =#REF! -> #REF! | Q10: =#REF! -> #REF! | R10: =#REF! -> #REF! | S10: =#REF! -> #REF! | ... U10: =#REF! -> #REF! | Y10: ='Team Info'!$B$19&": "&O10&"" -> #REF! | Z10: ='Team Info'!$B$19&": "&N10&"" -> #REF! | AB10: =L10&" PPG" -> #REF! | AC10: =M10&" FG" -> #REF! | AD10: =N10&" 3-PT" -> #REF! | AE10: =O10&" FT" -> #REF! | AF10: =P10&" RPG" -> #REF! | AG10: =Q10&" APG" -> #REF! | AH10: =R10&" BPG" -> #REF! | AI10: =S10&" SPG" -> #REF! | AJ10: =T10&" MPG" -> #REF!
A11: 10 | B11: 10 | C11: =Roster!$T13 -> Peyton Minyard | L11: =#REF! -> #REF! | M11: =#REF! -> #REF! | N11: =#REF! -> #REF! | O11: =#REF! -> #REF! | P11: =#REF! -> #REF! | Q11: =#REF! -> #REF! | R11: =#REF! -> #REF! | S11: =#REF! -> #REF! | ... U11: =#REF! -> #REF! | Y11: ='Team Info'!$B$19&": "&O11&"" -> #REF! | Z11: ='Team Info'!$B$19&": "&N11&"" -> #REF! | AB11: =L11&" PPG" -> #REF! | AC11: =M11&" FG" -> #REF! | AD11: =N11&" 3-PT" -> #REF! | AE11: =O11&" FT" -> #REF! | AF11: =P11&" RPG" -> #REF! | AG11: =Q11&" APG" -> #REF! | AH11: =R11&" BPG" -> #REF! | AI11: =S11&" SPG" -> #REF! | AJ11: =T11&" MPG" -> #REF!
A12: 11 | B12: 11 | C12: =Roster!$T14 -> Alayna Crabtree | L12: =#REF! -> #REF! | M12: =#REF! -> #REF! | N12: =#REF! -> #REF! | O12: =#REF! -> #REF! | P12: =#REF! -> #REF! | Q12: =#REF! -> #REF! | R12: =#REF! -> #REF! | S12: =#REF! -> #REF! | ... U12: =#REF! -> #REF! | Y12: ='Team Info'!$B$19&": "&O12&"" -> #REF! | Z12: ='Team Info'!$B$19&": "&N12&"" -> #REF! | AB12: =L12&" PPG" -> #REF! | AC12: =M12&" FG" -> #REF! | AD12: =N12&" 3-PT" -> #REF! | AE12: =O12&" FT" -> #REF! | AF12: =P12&" RPG" -> #REF! | AG12: =Q12&" APG" -> #REF! | AH12: =R12&" BPG" -> #REF! | AI12: =S12&" SPG" -> #REF! | AJ12: =T12&" MPG" -> #REF!
A13: 12 | B13: 12 | C13: =Roster!$T15 -> Izzy Clavenna | L13: =#REF! -> #REF! | M13: =#REF! -> #REF! | N13: =#REF! -> #REF! | O13: =#REF! -> #REF! | P13: =#REF! -> #REF! | Q13: =#REF! -> #REF! | R13: =#REF! -> #REF! | S13: =#REF! -> #REF! | ... U13: =#REF! -> #REF! | Y13: ='Team Info'!$B$19&": "&O13&"" -> #REF! | Z13: ='Team Info'!$B$19&": "&N13&"" -> #REF! | AB13: =L13&" PPG" -> #REF! | AC13: =M13&" FG" -> #REF! | AD13: =N13&" 3-PT" -> #REF! | AE13: =O13&" FT" -> #REF! | AF13: =P13&" RPG" -> #REF! | AG13: =Q13&" APG" -> #REF! | AH13: =R13&" BPG" -> #REF! | AI13: =S13&" SPG" -> #REF! | AJ13: =T13&" MPG" -> #REF!
A14: 13 | B14: 13 | C14: =Roster!$T16 | L14: =#REF! -> #REF! | M14: =#REF! -> #REF! | N14: =#REF! -> #REF! | O14: =#REF! -> #REF! | P14: =#REF! -> #REF! | Q14: =#REF! -> #REF! | R14: =#REF! -> #REF! | S14: =#REF! -> #REF! | ... U14: =#REF! -> #REF! | Y14: ='Team Info'!$B$19&": "&O14&"" -> #REF! | Z14: ='Team Info'!$B$19&": "&N14&"" -> #REF! | AB14: =L14&" PPG" -> #REF! | AC14: =M14&" FG" -> #REF! | AD14: =N14&" 3-PT" -> #REF! | AE14: =O14&" FT" -> #REF! | AF14: =P14&" RPG" -> #REF! | AG14: =Q14&" APG" -> #REF! | AH14: =R14&" BPG" -> #REF! | AI14: =S14&" SPG" -> #REF! | AJ14: =T14&" MPG" -> #REF!
A15: 14 | B15: 14 | C15: =Roster!$T17 | L15: =#REF! -> #REF! | M15: =#REF! -> #REF! | N15: =#REF! -> #REF! | O15: =#REF! -> #REF! | P15: =#REF! -> #REF! | Q15: =#REF! -> #REF! | R15: =#REF! -> #REF! | S15: =#REF! -> #REF! | ... U15: =#REF! -> #REF! | Y15: ='Team Info'!$B$19&": "&O15&"" -> #REF! | Z15: ='Team Info'!$B$19&": "&N15&"" -> #REF! | AB15: =L15&" PPG" -> #REF! | AC15: =M15&" FG" -> #REF! | AD15: =N15&" 3-PT" -> #REF! | AE15: =O15&" FT" -> #REF! | AF15: =P15&" RPG" -> #REF! | AG15: =Q15&" APG" -> #REF! | AH15: =R15&" BPG" -> #REF! | AI15: =S15&" SPG" -> #REF! | AJ15: =T15&" MPG" -> #REF!
... A75: 74 | B75: 74 | C75: =Roster!$T77 | L75: =#REF! -> #REF! | M75: =#REF! -> #REF! | N75: =#REF! -> #REF! | O75: =#REF! -> #REF! | P75: =#REF! -> #REF! | Q75: =#REF! -> #REF! | R75: =#REF! -> #REF! | S75: =#REF! -> #REF! | ... U75: =#REF! -> #REF! | Y75: ='Team Info'!$B$19&": "&O75&"" -> #REF! | Z75: ='Team Info'!$B$19&": "&N75&"" -> #REF! | AB75: =L75&" PPG" -> #REF! | AC75: =M75&" FG" -> #REF! | AD75: =N75&" 3-PT" -> #REF! | AE75: =O75&" FT" -> #REF! | AF75: =P75&" RPG" -> #REF! | AG75: =Q75&" APG" -> #REF! | AH75: =R75&" BPG" -> #REF! | AI75: =S75&" SPG" -> #REF! | AJ75: =T75&" MPG" -> #REF!
A76: 75 | B76: 75 | C76: =Roster!$T78 | L76: 0 | M76: 0 | N76: =#REF! -> #REF! | O76: 0 | P76: =#REF! -> #REF! | Q76: 0 | R76: =#REF! -> #REF! | S76: 0 | T76: =#REF! -> #REF! | U76: =#REF! -> #REF! | Y76: ='Team Info'!$B$19&": "&O76&"" -> Last Season: 0 | Z76: ='Team Info'!$B$19&": "&N76&"" -> #REF! | AB76: =L76&" PPG" -> 0 PPG | AC76: =M76&" FG" -> 0 FG | AD76: =N76&" 3-PT" -> #REF! | AE76: =O76&" FT" -> 0 FT | AF76: =P76&" RPG" -> #REF! | AG76: =Q76&" APG" -> 0 APG | AH76: =R76&" BPG" -> #REF! | AI76: =S76&" SPG" -> 0 SPG | AJ76: =T76&" MPG" -> #REF!
A77: 76 | B77: 76 | C77: =Roster!$T79 | L77: =#REF! -> #REF! | M77: =#REF! -> #REF! | N77: =#REF! -> #REF! | O77: =#REF! -> #REF! | P77: =#REF! -> #REF! | Q77: =#REF! -> #REF! | R77: =#REF! -> #REF! | S77: =#REF! -> #REF! | ... U77: =#REF! -> #REF! | Y77: ='Team Info'!$B$19&": "&O77&"" -> #REF! | Z77: ='Team Info'!$B$19&": "&N77&"" -> #REF! | AB77: =L77&" PPG" -> #REF! | AC77: =M77&" FG" -> #REF! | AD77: =N77&" 3-PT" -> #REF! | AE77: =O77&" FT" -> #REF! | AF77: =P77&" RPG" -> #REF! | AG77: =Q77&" APG" -> #REF! | AH77: =R77&" BPG" -> #REF! | AI77: =S77&" SPG" -> #REF! | AJ77: =T77&" MPG" -> #REF!
A78: 77 | B78: 77 | C78: =Roster!$T80 | L78: =#REF! -> #REF! | M78: =#REF! -> #REF! | N78: =#REF! -> #REF! | O78: =#REF! -> #REF! | P78: =#REF! -> #REF! | Q78: =#REF! -> #REF! | R78: =#REF! -> #REF! | S78: =#REF! -> #REF! | ... U78: =#REF! -> #REF! | Y78: ='Team Info'!$B$19&": "&O78&"" -> #REF! | Z78: ='Team Info'!$B$19&": "&N78&"" -> #REF! | AB78: =L78&" PPG" -> #REF! | AC78: =M78&" FG" -> #REF! | AD78: =N78&" 3-PT" -> #REF! | AE78: =O78&" FT" -> #REF! | AF78: =P78&" RPG" -> #REF! | AG78: =Q78&" APG" -> #REF! | AH78: =R78&" BPG" -> #REF! | AI78: =S78&" SPG" -> #REF! | AJ78: =T78&" MPG" -> #REF!
A79: 78 | B79: 78 | C79: =Roster!$T81 | L79: =#REF! -> #REF! | M79: =#REF! -> #REF! | N79: =#REF! -> #REF! | O79: =#REF! -> #REF! | P79: =#REF! -> #REF! | Q79: =#REF! -> #REF! | R79: =#REF! -> #REF! | S79: =#REF! -> #REF! | ... U79: =#REF! -> #REF! | Y79: ='Team Info'!$B$19&": "&O79&"" -> #REF! | Z79: ='Team Info'!$B$19&": "&N79&"" -> #REF! | AB79: =L79&" PPG" -> #REF! | AC79: =M79&" FG" -> #REF! | AD79: =N79&" 3-PT" -> #REF! | AE79: =O79&" FT" -> #REF! | AF79: =P79&" RPG" -> #REF! | AG79: =Q79&" APG" -> #REF! | AH79: =R79&" BPG" -> #REF! | AI79: =S79&" SPG" -> #REF! | AJ79: =T79&" MPG" -> #REF!
A80: 79 | B80: 79 | C80: =Roster!$T82 | L80: =#REF! -> #REF! | M80: =#REF! -> #REF! | N80: =#REF! -> #REF! | O80: =#REF! -> #REF! | P80: =#REF! -> #REF! | Q80: =#REF! -> #REF! | R80: =#REF! -> #REF! | S80: =#REF! -> #REF! | ... U80: =#REF! -> #REF! | Y80: ='Team Info'!$B$19&": "&O80&"" -> #REF! | Z80: ='Team Info'!$B$19&": "&N80&"" -> #REF! | AB80: =L80&" PPG" -> #REF! | AC80: =M80&" FG" -> #REF! | AD80: =N80&" 3-PT" -> #REF! | AE80: =O80&" FT" -> #REF! | AF80: =P80&" RPG" -> #REF! | AG80: =Q80&" APG" -> #REF! | AH80: =R80&" BPG" -> #REF! | AI80: =S80&" SPG" -> #REF! | AJ80: =T80&" MPG" -> #REF!
A81: 80 | B81: 80 | C81: =Roster!$T83 | L81: =#REF! -> #REF! | M81: =#REF! -> #REF! | N81: =#REF! -> #REF! | O81: =#REF! -> #REF! | P81: =#REF! -> #REF! | Q81: =#REF! -> #REF! | R81: =#REF! -> #REF! | S81: =#REF! -> #REF! | ... U81: =#REF! -> #REF! | Y81: ='Team Info'!$B$19&": "&O81&"" -> #REF! | Z81: ='Team Info'!$B$19&": "&N81&"" -> #REF! | AB81: =L81&" PPG" -> #REF! | AC81: =M81&" FG" -> #REF! | AD81: =N81&" 3-PT" -> #REF! | AE81: =O81&" FT" -> #REF! | AF81: =P81&" RPG" -> #REF! | AG81: =Q81&" APG" -> #REF! | AH81: =R81&" BPG" -> #REF! | AI81: =S81&" SPG" -> #REF! | AJ81: =T81&" MPG" -> #REF!
A82: 81 | B82: 81 | C82: =Roster!$T84 | L82: =#REF! -> #REF! | M82: =#REF! -> #REF! | N82: =#REF! -> #REF! | O82: =#REF! -> #REF! | P82: =#REF! -> #REF! | Q82: =#REF! -> #REF! | R82: =#REF! -> #REF! | S82: =#REF! -> #REF! | ... U82: =#REF! -> #REF! | Y82: ='Team Info'!$B$19&": "&O82&"" -> #REF! | Z82: ='Team Info'!$B$19&": "&N82&"" -> #REF! | AB82: =L82&" PPG" -> #REF! | AC82: =M82&" FG" -> #REF! | AD82: =N82&" 3-PT" -> #REF! | AE82: =O82&" FT" -> #REF! | AF82: =P82&" RPG" -> #REF! | AG82: =Q82&" APG" -> #REF! | AH82: =R82&" BPG" -> #REF! | AI82: =S82&" SPG" -> #REF! | AJ82: =T82&" MPG" -> #REF!
A83: 82 | B83: 82 | C83: =Roster!$T85 | L83: =#REF! -> #REF! | M83: =#REF! -> #REF! | N83: =#REF! -> #REF! | O83: =#REF! -> #REF! | P83: =#REF! -> #REF! | Q83: =#REF! -> #REF! | R83: =#REF! -> #REF! | S83: =#REF! -> #REF! | ... U83: =#REF! -> #REF! | Y83: ='Team Info'!$B$19&": "&O83&"" -> #REF! | Z83: ='Team Info'!$B$19&": "&N83&"" -> #REF! | AB83: =L83&" PPG" -> #REF! | AC83: =M83&" FG" -> #REF! | AD83: =N83&" 3-PT" -> #REF! | AE83: =O83&" FT" -> #REF! | AF83: =P83&" RPG" -> #REF! | AG83: =Q83&" APG" -> #REF! | AH83: =R83&" BPG" -> #REF! | AI83: =S83&" SPG" -> #REF! | AJ83: =T83&" MPG" -> #REF!
A84: 83 | B84: 83 | C84: =Roster!$T86 | L84: =#REF! -> #REF! | M84: =#REF! -> #REF! | N84: =#REF! -> #REF! | O84: =#REF! -> #REF! | P84: =#REF! -> #REF! | Q84: =#REF! -> #REF! | R84: =#REF! -> #REF! | S84: =#REF! -> #REF! | ... U84: =#REF! -> #REF! | Y84: ='Team Info'!$B$19&": "&O84&"" -> #REF! | Z84: ='Team Info'!$B$19&": "&N84&"" -> #REF! | AB84: =L84&" PPG" -> #REF! | AC84: =M84&" FG" -> #REF! | AD84: =N84&" 3-PT" -> #REF! | AE84: =O84&" FT" -> #REF! | AF84: =P84&" RPG" -> #REF! | AG84: =Q84&" APG" -> #REF! | AH84: =R84&" BPG" -> #REF! | AI84: =S84&" SPG" -> #REF! | AJ84: =T84&" MPG" -> #REF!
A85: 84 | B85: 84 | C85: =Roster!$T87 | L85: =#REF! -> #REF! | M85: =#REF! -> #REF! | N85: =#REF! -> #REF! | O85: =#REF! -> #REF! | P85: =#REF! -> #REF! | Q85: =#REF! -> #REF! | R85: =#REF! -> #REF! | S85: =#REF! -> #REF! | ... U85: =#REF! -> #REF! | Y85: ='Team Info'!$B$19&": "&O85&"" -> #REF! | Z85: ='Team Info'!$B$19&": "&N85&"" -> #REF! | AB85: =L85&" PPG" -> #REF! | AC85: =M85&" FG" -> #REF! | AD85: =N85&" 3-PT" -> #REF! | AE85: =O85&" FT" -> #REF! | AF85: =P85&" RPG" -> #REF! | AG85: =Q85&" APG" -> #REF! | AH85: =R85&" BPG" -> #REF! | AI85: =S85&" SPG" -> #REF! | AJ85: =T85&" MPG" -> #REF!
A86: 85 | B86: 85 | C86: =Roster!$T88 | L86: =#REF! -> #REF! | M86: =#REF! -> #REF! | N86: =#REF! -> #REF! | O86: =#REF! -> #REF! | P86: =#REF! -> #REF! | Q86: =#REF! -> #REF! | R86: =#REF! -> #REF! | S86: =#REF! -> #REF! | ... U86: =#REF! -> #REF! | Y86: ='Team Info'!$B$19&": "&O86&"" -> #REF! | Z86: ='Team Info'!$B$19&": "&N86&"" -> #REF! | AB86: =L86&" PPG" -> #REF! | AC86: =M86&" FG" -> #REF! | AD86: =N86&" 3-PT" -> #REF! | AE86: =O86&" FT" -> #REF! | AF86: =P86&" RPG" -> #REF! | AG86: =Q86&" APG" -> #REF! | AH86: =R86&" BPG" -> #REF! | AI86: =S86&" SPG" -> #REF! | AJ86: =T86&" MPG" -> #REF!
